2025-04-24 15:43:10,876 ERROR frappe Could not take error snapshot: (2003, "Can't connect to MySQL server on '127.0.0.1' ([Errno 111] Connection refused)")
Site: aria.localhost
Form Dict: {}
Traceback (most recent call last):
  File "/home/plm/ariasousse/env/lib/python3.10/site-packages/pymysql/connections.py", line 649, in connect
    sock = socket.create_connection(
  File "/usr/lib/python3.10/socket.py", line 845, in create_connection
    raise err
  File "/usr/lib/python3.10/socket.py", line 833, in create_connection
    sock.connect(sa)
ConnectionRefusedError: [Errno 111] Connection refused

During handling of the above exception, another exception occurred:

Traceback (most recent call last):
  File "/home/plm/ariasousse/apps/frappe/frappe/website/serve.py", line 19, in get_response
    endpoint, renderer_instance = path_resolver.resolve()
  File "/home/plm/ariasousse/apps/frappe/frappe/website/path_resolver.py", line 38, in resolve
    resolve_redirect(self.path, request.query_string)
  File "/home/plm/ariasousse/apps/frappe/frappe/website/path_resolver.py", line 118, in resolve_redirect
    redirects += frappe.get_all(
  File "/home/plm/ariasousse/apps/frappe/frappe/__init__.py", line 2014, in get_all
    return get_list(doctype, *args, **kwargs)
  File "/home/plm/ariasousse/apps/frappe/frappe/__init__.py", line 1989, in get_list
    return frappe.model.db_query.DatabaseQuery(doctype).execute(*args, **kwargs)
  File "/home/plm/ariasousse/apps/frappe/frappe/model/db_query.py", line 167, in execute
    if is_virtual_doctype(self.doctype):
  File "/home/plm/ariasousse/apps/frappe/frappe/utils/caching.py", line 121, in site_cache_wrapper
    _SITE_CACHE[func_key][frappe.local.site][func_call_key] = func(*args, **kwargs)
  File "/home/plm/ariasousse/apps/frappe/frappe/model/utils/__init__.py", line 135, in is_virtual_doctype
    return frappe.db.get_value("DocType", doctype, "is_virtual")
  File "/home/plm/ariasousse/apps/frappe/frappe/database/database.py", line 515, in get_value
    result = self.get_values(
  File "/home/plm/ariasousse/apps/frappe/frappe/database/database.py", line 619, in get_values
    out = self._get_values_from_table(
  File "/home/plm/ariasousse/apps/frappe/frappe/database/database.py", line 892, in _get_values_from_table
    return query.run(as_dict=as_dict, debug=debug, update=update, run=run, pluck=pluck)
  File "/home/plm/ariasousse/apps/frappe/frappe/query_builder/utils.py", line 87, in execute_query
    result = frappe.db.sql(query, params, *args, **kwargs)  # nosemgrep
  File "/home/plm/ariasousse/apps/frappe/frappe/database/database.py", line 207, in sql
    self.connect()
  File "/home/plm/ariasousse/apps/frappe/frappe/database/database.py", line 112, in connect
    self._conn: "MariadbConnection" | "PostgresConnection" = self.get_connection()
  File "/home/plm/ariasousse/apps/frappe/frappe/database/mariadb/database.py", line 107, in get_connection
    conn = self._get_connection()
  File "/home/plm/ariasousse/apps/frappe/frappe/database/mariadb/database.py", line 113, in _get_connection
    return self.create_connection()
  File "/home/plm/ariasousse/apps/frappe/frappe/database/mariadb/database.py", line 116, in create_connection
    return pymysql.connect(**self.get_connection_settings())
  File "/home/plm/ariasousse/env/lib/python3.10/site-packages/pymysql/connections.py", line 361, in __init__
    self.connect()
  File "/home/plm/ariasousse/env/lib/python3.10/site-packages/pymysql/connections.py", line 716, in connect
    raise exc
pymysql.err.OperationalError: (2003, "Can't connect to MySQL server on '127.0.0.1' ([Errno 111] Connection refused)")

During handling of the above exception, another exception occurred:

Traceback (most recent call last):
  File "/home/plm/ariasousse/env/lib/python3.10/site-packages/pymysql/connections.py", line 649, in connect
    sock = socket.create_connection(
  File "/usr/lib/python3.10/socket.py", line 845, in create_connection
    raise err
  File "/usr/lib/python3.10/socket.py", line 833, in create_connection
    sock.connect(sa)
ConnectionRefusedError: [Errno 111] Connection refused

During handling of the above exception, another exception occurred:

Traceback (most recent call last):
  File "/home/plm/ariasousse/apps/frappe/frappe/app.py", line 123, in application
    response = get_response()
  File "/home/plm/ariasousse/apps/frappe/frappe/website/serve.py", line 28, in get_response
    response = ErrorPage(exception=e).render()
  File "/home/plm/ariasousse/apps/frappe/frappe/website/page_renderers/template_page.py", line 84, in render
    html = self.get_html()
  File "/home/plm/ariasousse/apps/frappe/frappe/website/utils.py", line 530, in cache_html_decorator
    html = func(*args, **kwargs)
  File "/home/plm/ariasousse/apps/frappe/frappe/website/page_renderers/template_page.py", line 92, in get_html
    self.init_context()
  File "/home/plm/ariasousse/apps/frappe/frappe/website/page_renderers/error_page.py", line 14, in init_context
    super().init_context()
  File "/home/plm/ariasousse/apps/frappe/frappe/website/page_renderers/base_template_page.py", line 15, in init_context
    self.context.update(get_website_settings())
  File "/home/plm/ariasousse/apps/frappe/frappe/website/doctype/website_settings/website_settings.py", line 263, in get_website_settings
    context.boot = get_boot_data()
  File "/home/plm/ariasousse/apps/frappe/frappe/website/utils.py", line 169, in get_boot_data
    apps = get_apps() or []
  File "/home/plm/ariasousse/apps/frappe/frappe/utils/typing_validations.py", line 31, in wrapper
    return func(*args, **kwargs)
  File "/home/plm/ariasousse/apps/frappe/frappe/apps.py", line 15, in get_apps
    allowed_workspaces = get_workspace_sidebar_items().get("pages")
  File "/home/plm/ariasousse/apps/frappe/frappe/utils/typing_validations.py", line 31, in wrapper
    return func(*args, **kwargs)
  File "/home/plm/ariasousse/apps/frappe/frappe/desk/desktop.py", line 447, in get_workspace_sidebar_items
    all_pages = frappe.get_all(
  File "/home/plm/ariasousse/apps/frappe/frappe/__init__.py", line 2014, in get_all
    return get_list(doctype, *args, **kwargs)
  File "/home/plm/ariasousse/apps/frappe/frappe/__init__.py", line 1989, in get_list
    return frappe.model.db_query.DatabaseQuery(doctype).execute(*args, **kwargs)
  File "/home/plm/ariasousse/apps/frappe/frappe/model/db_query.py", line 167, in execute
    if is_virtual_doctype(self.doctype):
  File "/home/plm/ariasousse/apps/frappe/frappe/utils/caching.py", line 121, in site_cache_wrapper
    _SITE_CACHE[func_key][frappe.local.site][func_call_key] = func(*args, **kwargs)
  File "/home/plm/ariasousse/apps/frappe/frappe/model/utils/__init__.py", line 135, in is_virtual_doctype
    return frappe.db.get_value("DocType", doctype, "is_virtual")
  File "/home/plm/ariasousse/apps/frappe/frappe/database/database.py", line 515, in get_value
    result = self.get_values(
  File "/home/plm/ariasousse/apps/frappe/frappe/database/database.py", line 619, in get_values
    out = self._get_values_from_table(
  File "/home/plm/ariasousse/apps/frappe/frappe/database/database.py", line 892, in _get_values_from_table
    return query.run(as_dict=as_dict, debug=debug, update=update, run=run, pluck=pluck)
  File "/home/plm/ariasousse/apps/frappe/frappe/query_builder/utils.py", line 87, in execute_query
    result = frappe.db.sql(query, params, *args, **kwargs)  # nosemgrep
  File "/home/plm/ariasousse/apps/frappe/frappe/database/database.py", line 207, in sql
    self.connect()
  File "/home/plm/ariasousse/apps/frappe/frappe/database/database.py", line 112, in connect
    self._conn: "MariadbConnection" | "PostgresConnection" = self.get_connection()
  File "/home/plm/ariasousse/apps/frappe/frappe/database/mariadb/database.py", line 107, in get_connection
    conn = self._get_connection()
  File "/home/plm/ariasousse/apps/frappe/frappe/database/mariadb/database.py", line 113, in _get_connection
    return self.create_connection()
  File "/home/plm/ariasousse/apps/frappe/frappe/database/mariadb/database.py", line 116, in create_connection
    return pymysql.connect(**self.get_connection_settings())
  File "/home/plm/ariasousse/env/lib/python3.10/site-packages/pymysql/connections.py", line 361, in __init__
    self.connect()
  File "/home/plm/ariasousse/env/lib/python3.10/site-packages/pymysql/connections.py", line 716, in connect
    raise exc
pymysql.err.OperationalError: (2003, "Can't connect to MySQL server on '127.0.0.1' ([Errno 111] Connection refused)")

During handling of the above exception, another exception occurred:

Traceback (most recent call last):
  File "/home/plm/ariasousse/env/lib/python3.10/site-packages/pymysql/connections.py", line 649, in connect
    sock = socket.create_connection(
  File "/usr/lib/python3.10/socket.py", line 845, in create_connection
    raise err
  File "/usr/lib/python3.10/socket.py", line 833, in create_connection
    sock.connect(sa)
ConnectionRefusedError: [Errno 111] Connection refused

During handling of the above exception, another exception occurred:

Traceback (most recent call last):
  File "/home/plm/ariasousse/apps/frappe/frappe/utils/error.py", line 86, in log_error_snapshot
    log_error(title=str(exception), defer_insert=True)
  File "/home/plm/ariasousse/apps/frappe/frappe/utils/error.py", line 61, in log_error
    error_log = frappe.get_doc(
  File "/home/plm/ariasousse/apps/frappe/frappe/__init__.py", line 1290, in get_doc
    doc = frappe.model.document.get_doc(*args, **kwargs)
  File "/home/plm/ariasousse/apps/frappe/frappe/model/document.py", line 83, in get_doc
    controller = get_controller(doctype)
  File "/home/plm/ariasousse/apps/frappe/frappe/model/base_document.py", line 70, in get_controller
    site_controllers[doctype] = import_controller(doctype)
  File "/home/plm/ariasousse/apps/frappe/frappe/model/base_document.py", line 81, in import_controller
    doctype_info = frappe.db.get_value("DocType", doctype, fieldname="*")
  File "/home/plm/ariasousse/apps/frappe/frappe/database/database.py", line 515, in get_value
    result = self.get_values(
  File "/home/plm/ariasousse/apps/frappe/frappe/database/database.py", line 619, in get_values
    out = self._get_values_from_table(
  File "/home/plm/ariasousse/apps/frappe/frappe/database/database.py", line 892, in _get_values_from_table
    return query.run(as_dict=as_dict, debug=debug, update=update, run=run, pluck=pluck)
  File "/home/plm/ariasousse/apps/frappe/frappe/query_builder/utils.py", line 87, in execute_query
    result = frappe.db.sql(query, params, *args, **kwargs)  # nosemgrep
  File "/home/plm/ariasousse/apps/frappe/frappe/database/database.py", line 207, in sql
    self.connect()
  File "/home/plm/ariasousse/apps/frappe/frappe/database/database.py", line 112, in connect
    self._conn: "MariadbConnection" | "PostgresConnection" = self.get_connection()
  File "/home/plm/ariasousse/apps/frappe/frappe/database/mariadb/database.py", line 107, in get_connection
    conn = self._get_connection()
  File "/home/plm/ariasousse/apps/frappe/frappe/database/mariadb/database.py", line 113, in _get_connection
    return self.create_connection()
  File "/home/plm/ariasousse/apps/frappe/frappe/database/mariadb/database.py", line 116, in create_connection
    return pymysql.connect(**self.get_connection_settings())
  File "/home/plm/ariasousse/env/lib/python3.10/site-packages/pymysql/connections.py", line 361, in __init__
    self.connect()
  File "/home/plm/ariasousse/env/lib/python3.10/site-packages/pymysql/connections.py", line 716, in connect
    raise exc
pymysql.err.OperationalError: (2003, "Can't connect to MySQL server on '127.0.0.1' ([Errno 111] Connection refused)")
2025-04-24 15:48:30,392 ERROR frappe New Exception collected in error log
Site: aria.localhost
Form Dict: {'doctype': 'Patient et demande', 'name': 'QWERTY', 'fieldname': '{"status":"Avis à modifier","custom_arguments":"<div class=\\"ql-editor read-mode\\"><p>Ceci est un exemple de pour afficher l\'argumentaire de cet AVIS</p><p><br></p><p><strong>Anwar Benjeddou</strong></p><p><strong>\ufeff</strong></p><p><em>Tunis, le 18&nbsp;Avril&nbsp;2025 test</em></p></div>"}', 'cmd': 'frappe.client.set_value'}
2025-04-24 15:50:36,179 ERROR frappe New Exception collected in error log
Site: aria.localhost
Form Dict: {'doctype': 'Patient et demande', 'name': 'QWERTY', 'fieldname': '{"status":"Avis à modifier","custom_arguments":"<div class=\\"ql-editor read-mode\\"><p>Ceci est un exemple de pour afficher l\'argumentaire de cet AVIS</p><p><br></p><p><strong>Anwar Benjeddou</strong></p><p><strong>\ufeff</strong></p><p><em>Tunis, le 18&nbsp;Avril&nbsp;2025 </em></p></div>"}', 'cmd': 'frappe.client.set_value'}
2025-04-24 15:57:45,683 ERROR frappe New Exception collected in error log
Site: aria.localhost
Form Dict: {'doctype': 'Patient et demande', 'name': 'QWERTY', 'fieldname': '{"status":"Avis à modifier","custom_arguments":"<div class=\\"ql-editor read-mode\\"><p>Ceci est un exemple de pour afficher l\'argumentaire de cet AVIS</p><p><br></p><p><strong>Anwar Benjeddou</strong></p><p><strong>\ufeff</strong></p><p><em>Tunis, le 18&nbsp;Avril&nbsp;2025 </em></p></div>"}', 'cmd': 'frappe.client.set_value'}
2025-04-24 15:57:54,019 ERROR frappe New Exception collected in error log
Site: aria.localhost
Form Dict: {'doctype': 'Patient et demande', 'name': 'QWERTY', 'fieldname': '{"status":"Avis à modifier","custom_arguments":"<div class=\\"ql-editor read-mode\\"><p>Ceci est un exemple de pour afficher l\'argumentaire de cet AVIS</p><p><br></p><p><strong>Anwar Benjeddou</strong></p><p><strong>\ufeff</strong></p><p><em>Tunis, le 18&nbsp;Avril&nbsp;2025 </em></p></div>"}', 'cmd': 'frappe.client.set_value'}
2025-04-24 15:59:34,665 ERROR frappe New Exception collected in error log
Site: aria.localhost
Form Dict: {'doc': '{"name":"QWERTY","owner":"maher@linca.com","creation":"2025-03-26 23:21:21.145276","modified":"2025-04-24 16:30:28.592536","modified_by":"expert@linca.com","docstatus":0,"idx":0,"custom_modification_count":5,"status":"Avis en cours","prénom_du_patient":"QWERTY","nom_du_patient":"QWERTY","age":0,"poid_estimé_kg":0,"taille_estimecm":0,"on_demande_un_aide_au_diag":0,"on_demande_une_aide_thérapeutique":0,"on_demande_un_transfer_a_votre_service":0,"on_demande_un_conseil_de_preventionvaccination":0,"autre_apréciser":0,"votre_patient__a_été":0,"votre_patient":0,"votre_patient_2":0,"oui":0,"non":0,"allergie_aux_bétalacamines__penicillines":0,"autre_type_allergie":0,"custom_mineur_":0,"custom_mjoeur":0,"custom_documented_allergy":0,"custom_undocumented_allergy":0,"custom_corticothérapie15_jours":0,"custom_biographie_":0,"custom_immunosuppresseurs":0,"custom_chimiothérapie":0,"custom_issufisance_rénale_au_stade_dhémodialyse":0,"custom_insuffisance_hépatique_crrihose":0,"custom_splénectomie":0,"custom_infection_à_vih_":0,"custom_ouioui":0,"custom_custom_non":0,"custom_diabéte":0,"custom_hta":0,"custom_coronaropathie":0,"custom_bpco":0,"custom_autrea_préciser":0,"custom_oui_fiévre":0,"custom__mentionne_la_température_c":0,"custom_non_fiévre_":0,"custom_oui_hypotension_artierelle":0,"custom_mentionner_la_ta_mmhg":0,"custom__non_hypotension_artierelle":0,"custom_oui_matriel_etranger_":0,"custom_non_matriel_etranger_":0,"custom_bladder_catheter":0,"custom_vesicostomy_tube":0,"custom_nephrostomy_tube":0,"custom_peripheral_kt":0,"custom_kt_jigular":0,"custom_femoral_kt":0,"custom_prosthesis":0,"custom_osteosynthesis_equipment":0,"custom_tracheostomy_tube":0,"custom_tracheal_intubation_tube":0,"custom_implantable_chamber":0,"custom_pacemaker":0,"custom_other":0,"custom_bladder_catheter_in_place":0,"custom_bladder_catheter_removed":0,"custom_bladder_catheter_inflammatory_signs_presence_yes":0,"custom_bladder_catheter_inflammatory_signs_presence_no":0,"custom_vesicostomy_tube_in_place":0,"custom_vesicostomy_tube_removed":0,"custom_vesicostomy_tube_inflammatory_signs_presence_yes":0,"custom_vesicostomy_tube_inflammatory_signs_presence_no":0,"custom_nephrostomy_tube_in_place":0,"custom_nephrostomy_tube_removed":0,"custom_nephrostomy_tube_inflammatory_signs_presence_yes":0,"custom_nephrostomy_tube_inflammatory_signs_presence_no":0,"custom_peripheral_kt_in_place":0,"custom_peripheral_kt_removed":0,"custom_peripheral_kt_inflammatory_signs_presence_yes":0,"custom_peripheral_kt_inflammatory_signs_presence_no":0,"custom_kt_jigular_in_place":0,"custom_kt_jigular_removed":0,"custom_kt_jigular_inflammatory_signs_presence_yes":0,"custom_kt_jigular_inflammatory_signs_presence_no":0,"custom_femoral_kt_in_place":0,"custom_femoral_kt_removed":0,"custom_femoral_kt_inflammatory_signs_presence_yes":0,"custom_femoral_kt_inflammatory_signs_presence_no":0,"custom_prosthesis_in_place":0,"custom_prosthesis_removed":0,"custom_prosthesis_inflammatory_signs_presence_yes":0,"custom_prosthesis_inflammatory_signs_presence_no":0,"custom_osteosynthesis_equipment_in_place":0,"custom_osteosynthesis_equipment_removed":0,"custom_osteosynthesis_equipment_inflammatory_sign_presence_yes":0,"custom_osteosynthesis_equipment_inflammatory_sign_presence_no":0,"custom_tracheostomy_tube_in_place":0,"custom_tracheostomy_tube_removed":0,"custom_tracheostomy_tube_inflammatory_signs_presence_yes":0,"custom_tracheostomy_tube_inflammatory_signs_presence_no":0,"custom_tracheal_intubation_tube_in_place":0,"custom_tracheal_intubation_tube_removed":0,"custom_tracheal_intubation_tube_inflammatory_signs_presence_yes":0,"custom_tracheal_intubation_tube_inflammatory_signs_presence_no":0,"custom_implantable_chamber_in_place":0,"custom_implantable_chamber_removed":0,"custom_implantable_chamber_inflammatory_signs_presence_yes":0,"custom_implantable_chamber_inflammatory_signs_presence_no":0,"custom_pacemaker_in_place":0,"custom_pacemaker_removed":0,"custom_pacemaker_inflammatory_signs_presence_yes":0,"custom_pacemaker_inflammatory_signs_presence_no":0,"custom_yes":0,"custom_no":0,"custom_blood_count_yes":0,"custom_blood_count_no":0,"custom_renal_function_yes":0,"custom_renal_function_no":0,"custom_liver_function_yes":0,"custom_liver_function_no":0,"custom_inflammatory_assessment_yes":0,"custom_inflammatory_assessment_no":0,"custom_other_biology_yes":0,"custom_other_biology_no":0,"custom_microbiological_examination_done_yes":1,"custom_microbiological_examination_done_no":0,"custom_blood_culture":1,"custom_lumbar_puncture":0,"custom_ecbc":0,"custom_lba":0,"custom_ptp":0,"custom_pcr":0,"custom_serology":0,"custom_rbk":0,"custom_ecbu":1,"custom_coproculture":0,"custom_stools_parasitological_examination":0,"custom_superficial_pus":0,"custom_deep_pus":0,"custom_prosthesis_material":0,"custom_device":0,"custom_number_of_blood_cultures":1,"custom_number_of_ecbu":0,"custom_number_of_pl":0,"custom_number_of_stool_cultures":0,"custom_number_of_ecbc":0,"custom_number_of_bal":0,"custom_number_of_ptps":0,"custom_number_of_rbks":0,"custom_number_of_eps":0,"custom_number_of_superficial_pus":0,"custom_number_of_deep_pus":0,"custom_number_of_prosthesis":0,"custom_number_of_devices":0,"custom_number_of_serologies":0,"custom_number_of_pcr":0,"custom_radiological_examination_done_yes":0,"custom_radiological_examination_done_no":0,"custom_arguments":"<div class=\\"ql-editor read-mode\\"><p>Ceci est un exemple de pour afficher l\'argumentaire de cet AVIS</p><p><br></p><p><strong>Anwar Benjeddou</strong></p><p><strong>\ufeff</strong></p><p><em>Tunis, le 18&nbsp;Avril&nbsp;2025 test </em></p></div>","doctype":"Patient et demande","custom_presence_dun_matrielle_etranger":[],"custom_rbks":[],"custom_ecbcs":[],"custom_liver_function_analysis":[],"custom_other_biology_list":[],"custom_blood_analysis":[],"custom_serologies":[],"custom_note":[],"custom_superficial_puses":[],"custom_ecbus":[],"custom_prosthesis_list":[],"custom_lumbar_punctures":[],"custom_inflammatory_assessment_analysis":[],"custom_ptp_protected_tracheal_sampling":[],"custom_pcrs":[],"custom_notice_anti_infective_item":[],"custom_devices_kt_probe_":[],"custom_blood_cultures":[{"name":"njk14b3l6t","owner":"expert@linca.com","creation":"2025-03-26 23:21:21.145276","modified":"2025-04-24 16:30:28.592536","modified_by":"expert@linca.com","docstatus":0,"idx":1,"analysis_date":"2025-04-15","state_culture":"Culture in progress","direct_examination":"RAS","antibiogram":"/private/files/Screenshot from 2025-04-22 09-13-03.png, /private/files/Screenshot from 2025-04-17 15-24-44.png","antibiogram_preview":"","parent":"QWERTY","parentfield":"custom_blood_cultures","parenttype":"Patient et demande","doctype":"Notice Blood culture Item"}],"custom_deep_puses":[],"custom_stool_cultures":[],"custom_bal_bronchoalveolar_fluid":[],"custom_eps":[],"custom_renal_function_analysis":[],"__last_sync_on":"2025-04-24T15:59:05.537Z","__unsaved":1}', 'action': 'Save', 'cmd': 'frappe.desk.form.save.savedocs'}
2025-04-24 16:01:05,178 ERROR frappe New Exception collected in error log
Site: aria.localhost
Form Dict: {'doc': '{"name":"QWERTY","owner":"maher@linca.com","creation":"2025-03-26 23:21:21.145276","modified":"2025-04-24 16:30:28.592536","modified_by":"expert@linca.com","docstatus":0,"idx":0,"custom_modification_count":5,"status":"Avis en cours","prénom_du_patient":"QWERTY","nom_du_patient":"QWERTY","age":0,"poid_estimé_kg":0,"taille_estimecm":0,"on_demande_un_aide_au_diag":0,"on_demande_une_aide_thérapeutique":0,"on_demande_un_transfer_a_votre_service":0,"on_demande_un_conseil_de_preventionvaccination":0,"autre_apréciser":0,"votre_patient__a_été":0,"votre_patient":0,"votre_patient_2":0,"oui":0,"non":0,"allergie_aux_bétalacamines__penicillines":0,"autre_type_allergie":0,"custom_mineur_":0,"custom_mjoeur":0,"custom_documented_allergy":0,"custom_undocumented_allergy":0,"custom_corticothérapie15_jours":0,"custom_biographie_":0,"custom_immunosuppresseurs":0,"custom_chimiothérapie":0,"custom_issufisance_rénale_au_stade_dhémodialyse":0,"custom_insuffisance_hépatique_crrihose":0,"custom_splénectomie":0,"custom_infection_à_vih_":0,"custom_ouioui":0,"custom_custom_non":0,"custom_diabéte":0,"custom_hta":0,"custom_coronaropathie":0,"custom_bpco":0,"custom_autrea_préciser":0,"custom_oui_fiévre":0,"custom__mentionne_la_température_c":0,"custom_non_fiévre_":0,"custom_oui_hypotension_artierelle":0,"custom_mentionner_la_ta_mmhg":0,"custom__non_hypotension_artierelle":0,"custom_oui_matriel_etranger_":0,"custom_non_matriel_etranger_":0,"custom_bladder_catheter":0,"custom_vesicostomy_tube":0,"custom_nephrostomy_tube":0,"custom_peripheral_kt":0,"custom_kt_jigular":0,"custom_femoral_kt":0,"custom_prosthesis":0,"custom_osteosynthesis_equipment":0,"custom_tracheostomy_tube":0,"custom_tracheal_intubation_tube":0,"custom_implantable_chamber":0,"custom_pacemaker":0,"custom_other":0,"custom_bladder_catheter_in_place":0,"custom_bladder_catheter_removed":0,"custom_bladder_catheter_inflammatory_signs_presence_yes":0,"custom_bladder_catheter_inflammatory_signs_presence_no":0,"custom_vesicostomy_tube_in_place":0,"custom_vesicostomy_tube_removed":0,"custom_vesicostomy_tube_inflammatory_signs_presence_yes":0,"custom_vesicostomy_tube_inflammatory_signs_presence_no":0,"custom_nephrostomy_tube_in_place":0,"custom_nephrostomy_tube_removed":0,"custom_nephrostomy_tube_inflammatory_signs_presence_yes":0,"custom_nephrostomy_tube_inflammatory_signs_presence_no":0,"custom_peripheral_kt_in_place":0,"custom_peripheral_kt_removed":0,"custom_peripheral_kt_inflammatory_signs_presence_yes":0,"custom_peripheral_kt_inflammatory_signs_presence_no":0,"custom_kt_jigular_in_place":0,"custom_kt_jigular_removed":0,"custom_kt_jigular_inflammatory_signs_presence_yes":0,"custom_kt_jigular_inflammatory_signs_presence_no":0,"custom_femoral_kt_in_place":0,"custom_femoral_kt_removed":0,"custom_femoral_kt_inflammatory_signs_presence_yes":0,"custom_femoral_kt_inflammatory_signs_presence_no":0,"custom_prosthesis_in_place":0,"custom_prosthesis_removed":0,"custom_prosthesis_inflammatory_signs_presence_yes":0,"custom_prosthesis_inflammatory_signs_presence_no":0,"custom_osteosynthesis_equipment_in_place":0,"custom_osteosynthesis_equipment_removed":0,"custom_osteosynthesis_equipment_inflammatory_sign_presence_yes":0,"custom_osteosynthesis_equipment_inflammatory_sign_presence_no":0,"custom_tracheostomy_tube_in_place":0,"custom_tracheostomy_tube_removed":0,"custom_tracheostomy_tube_inflammatory_signs_presence_yes":0,"custom_tracheostomy_tube_inflammatory_signs_presence_no":0,"custom_tracheal_intubation_tube_in_place":0,"custom_tracheal_intubation_tube_removed":0,"custom_tracheal_intubation_tube_inflammatory_signs_presence_yes":0,"custom_tracheal_intubation_tube_inflammatory_signs_presence_no":0,"custom_implantable_chamber_in_place":0,"custom_implantable_chamber_removed":0,"custom_implantable_chamber_inflammatory_signs_presence_yes":0,"custom_implantable_chamber_inflammatory_signs_presence_no":0,"custom_pacemaker_in_place":0,"custom_pacemaker_removed":0,"custom_pacemaker_inflammatory_signs_presence_yes":0,"custom_pacemaker_inflammatory_signs_presence_no":0,"custom_yes":0,"custom_no":0,"custom_blood_count_yes":0,"custom_blood_count_no":0,"custom_renal_function_yes":0,"custom_renal_function_no":0,"custom_liver_function_yes":0,"custom_liver_function_no":0,"custom_inflammatory_assessment_yes":0,"custom_inflammatory_assessment_no":0,"custom_other_biology_yes":0,"custom_other_biology_no":0,"custom_microbiological_examination_done_yes":1,"custom_microbiological_examination_done_no":0,"custom_blood_culture":1,"custom_lumbar_puncture":0,"custom_ecbc":0,"custom_lba":0,"custom_ptp":0,"custom_pcr":0,"custom_serology":0,"custom_rbk":0,"custom_ecbu":1,"custom_coproculture":0,"custom_stools_parasitological_examination":0,"custom_superficial_pus":0,"custom_deep_pus":0,"custom_prosthesis_material":0,"custom_device":0,"custom_number_of_blood_cultures":1,"custom_number_of_ecbu":0,"custom_number_of_pl":0,"custom_number_of_stool_cultures":0,"custom_number_of_ecbc":0,"custom_number_of_bal":0,"custom_number_of_ptps":0,"custom_number_of_rbks":0,"custom_number_of_eps":0,"custom_number_of_superficial_pus":0,"custom_number_of_deep_pus":0,"custom_number_of_prosthesis":0,"custom_number_of_devices":0,"custom_number_of_serologies":0,"custom_number_of_pcr":0,"custom_radiological_examination_done_yes":0,"custom_radiological_examination_done_no":0,"custom_arguments":"<div class=\\"ql-editor read-mode\\"><p>Ceci est un exemple de pour afficher l\'argumentaire de cet AVIS</p><p><br></p><p><strong>Anwar Benjeddou</strong></p><p><strong>\ufeff</strong></p><p><em>Tunis, le 18&nbsp;Avril&nbsp;2025 </em></p></div>","doctype":"Patient et demande","custom_presence_dun_matrielle_etranger":[],"custom_rbks":[],"custom_ecbcs":[],"custom_liver_function_analysis":[],"custom_other_biology_list":[],"custom_blood_analysis":[],"custom_serologies":[],"custom_note":[],"custom_superficial_puses":[],"custom_ecbus":[],"custom_prosthesis_list":[],"custom_lumbar_punctures":[],"custom_inflammatory_assessment_analysis":[],"custom_ptp_protected_tracheal_sampling":[],"custom_pcrs":[],"custom_notice_anti_infective_item":[],"custom_devices_kt_probe_":[],"custom_blood_cultures":[{"name":"njk14b3l6t","owner":"expert@linca.com","creation":"2025-03-26 23:21:21.145276","modified":"2025-04-24 16:30:28.592536","modified_by":"expert@linca.com","docstatus":0,"idx":1,"analysis_date":"2025-04-15","state_culture":"Culture in progress","direct_examination":"RAS","antibiogram":"/private/files/Screenshot from 2025-04-22 09-13-03.png, /private/files/Screenshot from 2025-04-17 15-24-44.png","antibiogram_preview":"","parent":"QWERTY","parentfield":"custom_blood_cultures","parenttype":"Patient et demande","doctype":"Notice Blood culture Item"}],"custom_deep_puses":[],"custom_stool_cultures":[],"custom_bal_bronchoalveolar_fluid":[],"custom_eps":[],"custom_renal_function_analysis":[],"__last_sync_on":"2025-04-24T16:00:24.406Z","__unsaved":1}', 'action': 'Save', 'cmd': 'frappe.desk.form.save.savedocs'}
2025-04-24 16:12:25,491 ERROR frappe New Exception collected in error log
Site: aria.localhost
Form Dict: {'doc': 'Patient et demande', 'name': 'QWERTY', 'format': 'Custom Doctor Notice', 'no_letterhead': '1', 'cmd': 'frappe.www.printview.get_html_and_style'}
2025-04-24 16:12:25,710 ERROR frappe New Exception collected in error log
Site: aria.localhost
Form Dict: {'doc': 'Patient et demande', 'name': 'QWERTY', 'format': 'Custom Doctor Notice', 'no_letterhead': '1', 'cmd': 'frappe.www.printview.get_html_and_style'}
2025-04-24 16:12:59,532 ERROR frappe New Exception collected in error log
Site: aria.localhost
Form Dict: {'doctype': 'Patient et demande', 'name': 'QWERTY', 'fieldname': '{"status":"Avis à modifier","custom_arguments":"<div class=\\"ql-editor read-mode\\"><p>Ceci est un exemple de pour afficher l\'argumentaire de cet AVIS</p><p><br></p><p><strong>Anwar Benjeddou</strong></p><p><strong>\ufeff</strong></p><p><em>Tunis, le 18&nbsp;Avril&nbsp;2025</em></p><p><em> </em></p></div>"}', 'cmd': 'frappe.client.set_value'}
2025-04-25 08:31:26,897 ERROR frappe New Exception collected in error log
Site: aria.localhost
Form Dict: {'doc': '{"name":"tiba12","owner":"maher@linca.com","creation":"2025-04-25 08:38:30.646671","modified":"2025-04-25 08:42:35.502692","modified_by":"expert@linca.com","docstatus":0,"idx":0,"dr":"maher","service":"Chirurgie générale","custom_doctor_phone_number":"","custom_modification_count":0,"custom_doctor_grade":"Résident","custom_doctor_institution":"Hôpital Farhat Hached","status":"Avis en cours","prénom_du_patient":"soumaya","nom_du_patient":"tiba12","age":0,"poid_estimé_kg":0,"taille_estimecm":0,"on_demande_un_aide_au_diag":0,"on_demande_une_aide_thérapeutique":0,"on_demande_un_transfer_a_votre_service":0,"on_demande_un_conseil_de_preventionvaccination":0,"autre_apréciser":1,"votre_patient__a_été":1,"votre_patient":0,"votre_patient_2":1,"oui":0,"non":0,"allergie_aux_bétalacamines__penicillines":0,"autre_type_allergie":0,"custom_mineur_":0,"custom_mjoeur":0,"custom_documented_allergy":0,"custom_undocumented_allergy":0,"custom_corticothérapie15_jours":0,"custom_biographie_":0,"custom_immunosuppresseurs":0,"custom_chimiothérapie":0,"custom_issufisance_rénale_au_stade_dhémodialyse":0,"custom_insuffisance_hépatique_crrihose":0,"custom_splénectomie":0,"custom_infection_à_vih_":0,"custom_ouioui":0,"custom_custom_non":0,"custom_diabéte":0,"custom_hta":0,"custom_coronaropathie":0,"custom_bpco":0,"custom_autrea_préciser":0,"custom_oui_fiévre":0,"custom__mentionne_la_température_c":0,"custom_non_fiévre_":0,"custom_oui_hypotension_artierelle":0,"custom_mentionner_la_ta_mmhg":0,"custom__non_hypotension_artierelle":0,"custom_oui_matriel_etranger_":0,"custom_non_matriel_etranger_":0,"custom_bladder_catheter":0,"custom_vesicostomy_tube":0,"custom_nephrostomy_tube":0,"custom_peripheral_kt":0,"custom_kt_jigular":0,"custom_femoral_kt":0,"custom_prosthesis":0,"custom_osteosynthesis_equipment":0,"custom_tracheostomy_tube":0,"custom_tracheal_intubation_tube":0,"custom_implantable_chamber":0,"custom_pacemaker":0,"custom_other":0,"custom_bladder_catheter_in_place":0,"custom_bladder_catheter_removed":0,"custom_bladder_catheter_inflammatory_signs_presence_yes":0,"custom_bladder_catheter_inflammatory_signs_presence_no":0,"custom_vesicostomy_tube_in_place":0,"custom_vesicostomy_tube_removed":0,"custom_vesicostomy_tube_inflammatory_signs_presence_yes":0,"custom_vesicostomy_tube_inflammatory_signs_presence_no":0,"custom_nephrostomy_tube_in_place":0,"custom_nephrostomy_tube_removed":0,"custom_nephrostomy_tube_inflammatory_signs_presence_yes":0,"custom_nephrostomy_tube_inflammatory_signs_presence_no":0,"custom_peripheral_kt_in_place":0,"custom_peripheral_kt_removed":0,"custom_peripheral_kt_inflammatory_signs_presence_yes":0,"custom_peripheral_kt_inflammatory_signs_presence_no":0,"custom_kt_jigular_in_place":0,"custom_kt_jigular_removed":0,"custom_kt_jigular_inflammatory_signs_presence_yes":0,"custom_kt_jigular_inflammatory_signs_presence_no":0,"custom_femoral_kt_in_place":0,"custom_femoral_kt_removed":0,"custom_femoral_kt_inflammatory_signs_presence_yes":0,"custom_femoral_kt_inflammatory_signs_presence_no":0,"custom_prosthesis_in_place":0,"custom_prosthesis_removed":0,"custom_prosthesis_inflammatory_signs_presence_yes":0,"custom_prosthesis_inflammatory_signs_presence_no":0,"custom_osteosynthesis_equipment_in_place":0,"custom_osteosynthesis_equipment_removed":0,"custom_osteosynthesis_equipment_inflammatory_sign_presence_yes":0,"custom_osteosynthesis_equipment_inflammatory_sign_presence_no":0,"custom_tracheostomy_tube_in_place":0,"custom_tracheostomy_tube_removed":0,"custom_tracheostomy_tube_inflammatory_signs_presence_yes":0,"custom_tracheostomy_tube_inflammatory_signs_presence_no":0,"custom_tracheal_intubation_tube_in_place":0,"custom_tracheal_intubation_tube_removed":0,"custom_tracheal_intubation_tube_inflammatory_signs_presence_yes":0,"custom_tracheal_intubation_tube_inflammatory_signs_presence_no":0,"custom_implantable_chamber_in_place":0,"custom_implantable_chamber_removed":0,"custom_implantable_chamber_inflammatory_signs_presence_yes":0,"custom_implantable_chamber_inflammatory_signs_presence_no":0,"custom_pacemaker_in_place":0,"custom_pacemaker_removed":0,"custom_pacemaker_inflammatory_signs_presence_yes":0,"custom_pacemaker_inflammatory_signs_presence_no":0,"custom_yes":0,"custom_no":0,"custom_blood_count_yes":0,"custom_blood_count_no":0,"custom_renal_function_yes":0,"custom_renal_function_no":0,"custom_liver_function_yes":0,"custom_liver_function_no":0,"custom_inflammatory_assessment_yes":0,"custom_inflammatory_assessment_no":0,"custom_other_biology_yes":0,"custom_other_biology_no":0,"custom_microbiological_examination_done_yes":0,"custom_microbiological_examination_done_no":0,"custom_blood_culture":0,"custom_lumbar_puncture":0,"custom_ecbc":0,"custom_lba":0,"custom_ptp":0,"custom_pcr":0,"custom_serology":0,"custom_rbk":0,"custom_ecbu":0,"custom_coproculture":0,"custom_stools_parasitological_examination":0,"custom_superficial_pus":0,"custom_deep_pus":0,"custom_prosthesis_material":0,"custom_device":0,"custom_number_of_blood_cultures":0,"custom_number_of_ecbu":0,"custom_number_of_pl":0,"custom_number_of_stool_cultures":0,"custom_number_of_ecbc":0,"custom_number_of_bal":0,"custom_number_of_ptps":0,"custom_number_of_rbks":0,"custom_number_of_eps":0,"custom_number_of_superficial_pus":0,"custom_number_of_deep_pus":0,"custom_number_of_prosthesis":0,"custom_number_of_devices":0,"custom_number_of_serologies":0,"custom_number_of_pcr":0,"custom_radiological_examination_done_yes":0,"custom_radiological_examination_done_no":0,"doctype":"Patient et demande","custom_liver_function_analysis":[],"custom_superficial_puses":[],"custom_deep_puses":[],"custom_stool_cultures":[],"custom_serologies":[],"custom_renal_function_analysis":[],"custom_pcrs":[],"custom_presence_dun_matrielle_etranger":[],"custom_blood_analysis":[],"custom_prosthesis_list":[],"custom_rbks":[],"custom_lumbar_punctures":[],"custom_other_biology_list":[],"custom_blood_cultures":[],"custom_ecbcs":[],"custom_bal_bronchoalveolar_fluid":[],"custom_ecbus":[],"custom_devices_kt_probe_":[],"custom_ptp_protected_tracheal_sampling":[],"custom_note":[],"custom_eps":[],"custom_notice_anti_infective_item":[],"custom_inflammatory_assessment_analysis":[],"__last_sync_on":"2025-04-25T08:31:11.025Z","custom_arguments":"<div class=\\"ql-editor read-mode\\"><p>test</p></div>","__unsaved":1}', 'action': 'Save', 'cmd': 'frappe.desk.form.save.savedocs'}
2025-04-25 13:34:27,137 ERROR frappe Could not take error snapshot: (0, '')
Site: aria.localhost
Form Dict: {}
Traceback (most recent call last):
  File "/home/plm/ariasousse/apps/frappe/frappe/app.py", line 99, in application
    init_request(request)
  File "/home/plm/ariasousse/apps/frappe/frappe/app.py", line 195, in init_request
    frappe.local.http_request = HTTPRequest()
  File "/home/plm/ariasousse/apps/frappe/frappe/auth.py", line 44, in __init__
    self.set_session()
  File "/home/plm/ariasousse/apps/frappe/frappe/auth.py", line 78, in set_session
    frappe.local.login_manager = LoginManager()
  File "/home/plm/ariasousse/apps/frappe/frappe/auth.py", line 120, in __init__
    self.make_session(resume=True)
  File "/home/plm/ariasousse/apps/frappe/frappe/auth.py", line 213, in make_session
    frappe.local.session_obj = Session(
  File "/home/plm/ariasousse/apps/frappe/frappe/sessions.py", line 221, in __init__
    self.resume()
  File "/home/plm/ariasousse/apps/frappe/frappe/sessions.py", line 297, in resume
    self.validate_user()
  File "/home/plm/ariasousse/apps/frappe/frappe/sessions.py", line 229, in validate_user
    if not frappe.get_cached_value("User", self.user, "enabled"):
  File "/home/plm/ariasousse/apps/frappe/frappe/__init__.py", line 1221, in get_cached_value
    doc = get_cached_doc(doctype, name)
  File "/home/plm/ariasousse/apps/frappe/frappe/__init__.py", line 1164, in get_cached_doc
    doc = get_doc(*args, **kwargs)
  File "/home/plm/ariasousse/apps/frappe/frappe/__init__.py", line 1290, in get_doc
    doc = frappe.model.document.get_doc(*args, **kwargs)
  File "/home/plm/ariasousse/apps/frappe/frappe/model/document.py", line 85, in get_doc
    return controller(*args, **kwargs)
  File "/home/plm/ariasousse/apps/frappe/frappe/model/document.py", line 126, in __init__
    self.load_from_db()
  File "/home/plm/ariasousse/apps/frappe/frappe/model/document.py", line 151, in load_from_db
    if not getattr(self, "_metaclass", False) and self.meta.issingle:
  File "/usr/lib/python3.10/functools.py", line 981, in __get__
    val = self.func(instance)
  File "/home/plm/ariasousse/apps/frappe/frappe/model/base_document.py", line 142, in meta
    return frappe.get_meta(self.doctype)
  File "/home/plm/ariasousse/apps/frappe/frappe/__init__.py", line 1317, in get_meta
    return frappe.model.meta.get_meta(doctype, cached=cached)
  File "/home/plm/ariasousse/apps/frappe/frappe/model/meta.py", line 63, in get_meta
    meta = Meta(doctype)
  File "/home/plm/ariasousse/apps/frappe/frappe/model/meta.py", line 119, in __init__
    self.process()
  File "/home/plm/ariasousse/apps/frappe/frappe/model/meta.py", line 137, in process
    self.add_custom_fields()
  File "/home/plm/ariasousse/apps/frappe/frappe/model/meta.py", line 346, in add_custom_fields
    custom_fields = frappe.db.get_values(
  File "/home/plm/ariasousse/apps/frappe/frappe/database/database.py", line 619, in get_values
    out = self._get_values_from_table(
  File "/home/plm/ariasousse/apps/frappe/frappe/database/database.py", line 892, in _get_values_from_table
    return query.run(as_dict=as_dict, debug=debug, update=update, run=run, pluck=pluck)
  File "/home/plm/ariasousse/apps/frappe/frappe/query_builder/utils.py", line 87, in execute_query
    result = frappe.db.sql(query, params, *args, **kwargs)  # nosemgrep
  File "/home/plm/ariasousse/apps/frappe/frappe/database/database.py", line 230, in sql
    self._cursor.execute(query, values)
  File "/home/plm/ariasousse/env/lib/python3.10/site-packages/pymysql/cursors.py", line 153, in execute
    result = self._query(query)
  File "/home/plm/ariasousse/env/lib/python3.10/site-packages/pymysql/cursors.py", line 322, in _query
    conn.query(q)
  File "/home/plm/ariasousse/env/lib/python3.10/site-packages/pymysql/connections.py", line 563, in query
    self._affected_rows = self._read_query_result(unbuffered=unbuffered)
  File "/home/plm/ariasousse/env/lib/python3.10/site-packages/pymysql/connections.py", line 825, in _read_query_result
    result.read()
  File "/home/plm/ariasousse/env/lib/python3.10/site-packages/pymysql/connections.py", line 1199, in read
    first_packet = self.connection._read_packet()
  File "/home/plm/ariasousse/env/lib/python3.10/site-packages/pymysql/connections.py", line 744, in _read_packet
    packet_header = self._read_bytes(4)
  File "/home/plm/ariasousse/env/lib/python3.10/site-packages/pymysql/connections.py", line 798, in _read_bytes
    raise err.OperationalError(
pymysql.err.OperationalError: (2013, 'Lost connection to MySQL server during query')

During handling of the above exception, another exception occurred:

Traceback (most recent call last):
  File "/home/plm/ariasousse/apps/frappe/frappe/utils/error.py", line 86, in log_error_snapshot
    log_error(title=str(exception), defer_insert=True)
  File "/home/plm/ariasousse/apps/frappe/frappe/utils/error.py", line 61, in log_error
    error_log = frappe.get_doc(
  File "/home/plm/ariasousse/apps/frappe/frappe/__init__.py", line 1290, in get_doc
    doc = frappe.model.document.get_doc(*args, **kwargs)
  File "/home/plm/ariasousse/apps/frappe/frappe/model/document.py", line 83, in get_doc
    controller = get_controller(doctype)
  File "/home/plm/ariasousse/apps/frappe/frappe/model/base_document.py", line 70, in get_controller
    site_controllers[doctype] = import_controller(doctype)
  File "/home/plm/ariasousse/apps/frappe/frappe/model/base_document.py", line 81, in import_controller
    doctype_info = frappe.db.get_value("DocType", doctype, fieldname="*")
  File "/home/plm/ariasousse/apps/frappe/frappe/database/database.py", line 515, in get_value
    result = self.get_values(
  File "/home/plm/ariasousse/apps/frappe/frappe/database/database.py", line 619, in get_values
    out = self._get_values_from_table(
  File "/home/plm/ariasousse/apps/frappe/frappe/database/database.py", line 892, in _get_values_from_table
    return query.run(as_dict=as_dict, debug=debug, update=update, run=run, pluck=pluck)
  File "/home/plm/ariasousse/apps/frappe/frappe/query_builder/utils.py", line 87, in execute_query
    result = frappe.db.sql(query, params, *args, **kwargs)  # nosemgrep
  File "/home/plm/ariasousse/apps/frappe/frappe/database/database.py", line 230, in sql
    self._cursor.execute(query, values)
  File "/home/plm/ariasousse/env/lib/python3.10/site-packages/pymysql/cursors.py", line 153, in execute
    result = self._query(query)
  File "/home/plm/ariasousse/env/lib/python3.10/site-packages/pymysql/cursors.py", line 322, in _query
    conn.query(q)
  File "/home/plm/ariasousse/env/lib/python3.10/site-packages/pymysql/connections.py", line 562, in query
    self._execute_command(COMMAND.COM_QUERY, sql)
  File "/home/plm/ariasousse/env/lib/python3.10/site-packages/pymysql/connections.py", line 843, in _execute_command
    raise err.InterfaceError(0, "")
pymysql.err.InterfaceError: (0, '')
2025-04-25 13:34:29,758 ERROR frappe Could not take error snapshot: (2003, "Can't connect to MySQL server on '127.0.0.1' ([Errno 111] Connection refused)")
Site: aria.localhost
Form Dict: {'doctype': 'User Permission', 'fields': '["`tabUser Permission`.`name`","`tabUser Permission`.`owner`","`tabUser Permission`.`creation`","`tabUser Permission`.`modified`","`tabUser Permission`.`modified_by`","`tabUser Permission`.`_user_tags`","`tabUser Permission`.`_comments`","`tabUser Permission`.`_assign`","`tabUser Permission`.`_liked_by`","`tabUser Permission`.`docstatus`","`tabUser Permission`.`idx`","`tabUser Permission`.`user`","`tabUser Permission`.`allow`","`tabUser Permission`.`for_value`","`tabUser Permission`.`applicable_for`"]', 'filters': '[["User Permission","user","=","expert@linca.com"]]', 'order_by': '`tabUser Permission`.`modified` desc', 'start': '0', 'page_length': '20', 'view': 'List', 'group_by': '', 'with_comment_count': '1'}
Traceback (most recent call last):
  File "/home/plm/ariasousse/env/lib/python3.10/site-packages/pymysql/connections.py", line 649, in connect
    sock = socket.create_connection(
  File "/usr/lib/python3.10/socket.py", line 845, in create_connection
    raise err
  File "/usr/lib/python3.10/socket.py", line 833, in create_connection
    sock.connect(sa)
ConnectionRefusedError: [Errno 111] Connection refused

During handling of the above exception, another exception occurred:

Traceback (most recent call last):
  File "/home/plm/ariasousse/apps/frappe/frappe/app.py", line 99, in application
    init_request(request)
  File "/home/plm/ariasousse/apps/frappe/frappe/app.py", line 195, in init_request
    frappe.local.http_request = HTTPRequest()
  File "/home/plm/ariasousse/apps/frappe/frappe/auth.py", line 44, in __init__
    self.set_session()
  File "/home/plm/ariasousse/apps/frappe/frappe/auth.py", line 78, in set_session
    frappe.local.login_manager = LoginManager()
  File "/home/plm/ariasousse/apps/frappe/frappe/auth.py", line 120, in __init__
    self.make_session(resume=True)
  File "/home/plm/ariasousse/apps/frappe/frappe/auth.py", line 213, in make_session
    frappe.local.session_obj = Session(
  File "/home/plm/ariasousse/apps/frappe/frappe/sessions.py", line 221, in __init__
    self.resume()
  File "/home/plm/ariasousse/apps/frappe/frappe/sessions.py", line 292, in resume
    data = self.get_session_record()
  File "/home/plm/ariasousse/apps/frappe/frappe/sessions.py", line 310, in get_session_record
    r = self.get_session_data()
  File "/home/plm/ariasousse/apps/frappe/frappe/sessions.py", line 327, in get_session_data
    data = self.get_session_data_from_db()
  File "/home/plm/ariasousse/apps/frappe/frappe/sessions.py", line 356, in get_session_data_from_db
    ).run()
  File "/home/plm/ariasousse/apps/frappe/frappe/query_builder/utils.py", line 87, in execute_query
    result = frappe.db.sql(query, params, *args, **kwargs)  # nosemgrep
  File "/home/plm/ariasousse/apps/frappe/frappe/database/database.py", line 207, in sql
    self.connect()
  File "/home/plm/ariasousse/apps/frappe/frappe/database/database.py", line 112, in connect
    self._conn: "MariadbConnection" | "PostgresConnection" = self.get_connection()
  File "/home/plm/ariasousse/apps/frappe/frappe/database/mariadb/database.py", line 107, in get_connection
    conn = self._get_connection()
  File "/home/plm/ariasousse/apps/frappe/frappe/database/mariadb/database.py", line 113, in _get_connection
    return self.create_connection()
  File "/home/plm/ariasousse/apps/frappe/frappe/database/mariadb/database.py", line 116, in create_connection
    return pymysql.connect(**self.get_connection_settings())
  File "/home/plm/ariasousse/env/lib/python3.10/site-packages/pymysql/connections.py", line 361, in __init__
    self.connect()
  File "/home/plm/ariasousse/env/lib/python3.10/site-packages/pymysql/connections.py", line 716, in connect
    raise exc
pymysql.err.OperationalError: (2003, "Can't connect to MySQL server on '127.0.0.1' ([Errno 111] Connection refused)")

During handling of the above exception, another exception occurred:

Traceback (most recent call last):
  File "/home/plm/ariasousse/env/lib/python3.10/site-packages/pymysql/connections.py", line 649, in connect
    sock = socket.create_connection(
  File "/usr/lib/python3.10/socket.py", line 845, in create_connection
    raise err
  File "/usr/lib/python3.10/socket.py", line 833, in create_connection
    sock.connect(sa)
ConnectionRefusedError: [Errno 111] Connection refused

During handling of the above exception, another exception occurred:

Traceback (most recent call last):
  File "/home/plm/ariasousse/apps/frappe/frappe/utils/error.py", line 86, in log_error_snapshot
    log_error(title=str(exception), defer_insert=True)
  File "/home/plm/ariasousse/apps/frappe/frappe/utils/error.py", line 61, in log_error
    error_log = frappe.get_doc(
  File "/home/plm/ariasousse/apps/frappe/frappe/__init__.py", line 1290, in get_doc
    doc = frappe.model.document.get_doc(*args, **kwargs)
  File "/home/plm/ariasousse/apps/frappe/frappe/model/document.py", line 83, in get_doc
    controller = get_controller(doctype)
  File "/home/plm/ariasousse/apps/frappe/frappe/model/base_document.py", line 70, in get_controller
    site_controllers[doctype] = import_controller(doctype)
  File "/home/plm/ariasousse/apps/frappe/frappe/model/base_document.py", line 81, in import_controller
    doctype_info = frappe.db.get_value("DocType", doctype, fieldname="*")
  File "/home/plm/ariasousse/apps/frappe/frappe/database/database.py", line 515, in get_value
    result = self.get_values(
  File "/home/plm/ariasousse/apps/frappe/frappe/database/database.py", line 619, in get_values
    out = self._get_values_from_table(
  File "/home/plm/ariasousse/apps/frappe/frappe/database/database.py", line 892, in _get_values_from_table
    return query.run(as_dict=as_dict, debug=debug, update=update, run=run, pluck=pluck)
  File "/home/plm/ariasousse/apps/frappe/frappe/query_builder/utils.py", line 87, in execute_query
    result = frappe.db.sql(query, params, *args, **kwargs)  # nosemgrep
  File "/home/plm/ariasousse/apps/frappe/frappe/database/database.py", line 207, in sql
    self.connect()
  File "/home/plm/ariasousse/apps/frappe/frappe/database/database.py", line 112, in connect
    self._conn: "MariadbConnection" | "PostgresConnection" = self.get_connection()
  File "/home/plm/ariasousse/apps/frappe/frappe/database/mariadb/database.py", line 107, in get_connection
    conn = self._get_connection()
  File "/home/plm/ariasousse/apps/frappe/frappe/database/mariadb/database.py", line 113, in _get_connection
    return self.create_connection()
  File "/home/plm/ariasousse/apps/frappe/frappe/database/mariadb/database.py", line 116, in create_connection
    return pymysql.connect(**self.get_connection_settings())
  File "/home/plm/ariasousse/env/lib/python3.10/site-packages/pymysql/connections.py", line 361, in __init__
    self.connect()
  File "/home/plm/ariasousse/env/lib/python3.10/site-packages/pymysql/connections.py", line 716, in connect
    raise exc
pymysql.err.OperationalError: (2003, "Can't connect to MySQL server on '127.0.0.1' ([Errno 111] Connection refused)")
2025-04-25 13:34:40,834 ERROR frappe Could not take error snapshot: (2003, "Can't connect to MySQL server on '127.0.0.1' ([Errno 111] Connection refused)")
Site: aria.localhost
Form Dict: {'doctype': 'User', 'fields': '["`tabUser`.`name`","`tabUser`.`owner`","`tabUser`.`creation`","`tabUser`.`modified`","`tabUser`.`modified_by`","`tabUser`.`_user_tags`","`tabUser`.`_comments`","`tabUser`.`_assign`","`tabUser`.`_liked_by`","`tabUser`.`docstatus`","`tabUser`.`idx`","`tabUser`.`user_type`","`tabUser`.`full_name`","`tabUser`.`user_image`","`tabUser`.`enabled`"]', 'filters': '[]', 'order_by': '`tabUser`.`modified` desc', 'start': '0', 'page_length': '20', 'view': 'List', 'group_by': '', 'with_comment_count': '1'}
Traceback (most recent call last):
  File "/home/plm/ariasousse/env/lib/python3.10/site-packages/pymysql/connections.py", line 649, in connect
    sock = socket.create_connection(
  File "/usr/lib/python3.10/socket.py", line 845, in create_connection
    raise err
  File "/usr/lib/python3.10/socket.py", line 833, in create_connection
    sock.connect(sa)
ConnectionRefusedError: [Errno 111] Connection refused

During handling of the above exception, another exception occurred:

Traceback (most recent call last):
  File "/home/plm/ariasousse/apps/frappe/frappe/app.py", line 99, in application
    init_request(request)
  File "/home/plm/ariasousse/apps/frappe/frappe/app.py", line 195, in init_request
    frappe.local.http_request = HTTPRequest()
  File "/home/plm/ariasousse/apps/frappe/frappe/auth.py", line 44, in __init__
    self.set_session()
  File "/home/plm/ariasousse/apps/frappe/frappe/auth.py", line 78, in set_session
    frappe.local.login_manager = LoginManager()
  File "/home/plm/ariasousse/apps/frappe/frappe/auth.py", line 120, in __init__
    self.make_session(resume=True)
  File "/home/plm/ariasousse/apps/frappe/frappe/auth.py", line 213, in make_session
    frappe.local.session_obj = Session(
  File "/home/plm/ariasousse/apps/frappe/frappe/sessions.py", line 221, in __init__
    self.resume()
  File "/home/plm/ariasousse/apps/frappe/frappe/sessions.py", line 292, in resume
    data = self.get_session_record()
  File "/home/plm/ariasousse/apps/frappe/frappe/sessions.py", line 310, in get_session_record
    r = self.get_session_data()
  File "/home/plm/ariasousse/apps/frappe/frappe/sessions.py", line 327, in get_session_data
    data = self.get_session_data_from_db()
  File "/home/plm/ariasousse/apps/frappe/frappe/sessions.py", line 356, in get_session_data_from_db
    ).run()
  File "/home/plm/ariasousse/apps/frappe/frappe/query_builder/utils.py", line 87, in execute_query
    result = frappe.db.sql(query, params, *args, **kwargs)  # nosemgrep
  File "/home/plm/ariasousse/apps/frappe/frappe/database/database.py", line 207, in sql
    self.connect()
  File "/home/plm/ariasousse/apps/frappe/frappe/database/database.py", line 112, in connect
    self._conn: "MariadbConnection" | "PostgresConnection" = self.get_connection()
  File "/home/plm/ariasousse/apps/frappe/frappe/database/mariadb/database.py", line 107, in get_connection
    conn = self._get_connection()
  File "/home/plm/ariasousse/apps/frappe/frappe/database/mariadb/database.py", line 113, in _get_connection
    return self.create_connection()
  File "/home/plm/ariasousse/apps/frappe/frappe/database/mariadb/database.py", line 116, in create_connection
    return pymysql.connect(**self.get_connection_settings())
  File "/home/plm/ariasousse/env/lib/python3.10/site-packages/pymysql/connections.py", line 361, in __init__
    self.connect()
  File "/home/plm/ariasousse/env/lib/python3.10/site-packages/pymysql/connections.py", line 716, in connect
    raise exc
pymysql.err.OperationalError: (2003, "Can't connect to MySQL server on '127.0.0.1' ([Errno 111] Connection refused)")

During handling of the above exception, another exception occurred:

Traceback (most recent call last):
  File "/home/plm/ariasousse/env/lib/python3.10/site-packages/pymysql/connections.py", line 649, in connect
    sock = socket.create_connection(
  File "/usr/lib/python3.10/socket.py", line 845, in create_connection
    raise err
  File "/usr/lib/python3.10/socket.py", line 833, in create_connection
    sock.connect(sa)
ConnectionRefusedError: [Errno 111] Connection refused

During handling of the above exception, another exception occurred:

Traceback (most recent call last):
  File "/home/plm/ariasousse/apps/frappe/frappe/utils/error.py", line 86, in log_error_snapshot
    log_error(title=str(exception), defer_insert=True)
  File "/home/plm/ariasousse/apps/frappe/frappe/utils/error.py", line 61, in log_error
    error_log = frappe.get_doc(
  File "/home/plm/ariasousse/apps/frappe/frappe/__init__.py", line 1290, in get_doc
    doc = frappe.model.document.get_doc(*args, **kwargs)
  File "/home/plm/ariasousse/apps/frappe/frappe/model/document.py", line 83, in get_doc
    controller = get_controller(doctype)
  File "/home/plm/ariasousse/apps/frappe/frappe/model/base_document.py", line 70, in get_controller
    site_controllers[doctype] = import_controller(doctype)
  File "/home/plm/ariasousse/apps/frappe/frappe/model/base_document.py", line 81, in import_controller
    doctype_info = frappe.db.get_value("DocType", doctype, fieldname="*")
  File "/home/plm/ariasousse/apps/frappe/frappe/database/database.py", line 515, in get_value
    result = self.get_values(
  File "/home/plm/ariasousse/apps/frappe/frappe/database/database.py", line 619, in get_values
    out = self._get_values_from_table(
  File "/home/plm/ariasousse/apps/frappe/frappe/database/database.py", line 892, in _get_values_from_table
    return query.run(as_dict=as_dict, debug=debug, update=update, run=run, pluck=pluck)
  File "/home/plm/ariasousse/apps/frappe/frappe/query_builder/utils.py", line 87, in execute_query
    result = frappe.db.sql(query, params, *args, **kwargs)  # nosemgrep
  File "/home/plm/ariasousse/apps/frappe/frappe/database/database.py", line 207, in sql
    self.connect()
  File "/home/plm/ariasousse/apps/frappe/frappe/database/database.py", line 112, in connect
    self._conn: "MariadbConnection" | "PostgresConnection" = self.get_connection()
  File "/home/plm/ariasousse/apps/frappe/frappe/database/mariadb/database.py", line 107, in get_connection
    conn = self._get_connection()
  File "/home/plm/ariasousse/apps/frappe/frappe/database/mariadb/database.py", line 113, in _get_connection
    return self.create_connection()
  File "/home/plm/ariasousse/apps/frappe/frappe/database/mariadb/database.py", line 116, in create_connection
    return pymysql.connect(**self.get_connection_settings())
  File "/home/plm/ariasousse/env/lib/python3.10/site-packages/pymysql/connections.py", line 361, in __init__
    self.connect()
  File "/home/plm/ariasousse/env/lib/python3.10/site-packages/pymysql/connections.py", line 716, in connect
    raise exc
pymysql.err.OperationalError: (2003, "Can't connect to MySQL server on '127.0.0.1' ([Errno 111] Connection refused)")
2025-04-28 11:04:35,090 ERROR frappe New Exception collected in error log
Site: aria.localhost
Form Dict: {'doc_data': '{"docstatus":0,"doctype":"Patient et demande","name":"new-patient-et-demande-wjuhhlxoft","__islocal":1,"__unsaved":1,"owner":"maher.amamou@protonmail.com","custom_modification_count":0,"status":"Draft","on_demande_un_aide_au_diag":0,"on_demande_une_aide_thérapeutique":0,"on_demande_un_transfer_a_votre_service":0,"on_demande_un_conseil_de_preventionvaccination":0,"autre_apréciser":0,"votre_patient__a_été":0,"votre_patient":0,"votre_patient_2":0,"oui":0,"non":0,"allergie_aux_bétalacamines__penicillines":0,"autre_type_allergie":0,"custom_bladder_catheter":0,"custom_presence_dun_matrielle_etranger":[],"custom_notice_anti_infective_item":[],"custom_blood_analysis":[],"custom_renal_function_analysis":[],"custom_liver_function_analysis":[],"custom_inflammatory_assessment_analysis":[],"custom_other_biology_list":[],"custom_blood_cultures":[],"custom_ecbus":[],"custom_lumbar_punctures":[],"custom_stool_cultures":[],"custom_ecbcs":[],"custom_bal_bronchoalveolar_fluid":[],"custom_ptp_protected_tracheal_sampling":[],"custom_rbks":[],"custom_eps":[],"custom_superficial_puses":[],"custom_deep_puses":[],"custom_prosthesis_list":[],"custom_devices_kt_probe_":[],"custom_serologies":[],"custom_pcrs":[],"custom_note":[],"dr":"maher","custom_doctor_grade":"","custom_doctor_phone_number":""}', 'cmd': 'linca.utils.data.get_test_template'}
2025-04-28 11:06:05,760 ERROR frappe New Exception collected in error log
Site: aria.localhost
Form Dict: {'doc_data': '{"docstatus":0,"doctype":"Patient et demande","name":"new-patient-et-demande-wjuhhlxoft","__islocal":1,"__unsaved":1,"owner":"maher.amamou@protonmail.com","custom_modification_count":0,"status":"Draft","on_demande_un_aide_au_diag":0,"on_demande_une_aide_thérapeutique":0,"on_demande_un_transfer_a_votre_service":0,"on_demande_un_conseil_de_preventionvaccination":0,"autre_apréciser":0,"votre_patient__a_été":0,"votre_patient":0,"votre_patient_2":0,"oui":0,"non":0,"allergie_aux_bétalacamines__penicillines":0,"autre_type_allergie":0,"custom_bladder_catheter":0,"custom_presence_dun_matrielle_etranger":[],"custom_notice_anti_infective_item":[],"custom_blood_analysis":[],"custom_renal_function_analysis":[],"custom_liver_function_analysis":[],"custom_inflammatory_assessment_analysis":[],"custom_other_biology_list":[],"custom_blood_cultures":[],"custom_ecbus":[{"docstatus":0,"doctype":"Notice ECBU Item","name":"new-notice-ecbu-item-xrzwaszgvz","__islocal":1,"__unsaved":1,"owner":"maher.amamou@protonmail.com","white_blood_cells_unit":"/mm3","red_blood_cells_unit":"/mm3","state_culture":"","parent":"new-patient-et-demande-wjuhhlxoft","parentfield":"custom_ecbus","parenttype":"Patient et demande","idx":1,"__unedited":false,"analysis_date":"2025-04-02","white_blood_cells":50,"red_blood_cells":2}],"custom_lumbar_punctures":[],"custom_stool_cultures":[],"custom_ecbcs":[],"custom_bal_bronchoalveolar_fluid":[],"custom_ptp_protected_tracheal_sampling":[],"custom_rbks":[],"custom_eps":[],"custom_superficial_puses":[],"custom_deep_puses":[],"custom_prosthesis_list":[],"custom_devices_kt_probe_":[],"custom_serologies":[],"custom_pcrs":[],"custom_note":[],"dr":"maher","custom_doctor_grade":"","custom_doctor_phone_number":"","custom_microbiological_examination_done_yes":1,"custom_ecbu":1,"custom_number_of_ecbu":1,"custom_radiological_examination_done_yes":1,"custom_patient_history":"ùùù"}', 'cmd': 'linca.utils.data.get_test_template'}
2025-04-28 14:21:11,696 ERROR frappe New Exception collected in error log
Site: aria.localhost
Form Dict: {'doctype': 'User', 'fields': '["`tabUser`.`name`","`tabUser`.`owner`","`tabUser`.`creation`","`tabUser`.`modified`","`tabUser`.`modified_by`","`tabUser`.`_user_tags`","`tabUser`.`_comments`","`tabUser`.`_assign`","`tabUser`.`_liked_by`","`tabUser`.`docstatus`","`tabUser`.`idx`","`tabUser`.`user_type`","`tabUser`.`full_name`","`tabUser`.`user_image`","`tabUser`.`enabled`"]', 'filters': '[]', 'order_by': '`tabUser`.`modified` desc', 'start': '0', 'page_length': '20', 'view': 'List', 'group_by': '', 'with_comment_count': '1', 'cmd': 'frappe.desk.reportview.get'}
2025-04-28 14:25:11,756 ERROR frappe New Exception collected in error log
Site: aria.localhost
Form Dict: {'doctype': 'User', 'fields': '["`tabUser`.`name`","`tabUser`.`owner`","`tabUser`.`creation`","`tabUser`.`modified`","`tabUser`.`modified_by`","`tabUser`.`_user_tags`","`tabUser`.`_comments`","`tabUser`.`_assign`","`tabUser`.`_liked_by`","`tabUser`.`docstatus`","`tabUser`.`idx`","`tabUser`.`user_type`","`tabUser`.`full_name`","`tabUser`.`user_image`","`tabUser`.`enabled`"]', 'filters': '[]', 'order_by': '`tabUser`.`modified` desc', 'start': '0', 'page_length': '20', 'view': 'List', 'group_by': '', 'with_comment_count': '1', 'cmd': 'frappe.desk.reportview.get'}
2025-04-28 14:30:12,373 ERROR frappe Could not take error snapshot: (2003, "Can't connect to MySQL server on '127.0.0.1' ([Errno 111] Connection refused)")
Site: aria.localhost
Form Dict: {'doctype': 'User', 'fields': '["`tabUser`.`name`","`tabUser`.`owner`","`tabUser`.`creation`","`tabUser`.`modified`","`tabUser`.`modified_by`","`tabUser`.`_user_tags`","`tabUser`.`_comments`","`tabUser`.`_assign`","`tabUser`.`_liked_by`","`tabUser`.`docstatus`","`tabUser`.`idx`","`tabUser`.`user_type`","`tabUser`.`full_name`","`tabUser`.`user_image`","`tabUser`.`enabled`"]', 'filters': '[]', 'order_by': '`tabUser`.`modified` desc', 'start': '0', 'page_length': '20', 'view': 'List', 'group_by': '', 'with_comment_count': '1', 'cmd': 'frappe.desk.reportview.get'}
Traceback (most recent call last):
  File "/home/plm/ariasousse/env/lib/python3.10/site-packages/pymysql/connections.py", line 649, in connect
    sock = socket.create_connection(
  File "/usr/lib/python3.10/socket.py", line 845, in create_connection
    raise err
  File "/usr/lib/python3.10/socket.py", line 833, in create_connection
    sock.connect(sa)
ConnectionRefusedError: [Errno 111] Connection refused

During handling of the above exception, another exception occurred:

Traceback (most recent call last):
  File "/home/plm/ariasousse/apps/frappe/frappe/app.py", line 114, in application
    response = frappe.api.handle(request)
  File "/home/plm/ariasousse/apps/frappe/frappe/api/__init__.py", line 49, in handle
    data = endpoint(**arguments)
  File "/home/plm/ariasousse/apps/frappe/frappe/api/v1.py", line 36, in handle_rpc_call
    return frappe.handler.handle()
  File "/home/plm/ariasousse/apps/frappe/frappe/handler.py", line 49, in handle
    data = execute_cmd(cmd)
  File "/home/plm/ariasousse/apps/frappe/frappe/handler.py", line 85, in execute_cmd
    return frappe.call(method, **frappe.form_dict)
  File "/home/plm/ariasousse/apps/frappe/frappe/__init__.py", line 1725, in call
    return fn(*args, **newargs)
  File "/home/plm/ariasousse/apps/frappe/frappe/utils/typing_validations.py", line 31, in wrapper
    return func(*args, **kwargs)
  File "/home/plm/ariasousse/apps/frappe/frappe/__init__.py", line 878, in wrapper_fn
    retval = fn(*args, **get_newargs(fn, kwargs))
  File "/home/plm/ariasousse/apps/frappe/frappe/desk/reportview.py", line 32, in get
    data = compress(execute(**args), args=args)
  File "/home/plm/ariasousse/apps/frappe/frappe/desk/reportview.py", line 78, in execute
    return DatabaseQuery(doctype).execute(*args, **kwargs)
  File "/home/plm/ariasousse/apps/frappe/frappe/model/db_query.py", line 191, in execute
    result = self.build_and_run()
  File "/home/plm/ariasousse/apps/frappe/frappe/model/db_query.py", line 232, in build_and_run
    return frappe.db.sql(
  File "/home/plm/ariasousse/apps/frappe/frappe/database/database.py", line 207, in sql
    self.connect()
  File "/home/plm/ariasousse/apps/frappe/frappe/database/database.py", line 112, in connect
    self._conn: "MariadbConnection" | "PostgresConnection" = self.get_connection()
  File "/home/plm/ariasousse/apps/frappe/frappe/database/mariadb/database.py", line 107, in get_connection
    conn = self._get_connection()
  File "/home/plm/ariasousse/apps/frappe/frappe/database/mariadb/database.py", line 113, in _get_connection
    return self.create_connection()
  File "/home/plm/ariasousse/apps/frappe/frappe/database/mariadb/database.py", line 116, in create_connection
    return pymysql.connect(**self.get_connection_settings())
  File "/home/plm/ariasousse/env/lib/python3.10/site-packages/pymysql/connections.py", line 361, in __init__
    self.connect()
  File "/home/plm/ariasousse/env/lib/python3.10/site-packages/pymysql/connections.py", line 716, in connect
    raise exc
pymysql.err.OperationalError: (2003, "Can't connect to MySQL server on '127.0.0.1' ([Errno 111] Connection refused)")

During handling of the above exception, another exception occurred:

Traceback (most recent call last):
  File "/home/plm/ariasousse/env/lib/python3.10/site-packages/pymysql/connections.py", line 649, in connect
    sock = socket.create_connection(
  File "/usr/lib/python3.10/socket.py", line 845, in create_connection
    raise err
  File "/usr/lib/python3.10/socket.py", line 833, in create_connection
    sock.connect(sa)
ConnectionRefusedError: [Errno 111] Connection refused

During handling of the above exception, another exception occurred:

Traceback (most recent call last):
  File "/home/plm/ariasousse/apps/frappe/frappe/utils/error.py", line 86, in log_error_snapshot
    log_error(title=str(exception), defer_insert=True)
  File "/home/plm/ariasousse/apps/frappe/frappe/utils/error.py", line 61, in log_error
    error_log = frappe.get_doc(
  File "/home/plm/ariasousse/apps/frappe/frappe/__init__.py", line 1290, in get_doc
    doc = frappe.model.document.get_doc(*args, **kwargs)
  File "/home/plm/ariasousse/apps/frappe/frappe/model/document.py", line 83, in get_doc
    controller = get_controller(doctype)
  File "/home/plm/ariasousse/apps/frappe/frappe/model/base_document.py", line 70, in get_controller
    site_controllers[doctype] = import_controller(doctype)
  File "/home/plm/ariasousse/apps/frappe/frappe/model/base_document.py", line 81, in import_controller
    doctype_info = frappe.db.get_value("DocType", doctype, fieldname="*")
  File "/home/plm/ariasousse/apps/frappe/frappe/database/database.py", line 515, in get_value
    result = self.get_values(
  File "/home/plm/ariasousse/apps/frappe/frappe/database/database.py", line 619, in get_values
    out = self._get_values_from_table(
  File "/home/plm/ariasousse/apps/frappe/frappe/database/database.py", line 892, in _get_values_from_table
    return query.run(as_dict=as_dict, debug=debug, update=update, run=run, pluck=pluck)
  File "/home/plm/ariasousse/apps/frappe/frappe/query_builder/utils.py", line 87, in execute_query
    result = frappe.db.sql(query, params, *args, **kwargs)  # nosemgrep
  File "/home/plm/ariasousse/apps/frappe/frappe/database/database.py", line 207, in sql
    self.connect()
  File "/home/plm/ariasousse/apps/frappe/frappe/database/database.py", line 112, in connect
    self._conn: "MariadbConnection" | "PostgresConnection" = self.get_connection()
  File "/home/plm/ariasousse/apps/frappe/frappe/database/mariadb/database.py", line 107, in get_connection
    conn = self._get_connection()
  File "/home/plm/ariasousse/apps/frappe/frappe/database/mariadb/database.py", line 113, in _get_connection
    return self.create_connection()
  File "/home/plm/ariasousse/apps/frappe/frappe/database/mariadb/database.py", line 116, in create_connection
    return pymysql.connect(**self.get_connection_settings())
  File "/home/plm/ariasousse/env/lib/python3.10/site-packages/pymysql/connections.py", line 361, in __init__
    self.connect()
  File "/home/plm/ariasousse/env/lib/python3.10/site-packages/pymysql/connections.py", line 716, in connect
    raise exc
pymysql.err.OperationalError: (2003, "Can't connect to MySQL server on '127.0.0.1' ([Errno 111] Connection refused)")
2025-04-28 14:35:15,368 ERROR frappe Could not take error snapshot: (2003, "Can't connect to MySQL server on '127.0.0.1' ([Errno 111] Connection refused)")
Site: aria.localhost
Form Dict: {'doctype': 'User', 'fields': '["`tabUser`.`name`","`tabUser`.`owner`","`tabUser`.`creation`","`tabUser`.`modified`","`tabUser`.`modified_by`","`tabUser`.`_user_tags`","`tabUser`.`_comments`","`tabUser`.`_assign`","`tabUser`.`_liked_by`","`tabUser`.`docstatus`","`tabUser`.`idx`","`tabUser`.`user_type`","`tabUser`.`full_name`","`tabUser`.`user_image`","`tabUser`.`enabled`"]', 'filters': '[]', 'order_by': '`tabUser`.`modified` desc', 'start': '0', 'page_length': '20', 'view': 'List', 'group_by': '', 'with_comment_count': '1', 'cmd': 'frappe.desk.reportview.get'}
Traceback (most recent call last):
  File "/home/plm/ariasousse/env/lib/python3.10/site-packages/pymysql/connections.py", line 649, in connect
    sock = socket.create_connection(
  File "/usr/lib/python3.10/socket.py", line 845, in create_connection
    raise err
  File "/usr/lib/python3.10/socket.py", line 833, in create_connection
    sock.connect(sa)
ConnectionRefusedError: [Errno 111] Connection refused

During handling of the above exception, another exception occurred:

Traceback (most recent call last):
  File "/home/plm/ariasousse/apps/frappe/frappe/app.py", line 114, in application
    response = frappe.api.handle(request)
  File "/home/plm/ariasousse/apps/frappe/frappe/api/__init__.py", line 49, in handle
    data = endpoint(**arguments)
  File "/home/plm/ariasousse/apps/frappe/frappe/api/v1.py", line 36, in handle_rpc_call
    return frappe.handler.handle()
  File "/home/plm/ariasousse/apps/frappe/frappe/handler.py", line 49, in handle
    data = execute_cmd(cmd)
  File "/home/plm/ariasousse/apps/frappe/frappe/handler.py", line 85, in execute_cmd
    return frappe.call(method, **frappe.form_dict)
  File "/home/plm/ariasousse/apps/frappe/frappe/__init__.py", line 1725, in call
    return fn(*args, **newargs)
  File "/home/plm/ariasousse/apps/frappe/frappe/utils/typing_validations.py", line 31, in wrapper
    return func(*args, **kwargs)
  File "/home/plm/ariasousse/apps/frappe/frappe/__init__.py", line 878, in wrapper_fn
    retval = fn(*args, **get_newargs(fn, kwargs))
  File "/home/plm/ariasousse/apps/frappe/frappe/desk/reportview.py", line 32, in get
    data = compress(execute(**args), args=args)
  File "/home/plm/ariasousse/apps/frappe/frappe/desk/reportview.py", line 78, in execute
    return DatabaseQuery(doctype).execute(*args, **kwargs)
  File "/home/plm/ariasousse/apps/frappe/frappe/model/db_query.py", line 191, in execute
    result = self.build_and_run()
  File "/home/plm/ariasousse/apps/frappe/frappe/model/db_query.py", line 232, in build_and_run
    return frappe.db.sql(
  File "/home/plm/ariasousse/apps/frappe/frappe/database/database.py", line 207, in sql
    self.connect()
  File "/home/plm/ariasousse/apps/frappe/frappe/database/database.py", line 112, in connect
    self._conn: "MariadbConnection" | "PostgresConnection" = self.get_connection()
  File "/home/plm/ariasousse/apps/frappe/frappe/database/mariadb/database.py", line 107, in get_connection
    conn = self._get_connection()
  File "/home/plm/ariasousse/apps/frappe/frappe/database/mariadb/database.py", line 113, in _get_connection
    return self.create_connection()
  File "/home/plm/ariasousse/apps/frappe/frappe/database/mariadb/database.py", line 116, in create_connection
    return pymysql.connect(**self.get_connection_settings())
  File "/home/plm/ariasousse/env/lib/python3.10/site-packages/pymysql/connections.py", line 361, in __init__
    self.connect()
  File "/home/plm/ariasousse/env/lib/python3.10/site-packages/pymysql/connections.py", line 716, in connect
    raise exc
pymysql.err.OperationalError: (2003, "Can't connect to MySQL server on '127.0.0.1' ([Errno 111] Connection refused)")

During handling of the above exception, another exception occurred:

Traceback (most recent call last):
  File "/home/plm/ariasousse/env/lib/python3.10/site-packages/pymysql/connections.py", line 649, in connect
    sock = socket.create_connection(
  File "/usr/lib/python3.10/socket.py", line 845, in create_connection
    raise err
  File "/usr/lib/python3.10/socket.py", line 833, in create_connection
    sock.connect(sa)
ConnectionRefusedError: [Errno 111] Connection refused

During handling of the above exception, another exception occurred:

Traceback (most recent call last):
  File "/home/plm/ariasousse/apps/frappe/frappe/utils/error.py", line 86, in log_error_snapshot
    log_error(title=str(exception), defer_insert=True)
  File "/home/plm/ariasousse/apps/frappe/frappe/utils/error.py", line 61, in log_error
    error_log = frappe.get_doc(
  File "/home/plm/ariasousse/apps/frappe/frappe/__init__.py", line 1290, in get_doc
    doc = frappe.model.document.get_doc(*args, **kwargs)
  File "/home/plm/ariasousse/apps/frappe/frappe/model/document.py", line 83, in get_doc
    controller = get_controller(doctype)
  File "/home/plm/ariasousse/apps/frappe/frappe/model/base_document.py", line 70, in get_controller
    site_controllers[doctype] = import_controller(doctype)
  File "/home/plm/ariasousse/apps/frappe/frappe/model/base_document.py", line 81, in import_controller
    doctype_info = frappe.db.get_value("DocType", doctype, fieldname="*")
  File "/home/plm/ariasousse/apps/frappe/frappe/database/database.py", line 515, in get_value
    result = self.get_values(
  File "/home/plm/ariasousse/apps/frappe/frappe/database/database.py", line 619, in get_values
    out = self._get_values_from_table(
  File "/home/plm/ariasousse/apps/frappe/frappe/database/database.py", line 892, in _get_values_from_table
    return query.run(as_dict=as_dict, debug=debug, update=update, run=run, pluck=pluck)
  File "/home/plm/ariasousse/apps/frappe/frappe/query_builder/utils.py", line 87, in execute_query
    result = frappe.db.sql(query, params, *args, **kwargs)  # nosemgrep
  File "/home/plm/ariasousse/apps/frappe/frappe/database/database.py", line 207, in sql
    self.connect()
  File "/home/plm/ariasousse/apps/frappe/frappe/database/database.py", line 112, in connect
    self._conn: "MariadbConnection" | "PostgresConnection" = self.get_connection()
  File "/home/plm/ariasousse/apps/frappe/frappe/database/mariadb/database.py", line 107, in get_connection
    conn = self._get_connection()
  File "/home/plm/ariasousse/apps/frappe/frappe/database/mariadb/database.py", line 113, in _get_connection
    return self.create_connection()
  File "/home/plm/ariasousse/apps/frappe/frappe/database/mariadb/database.py", line 116, in create_connection
    return pymysql.connect(**self.get_connection_settings())
  File "/home/plm/ariasousse/env/lib/python3.10/site-packages/pymysql/connections.py", line 361, in __init__
    self.connect()
  File "/home/plm/ariasousse/env/lib/python3.10/site-packages/pymysql/connections.py", line 716, in connect
    raise exc
pymysql.err.OperationalError: (2003, "Can't connect to MySQL server on '127.0.0.1' ([Errno 111] Connection refused)")
2025-04-28 14:40:12,249 ERROR frappe New Exception collected in error log
Site: aria.localhost
Form Dict: {'doctype': 'User', 'fields': '["`tabUser`.`name`","`tabUser`.`owner`","`tabUser`.`creation`","`tabUser`.`modified`","`tabUser`.`modified_by`","`tabUser`.`_user_tags`","`tabUser`.`_comments`","`tabUser`.`_assign`","`tabUser`.`_liked_by`","`tabUser`.`docstatus`","`tabUser`.`idx`","`tabUser`.`user_type`","`tabUser`.`full_name`","`tabUser`.`user_image`","`tabUser`.`enabled`"]', 'filters': '[]', 'order_by': '`tabUser`.`modified` desc', 'start': '0', 'page_length': '20', 'view': 'List', 'group_by': '', 'with_comment_count': '1', 'cmd': 'frappe.desk.reportview.get'}
2025-04-28 14:45:11,295 ERROR frappe Could not take error snapshot: (2003, "Can't connect to MySQL server on '127.0.0.1' ([Errno 111] Connection refused)")
Site: aria.localhost
Form Dict: {'doctype': 'User', 'fields': '["`tabUser`.`name`","`tabUser`.`owner`","`tabUser`.`creation`","`tabUser`.`modified`","`tabUser`.`modified_by`","`tabUser`.`_user_tags`","`tabUser`.`_comments`","`tabUser`.`_assign`","`tabUser`.`_liked_by`","`tabUser`.`docstatus`","`tabUser`.`idx`","`tabUser`.`user_type`","`tabUser`.`full_name`","`tabUser`.`user_image`","`tabUser`.`enabled`"]', 'filters': '[]', 'order_by': '`tabUser`.`modified` desc', 'start': '0', 'page_length': '20', 'view': 'List', 'group_by': '', 'with_comment_count': '1', 'cmd': 'frappe.desk.reportview.get'}
Traceback (most recent call last):
  File "/home/plm/ariasousse/env/lib/python3.10/site-packages/pymysql/connections.py", line 649, in connect
    sock = socket.create_connection(
  File "/usr/lib/python3.10/socket.py", line 845, in create_connection
    raise err
  File "/usr/lib/python3.10/socket.py", line 833, in create_connection
    sock.connect(sa)
ConnectionRefusedError: [Errno 111] Connection refused

During handling of the above exception, another exception occurred:

Traceback (most recent call last):
  File "/home/plm/ariasousse/apps/frappe/frappe/app.py", line 114, in application
    response = frappe.api.handle(request)
  File "/home/plm/ariasousse/apps/frappe/frappe/api/__init__.py", line 49, in handle
    data = endpoint(**arguments)
  File "/home/plm/ariasousse/apps/frappe/frappe/api/v1.py", line 36, in handle_rpc_call
    return frappe.handler.handle()
  File "/home/plm/ariasousse/apps/frappe/frappe/handler.py", line 49, in handle
    data = execute_cmd(cmd)
  File "/home/plm/ariasousse/apps/frappe/frappe/handler.py", line 85, in execute_cmd
    return frappe.call(method, **frappe.form_dict)
  File "/home/plm/ariasousse/apps/frappe/frappe/__init__.py", line 1725, in call
    return fn(*args, **newargs)
  File "/home/plm/ariasousse/apps/frappe/frappe/utils/typing_validations.py", line 31, in wrapper
    return func(*args, **kwargs)
  File "/home/plm/ariasousse/apps/frappe/frappe/__init__.py", line 878, in wrapper_fn
    retval = fn(*args, **get_newargs(fn, kwargs))
  File "/home/plm/ariasousse/apps/frappe/frappe/desk/reportview.py", line 32, in get
    data = compress(execute(**args), args=args)
  File "/home/plm/ariasousse/apps/frappe/frappe/desk/reportview.py", line 78, in execute
    return DatabaseQuery(doctype).execute(*args, **kwargs)
  File "/home/plm/ariasousse/apps/frappe/frappe/model/db_query.py", line 191, in execute
    result = self.build_and_run()
  File "/home/plm/ariasousse/apps/frappe/frappe/model/db_query.py", line 232, in build_and_run
    return frappe.db.sql(
  File "/home/plm/ariasousse/apps/frappe/frappe/database/database.py", line 207, in sql
    self.connect()
  File "/home/plm/ariasousse/apps/frappe/frappe/database/database.py", line 112, in connect
    self._conn: "MariadbConnection" | "PostgresConnection" = self.get_connection()
  File "/home/plm/ariasousse/apps/frappe/frappe/database/mariadb/database.py", line 107, in get_connection
    conn = self._get_connection()
  File "/home/plm/ariasousse/apps/frappe/frappe/database/mariadb/database.py", line 113, in _get_connection
    return self.create_connection()
  File "/home/plm/ariasousse/apps/frappe/frappe/database/mariadb/database.py", line 116, in create_connection
    return pymysql.connect(**self.get_connection_settings())
  File "/home/plm/ariasousse/env/lib/python3.10/site-packages/pymysql/connections.py", line 361, in __init__
    self.connect()
  File "/home/plm/ariasousse/env/lib/python3.10/site-packages/pymysql/connections.py", line 716, in connect
    raise exc
pymysql.err.OperationalError: (2003, "Can't connect to MySQL server on '127.0.0.1' ([Errno 111] Connection refused)")

During handling of the above exception, another exception occurred:

Traceback (most recent call last):
  File "/home/plm/ariasousse/env/lib/python3.10/site-packages/pymysql/connections.py", line 649, in connect
    sock = socket.create_connection(
  File "/usr/lib/python3.10/socket.py", line 845, in create_connection
    raise err
  File "/usr/lib/python3.10/socket.py", line 833, in create_connection
    sock.connect(sa)
ConnectionRefusedError: [Errno 111] Connection refused

During handling of the above exception, another exception occurred:

Traceback (most recent call last):
  File "/home/plm/ariasousse/apps/frappe/frappe/utils/error.py", line 86, in log_error_snapshot
    log_error(title=str(exception), defer_insert=True)
  File "/home/plm/ariasousse/apps/frappe/frappe/utils/error.py", line 61, in log_error
    error_log = frappe.get_doc(
  File "/home/plm/ariasousse/apps/frappe/frappe/__init__.py", line 1290, in get_doc
    doc = frappe.model.document.get_doc(*args, **kwargs)
  File "/home/plm/ariasousse/apps/frappe/frappe/model/document.py", line 83, in get_doc
    controller = get_controller(doctype)
  File "/home/plm/ariasousse/apps/frappe/frappe/model/base_document.py", line 70, in get_controller
    site_controllers[doctype] = import_controller(doctype)
  File "/home/plm/ariasousse/apps/frappe/frappe/model/base_document.py", line 81, in import_controller
    doctype_info = frappe.db.get_value("DocType", doctype, fieldname="*")
  File "/home/plm/ariasousse/apps/frappe/frappe/database/database.py", line 515, in get_value
    result = self.get_values(
  File "/home/plm/ariasousse/apps/frappe/frappe/database/database.py", line 619, in get_values
    out = self._get_values_from_table(
  File "/home/plm/ariasousse/apps/frappe/frappe/database/database.py", line 892, in _get_values_from_table
    return query.run(as_dict=as_dict, debug=debug, update=update, run=run, pluck=pluck)
  File "/home/plm/ariasousse/apps/frappe/frappe/query_builder/utils.py", line 87, in execute_query
    result = frappe.db.sql(query, params, *args, **kwargs)  # nosemgrep
  File "/home/plm/ariasousse/apps/frappe/frappe/database/database.py", line 207, in sql
    self.connect()
  File "/home/plm/ariasousse/apps/frappe/frappe/database/database.py", line 112, in connect
    self._conn: "MariadbConnection" | "PostgresConnection" = self.get_connection()
  File "/home/plm/ariasousse/apps/frappe/frappe/database/mariadb/database.py", line 107, in get_connection
    conn = self._get_connection()
  File "/home/plm/ariasousse/apps/frappe/frappe/database/mariadb/database.py", line 113, in _get_connection
    return self.create_connection()
  File "/home/plm/ariasousse/apps/frappe/frappe/database/mariadb/database.py", line 116, in create_connection
    return pymysql.connect(**self.get_connection_settings())
  File "/home/plm/ariasousse/env/lib/python3.10/site-packages/pymysql/connections.py", line 361, in __init__
    self.connect()
  File "/home/plm/ariasousse/env/lib/python3.10/site-packages/pymysql/connections.py", line 716, in connect
    raise exc
pymysql.err.OperationalError: (2003, "Can't connect to MySQL server on '127.0.0.1' ([Errno 111] Connection refused)")
2025-04-28 14:50:11,427 ERROR frappe New Exception collected in error log
Site: aria.localhost
Form Dict: {'doctype': 'User', 'fields': '["`tabUser`.`name`","`tabUser`.`owner`","`tabUser`.`creation`","`tabUser`.`modified`","`tabUser`.`modified_by`","`tabUser`.`_user_tags`","`tabUser`.`_comments`","`tabUser`.`_assign`","`tabUser`.`_liked_by`","`tabUser`.`docstatus`","`tabUser`.`idx`","`tabUser`.`user_type`","`tabUser`.`full_name`","`tabUser`.`user_image`","`tabUser`.`enabled`"]', 'filters': '[]', 'order_by': '`tabUser`.`modified` desc', 'start': '0', 'page_length': '20', 'view': 'List', 'group_by': '', 'with_comment_count': '1', 'cmd': 'frappe.desk.reportview.get'}
2025-04-28 14:55:12,282 ERROR frappe Could not take error snapshot: (2003, "Can't connect to MySQL server on '127.0.0.1' ([Errno 111] Connection refused)")
Site: aria.localhost
Form Dict: {'doctype': 'User', 'fields': '["`tabUser`.`name`","`tabUser`.`owner`","`tabUser`.`creation`","`tabUser`.`modified`","`tabUser`.`modified_by`","`tabUser`.`_user_tags`","`tabUser`.`_comments`","`tabUser`.`_assign`","`tabUser`.`_liked_by`","`tabUser`.`docstatus`","`tabUser`.`idx`","`tabUser`.`user_type`","`tabUser`.`full_name`","`tabUser`.`user_image`","`tabUser`.`enabled`"]', 'filters': '[]', 'order_by': '`tabUser`.`modified` desc', 'start': '0', 'page_length': '20', 'view': 'List', 'group_by': '', 'with_comment_count': '1', 'cmd': 'frappe.desk.reportview.get'}
Traceback (most recent call last):
  File "/home/plm/ariasousse/env/lib/python3.10/site-packages/pymysql/connections.py", line 649, in connect
    sock = socket.create_connection(
  File "/usr/lib/python3.10/socket.py", line 845, in create_connection
    raise err
  File "/usr/lib/python3.10/socket.py", line 833, in create_connection
    sock.connect(sa)
ConnectionRefusedError: [Errno 111] Connection refused

During handling of the above exception, another exception occurred:

Traceback (most recent call last):
  File "/home/plm/ariasousse/apps/frappe/frappe/app.py", line 114, in application
    response = frappe.api.handle(request)
  File "/home/plm/ariasousse/apps/frappe/frappe/api/__init__.py", line 49, in handle
    data = endpoint(**arguments)
  File "/home/plm/ariasousse/apps/frappe/frappe/api/v1.py", line 36, in handle_rpc_call
    return frappe.handler.handle()
  File "/home/plm/ariasousse/apps/frappe/frappe/handler.py", line 49, in handle
    data = execute_cmd(cmd)
  File "/home/plm/ariasousse/apps/frappe/frappe/handler.py", line 85, in execute_cmd
    return frappe.call(method, **frappe.form_dict)
  File "/home/plm/ariasousse/apps/frappe/frappe/__init__.py", line 1725, in call
    return fn(*args, **newargs)
  File "/home/plm/ariasousse/apps/frappe/frappe/utils/typing_validations.py", line 31, in wrapper
    return func(*args, **kwargs)
  File "/home/plm/ariasousse/apps/frappe/frappe/__init__.py", line 878, in wrapper_fn
    retval = fn(*args, **get_newargs(fn, kwargs))
  File "/home/plm/ariasousse/apps/frappe/frappe/desk/reportview.py", line 32, in get
    data = compress(execute(**args), args=args)
  File "/home/plm/ariasousse/apps/frappe/frappe/desk/reportview.py", line 78, in execute
    return DatabaseQuery(doctype).execute(*args, **kwargs)
  File "/home/plm/ariasousse/apps/frappe/frappe/model/db_query.py", line 191, in execute
    result = self.build_and_run()
  File "/home/plm/ariasousse/apps/frappe/frappe/model/db_query.py", line 232, in build_and_run
    return frappe.db.sql(
  File "/home/plm/ariasousse/apps/frappe/frappe/database/database.py", line 207, in sql
    self.connect()
  File "/home/plm/ariasousse/apps/frappe/frappe/database/database.py", line 112, in connect
    self._conn: "MariadbConnection" | "PostgresConnection" = self.get_connection()
  File "/home/plm/ariasousse/apps/frappe/frappe/database/mariadb/database.py", line 107, in get_connection
    conn = self._get_connection()
  File "/home/plm/ariasousse/apps/frappe/frappe/database/mariadb/database.py", line 113, in _get_connection
    return self.create_connection()
  File "/home/plm/ariasousse/apps/frappe/frappe/database/mariadb/database.py", line 116, in create_connection
    return pymysql.connect(**self.get_connection_settings())
  File "/home/plm/ariasousse/env/lib/python3.10/site-packages/pymysql/connections.py", line 361, in __init__
    self.connect()
  File "/home/plm/ariasousse/env/lib/python3.10/site-packages/pymysql/connections.py", line 716, in connect
    raise exc
pymysql.err.OperationalError: (2003, "Can't connect to MySQL server on '127.0.0.1' ([Errno 111] Connection refused)")

During handling of the above exception, another exception occurred:

Traceback (most recent call last):
  File "/home/plm/ariasousse/env/lib/python3.10/site-packages/pymysql/connections.py", line 649, in connect
    sock = socket.create_connection(
  File "/usr/lib/python3.10/socket.py", line 845, in create_connection
    raise err
  File "/usr/lib/python3.10/socket.py", line 833, in create_connection
    sock.connect(sa)
ConnectionRefusedError: [Errno 111] Connection refused

During handling of the above exception, another exception occurred:

Traceback (most recent call last):
  File "/home/plm/ariasousse/apps/frappe/frappe/utils/error.py", line 86, in log_error_snapshot
    log_error(title=str(exception), defer_insert=True)
  File "/home/plm/ariasousse/apps/frappe/frappe/utils/error.py", line 61, in log_error
    error_log = frappe.get_doc(
  File "/home/plm/ariasousse/apps/frappe/frappe/__init__.py", line 1290, in get_doc
    doc = frappe.model.document.get_doc(*args, **kwargs)
  File "/home/plm/ariasousse/apps/frappe/frappe/model/document.py", line 83, in get_doc
    controller = get_controller(doctype)
  File "/home/plm/ariasousse/apps/frappe/frappe/model/base_document.py", line 70, in get_controller
    site_controllers[doctype] = import_controller(doctype)
  File "/home/plm/ariasousse/apps/frappe/frappe/model/base_document.py", line 81, in import_controller
    doctype_info = frappe.db.get_value("DocType", doctype, fieldname="*")
  File "/home/plm/ariasousse/apps/frappe/frappe/database/database.py", line 515, in get_value
    result = self.get_values(
  File "/home/plm/ariasousse/apps/frappe/frappe/database/database.py", line 619, in get_values
    out = self._get_values_from_table(
  File "/home/plm/ariasousse/apps/frappe/frappe/database/database.py", line 892, in _get_values_from_table
    return query.run(as_dict=as_dict, debug=debug, update=update, run=run, pluck=pluck)
  File "/home/plm/ariasousse/apps/frappe/frappe/query_builder/utils.py", line 87, in execute_query
    result = frappe.db.sql(query, params, *args, **kwargs)  # nosemgrep
  File "/home/plm/ariasousse/apps/frappe/frappe/database/database.py", line 207, in sql
    self.connect()
  File "/home/plm/ariasousse/apps/frappe/frappe/database/database.py", line 112, in connect
    self._conn: "MariadbConnection" | "PostgresConnection" = self.get_connection()
  File "/home/plm/ariasousse/apps/frappe/frappe/database/mariadb/database.py", line 107, in get_connection
    conn = self._get_connection()
  File "/home/plm/ariasousse/apps/frappe/frappe/database/mariadb/database.py", line 113, in _get_connection
    return self.create_connection()
  File "/home/plm/ariasousse/apps/frappe/frappe/database/mariadb/database.py", line 116, in create_connection
    return pymysql.connect(**self.get_connection_settings())
  File "/home/plm/ariasousse/env/lib/python3.10/site-packages/pymysql/connections.py", line 361, in __init__
    self.connect()
  File "/home/plm/ariasousse/env/lib/python3.10/site-packages/pymysql/connections.py", line 716, in connect
    raise exc
pymysql.err.OperationalError: (2003, "Can't connect to MySQL server on '127.0.0.1' ([Errno 111] Connection refused)")
2025-04-28 15:00:11,342 ERROR frappe New Exception collected in error log
Site: aria.localhost
Form Dict: {'doctype': 'User', 'fields': '["`tabUser`.`name`","`tabUser`.`owner`","`tabUser`.`creation`","`tabUser`.`modified`","`tabUser`.`modified_by`","`tabUser`.`_user_tags`","`tabUser`.`_comments`","`tabUser`.`_assign`","`tabUser`.`_liked_by`","`tabUser`.`docstatus`","`tabUser`.`idx`","`tabUser`.`user_type`","`tabUser`.`full_name`","`tabUser`.`user_image`","`tabUser`.`enabled`"]', 'filters': '[]', 'order_by': '`tabUser`.`modified` desc', 'start': '0', 'page_length': '20', 'view': 'List', 'group_by': '', 'with_comment_count': '1', 'cmd': 'frappe.desk.reportview.get'}
2025-04-28 15:05:11,545 ERROR frappe New Exception collected in error log
Site: aria.localhost
Form Dict: {'doctype': 'User', 'fields': '["`tabUser`.`name`","`tabUser`.`owner`","`tabUser`.`creation`","`tabUser`.`modified`","`tabUser`.`modified_by`","`tabUser`.`_user_tags`","`tabUser`.`_comments`","`tabUser`.`_assign`","`tabUser`.`_liked_by`","`tabUser`.`docstatus`","`tabUser`.`idx`","`tabUser`.`user_type`","`tabUser`.`full_name`","`tabUser`.`user_image`","`tabUser`.`enabled`"]', 'filters': '[]', 'order_by': '`tabUser`.`modified` desc', 'start': '0', 'page_length': '20', 'view': 'List', 'group_by': '', 'with_comment_count': '1', 'cmd': 'frappe.desk.reportview.get'}
2025-04-28 15:10:13,810 ERROR frappe Could not take error snapshot: (2003, "Can't connect to MySQL server on '127.0.0.1' ([Errno 111] Connection refused)")
Site: aria.localhost
Form Dict: {'doctype': 'User', 'fields': '["`tabUser`.`name`","`tabUser`.`owner`","`tabUser`.`creation`","`tabUser`.`modified`","`tabUser`.`modified_by`","`tabUser`.`_user_tags`","`tabUser`.`_comments`","`tabUser`.`_assign`","`tabUser`.`_liked_by`","`tabUser`.`docstatus`","`tabUser`.`idx`","`tabUser`.`user_type`","`tabUser`.`full_name`","`tabUser`.`user_image`","`tabUser`.`enabled`"]', 'filters': '[]', 'order_by': '`tabUser`.`modified` desc', 'start': '0', 'page_length': '20', 'view': 'List', 'group_by': '', 'with_comment_count': '1', 'cmd': 'frappe.desk.reportview.get'}
Traceback (most recent call last):
  File "/home/plm/ariasousse/env/lib/python3.10/site-packages/pymysql/connections.py", line 649, in connect
    sock = socket.create_connection(
  File "/usr/lib/python3.10/socket.py", line 845, in create_connection
    raise err
  File "/usr/lib/python3.10/socket.py", line 833, in create_connection
    sock.connect(sa)
ConnectionRefusedError: [Errno 111] Connection refused

During handling of the above exception, another exception occurred:

Traceback (most recent call last):
  File "/home/plm/ariasousse/apps/frappe/frappe/app.py", line 114, in application
    response = frappe.api.handle(request)
  File "/home/plm/ariasousse/apps/frappe/frappe/api/__init__.py", line 49, in handle
    data = endpoint(**arguments)
  File "/home/plm/ariasousse/apps/frappe/frappe/api/v1.py", line 36, in handle_rpc_call
    return frappe.handler.handle()
  File "/home/plm/ariasousse/apps/frappe/frappe/handler.py", line 49, in handle
    data = execute_cmd(cmd)
  File "/home/plm/ariasousse/apps/frappe/frappe/handler.py", line 85, in execute_cmd
    return frappe.call(method, **frappe.form_dict)
  File "/home/plm/ariasousse/apps/frappe/frappe/__init__.py", line 1725, in call
    return fn(*args, **newargs)
  File "/home/plm/ariasousse/apps/frappe/frappe/utils/typing_validations.py", line 31, in wrapper
    return func(*args, **kwargs)
  File "/home/plm/ariasousse/apps/frappe/frappe/__init__.py", line 878, in wrapper_fn
    retval = fn(*args, **get_newargs(fn, kwargs))
  File "/home/plm/ariasousse/apps/frappe/frappe/desk/reportview.py", line 32, in get
    data = compress(execute(**args), args=args)
  File "/home/plm/ariasousse/apps/frappe/frappe/desk/reportview.py", line 78, in execute
    return DatabaseQuery(doctype).execute(*args, **kwargs)
  File "/home/plm/ariasousse/apps/frappe/frappe/model/db_query.py", line 191, in execute
    result = self.build_and_run()
  File "/home/plm/ariasousse/apps/frappe/frappe/model/db_query.py", line 232, in build_and_run
    return frappe.db.sql(
  File "/home/plm/ariasousse/apps/frappe/frappe/database/database.py", line 207, in sql
    self.connect()
  File "/home/plm/ariasousse/apps/frappe/frappe/database/database.py", line 112, in connect
    self._conn: "MariadbConnection" | "PostgresConnection" = self.get_connection()
  File "/home/plm/ariasousse/apps/frappe/frappe/database/mariadb/database.py", line 107, in get_connection
    conn = self._get_connection()
  File "/home/plm/ariasousse/apps/frappe/frappe/database/mariadb/database.py", line 113, in _get_connection
    return self.create_connection()
  File "/home/plm/ariasousse/apps/frappe/frappe/database/mariadb/database.py", line 116, in create_connection
    return pymysql.connect(**self.get_connection_settings())
  File "/home/plm/ariasousse/env/lib/python3.10/site-packages/pymysql/connections.py", line 361, in __init__
    self.connect()
  File "/home/plm/ariasousse/env/lib/python3.10/site-packages/pymysql/connections.py", line 716, in connect
    raise exc
pymysql.err.OperationalError: (2003, "Can't connect to MySQL server on '127.0.0.1' ([Errno 111] Connection refused)")

During handling of the above exception, another exception occurred:

Traceback (most recent call last):
  File "/home/plm/ariasousse/env/lib/python3.10/site-packages/pymysql/connections.py", line 649, in connect
    sock = socket.create_connection(
  File "/usr/lib/python3.10/socket.py", line 845, in create_connection
    raise err
  File "/usr/lib/python3.10/socket.py", line 833, in create_connection
    sock.connect(sa)
ConnectionRefusedError: [Errno 111] Connection refused

During handling of the above exception, another exception occurred:

Traceback (most recent call last):
  File "/home/plm/ariasousse/apps/frappe/frappe/utils/error.py", line 86, in log_error_snapshot
    log_error(title=str(exception), defer_insert=True)
  File "/home/plm/ariasousse/apps/frappe/frappe/utils/error.py", line 61, in log_error
    error_log = frappe.get_doc(
  File "/home/plm/ariasousse/apps/frappe/frappe/__init__.py", line 1290, in get_doc
    doc = frappe.model.document.get_doc(*args, **kwargs)
  File "/home/plm/ariasousse/apps/frappe/frappe/model/document.py", line 83, in get_doc
    controller = get_controller(doctype)
  File "/home/plm/ariasousse/apps/frappe/frappe/model/base_document.py", line 70, in get_controller
    site_controllers[doctype] = import_controller(doctype)
  File "/home/plm/ariasousse/apps/frappe/frappe/model/base_document.py", line 81, in import_controller
    doctype_info = frappe.db.get_value("DocType", doctype, fieldname="*")
  File "/home/plm/ariasousse/apps/frappe/frappe/database/database.py", line 515, in get_value
    result = self.get_values(
  File "/home/plm/ariasousse/apps/frappe/frappe/database/database.py", line 619, in get_values
    out = self._get_values_from_table(
  File "/home/plm/ariasousse/apps/frappe/frappe/database/database.py", line 892, in _get_values_from_table
    return query.run(as_dict=as_dict, debug=debug, update=update, run=run, pluck=pluck)
  File "/home/plm/ariasousse/apps/frappe/frappe/query_builder/utils.py", line 87, in execute_query
    result = frappe.db.sql(query, params, *args, **kwargs)  # nosemgrep
  File "/home/plm/ariasousse/apps/frappe/frappe/database/database.py", line 207, in sql
    self.connect()
  File "/home/plm/ariasousse/apps/frappe/frappe/database/database.py", line 112, in connect
    self._conn: "MariadbConnection" | "PostgresConnection" = self.get_connection()
  File "/home/plm/ariasousse/apps/frappe/frappe/database/mariadb/database.py", line 107, in get_connection
    conn = self._get_connection()
  File "/home/plm/ariasousse/apps/frappe/frappe/database/mariadb/database.py", line 113, in _get_connection
    return self.create_connection()
  File "/home/plm/ariasousse/apps/frappe/frappe/database/mariadb/database.py", line 116, in create_connection
    return pymysql.connect(**self.get_connection_settings())
  File "/home/plm/ariasousse/env/lib/python3.10/site-packages/pymysql/connections.py", line 361, in __init__
    self.connect()
  File "/home/plm/ariasousse/env/lib/python3.10/site-packages/pymysql/connections.py", line 716, in connect
    raise exc
pymysql.err.OperationalError: (2003, "Can't connect to MySQL server on '127.0.0.1' ([Errno 111] Connection refused)")
