2025-04-28 15:15:11,325 ERROR frappe Could not take error snapshot: (2003, "Can't connect to MySQL server on '127.0.0.1' ([Errno 111] Connection refused)")
Site: aria.localhost
Form Dict: {'doctype': 'User', 'fields': '["`tabUser`.`name`","`tabUser`.`owner`","`tabUser`.`creation`","`tabUser`.`modified`","`tabUser`.`modified_by`","`tabUser`.`_user_tags`","`tabUser`.`_comments`","`tabUser`.`_assign`","`tabUser`.`_liked_by`","`tabUser`.`docstatus`","`tabUser`.`idx`","`tabUser`.`user_type`","`tabUser`.`full_name`","`tabUser`.`user_image`","`tabUser`.`enabled`"]', 'filters': '[]', 'order_by': '`tabUser`.`modified` desc', 'start': '0', 'page_length': '20', 'view': 'List', 'group_by': '', 'with_comment_count': '1', 'cmd': 'frappe.desk.reportview.get'}
Traceback (most recent call last):
  File "/home/plm/ariasousse/env/lib/python3.10/site-packages/pymysql/connections.py", line 649, in connect
    sock = socket.create_connection(
  File "/usr/lib/python3.10/socket.py", line 845, in create_connection
    raise err
  File "/usr/lib/python3.10/socket.py", line 833, in create_connection
    sock.connect(sa)
ConnectionRefusedError: [Errno 111] Connection refused

During handling of the above exception, another exception occurred:

Traceback (most recent call last):
  File "/home/plm/ariasousse/apps/frappe/frappe/app.py", line 114, in application
    response = frappe.api.handle(request)
  File "/home/plm/ariasousse/apps/frappe/frappe/api/__init__.py", line 49, in handle
    data = endpoint(**arguments)
  File "/home/plm/ariasousse/apps/frappe/frappe/api/v1.py", line 36, in handle_rpc_call
    return frappe.handler.handle()
  File "/home/plm/ariasousse/apps/frappe/frappe/handler.py", line 49, in handle
    data = execute_cmd(cmd)
  File "/home/plm/ariasousse/apps/frappe/frappe/handler.py", line 85, in execute_cmd
    return frappe.call(method, **frappe.form_dict)
  File "/home/plm/ariasousse/apps/frappe/frappe/__init__.py", line 1725, in call
    return fn(*args, **newargs)
  File "/home/plm/ariasousse/apps/frappe/frappe/utils/typing_validations.py", line 31, in wrapper
    return func(*args, **kwargs)
  File "/home/plm/ariasousse/apps/frappe/frappe/__init__.py", line 878, in wrapper_fn
    retval = fn(*args, **get_newargs(fn, kwargs))
  File "/home/plm/ariasousse/apps/frappe/frappe/desk/reportview.py", line 32, in get
    data = compress(execute(**args), args=args)
  File "/home/plm/ariasousse/apps/frappe/frappe/desk/reportview.py", line 78, in execute
    return DatabaseQuery(doctype).execute(*args, **kwargs)
  File "/home/plm/ariasousse/apps/frappe/frappe/model/db_query.py", line 191, in execute
    result = self.build_and_run()
  File "/home/plm/ariasousse/apps/frappe/frappe/model/db_query.py", line 232, in build_and_run
    return frappe.db.sql(
  File "/home/plm/ariasousse/apps/frappe/frappe/database/database.py", line 207, in sql
    self.connect()
  File "/home/plm/ariasousse/apps/frappe/frappe/database/database.py", line 112, in connect
    self._conn: "MariadbConnection" | "PostgresConnection" = self.get_connection()
  File "/home/plm/ariasousse/apps/frappe/frappe/database/mariadb/database.py", line 107, in get_connection
    conn = self._get_connection()
  File "/home/plm/ariasousse/apps/frappe/frappe/database/mariadb/database.py", line 113, in _get_connection
    return self.create_connection()
  File "/home/plm/ariasousse/apps/frappe/frappe/database/mariadb/database.py", line 116, in create_connection
    return pymysql.connect(**self.get_connection_settings())
  File "/home/plm/ariasousse/env/lib/python3.10/site-packages/pymysql/connections.py", line 361, in __init__
    self.connect()
  File "/home/plm/ariasousse/env/lib/python3.10/site-packages/pymysql/connections.py", line 716, in connect
    raise exc
pymysql.err.OperationalError: (2003, "Can't connect to MySQL server on '127.0.0.1' ([Errno 111] Connection refused)")

During handling of the above exception, another exception occurred:

Traceback (most recent call last):
  File "/home/plm/ariasousse/env/lib/python3.10/site-packages/pymysql/connections.py", line 649, in connect
    sock = socket.create_connection(
  File "/usr/lib/python3.10/socket.py", line 845, in create_connection
    raise err
  File "/usr/lib/python3.10/socket.py", line 833, in create_connection
    sock.connect(sa)
ConnectionRefusedError: [Errno 111] Connection refused

During handling of the above exception, another exception occurred:

Traceback (most recent call last):
  File "/home/plm/ariasousse/apps/frappe/frappe/utils/error.py", line 86, in log_error_snapshot
    log_error(title=str(exception), defer_insert=True)
  File "/home/plm/ariasousse/apps/frappe/frappe/utils/error.py", line 61, in log_error
    error_log = frappe.get_doc(
  File "/home/plm/ariasousse/apps/frappe/frappe/__init__.py", line 1290, in get_doc
    doc = frappe.model.document.get_doc(*args, **kwargs)
  File "/home/plm/ariasousse/apps/frappe/frappe/model/document.py", line 83, in get_doc
    controller = get_controller(doctype)
  File "/home/plm/ariasousse/apps/frappe/frappe/model/base_document.py", line 70, in get_controller
    site_controllers[doctype] = import_controller(doctype)
  File "/home/plm/ariasousse/apps/frappe/frappe/model/base_document.py", line 81, in import_controller
    doctype_info = frappe.db.get_value("DocType", doctype, fieldname="*")
  File "/home/plm/ariasousse/apps/frappe/frappe/database/database.py", line 515, in get_value
    result = self.get_values(
  File "/home/plm/ariasousse/apps/frappe/frappe/database/database.py", line 619, in get_values
    out = self._get_values_from_table(
  File "/home/plm/ariasousse/apps/frappe/frappe/database/database.py", line 892, in _get_values_from_table
    return query.run(as_dict=as_dict, debug=debug, update=update, run=run, pluck=pluck)
  File "/home/plm/ariasousse/apps/frappe/frappe/query_builder/utils.py", line 87, in execute_query
    result = frappe.db.sql(query, params, *args, **kwargs)  # nosemgrep
  File "/home/plm/ariasousse/apps/frappe/frappe/database/database.py", line 207, in sql
    self.connect()
  File "/home/plm/ariasousse/apps/frappe/frappe/database/database.py", line 112, in connect
    self._conn: "MariadbConnection" | "PostgresConnection" = self.get_connection()
  File "/home/plm/ariasousse/apps/frappe/frappe/database/mariadb/database.py", line 107, in get_connection
    conn = self._get_connection()
  File "/home/plm/ariasousse/apps/frappe/frappe/database/mariadb/database.py", line 113, in _get_connection
    return self.create_connection()
  File "/home/plm/ariasousse/apps/frappe/frappe/database/mariadb/database.py", line 116, in create_connection
    return pymysql.connect(**self.get_connection_settings())
  File "/home/plm/ariasousse/env/lib/python3.10/site-packages/pymysql/connections.py", line 361, in __init__
    self.connect()
  File "/home/plm/ariasousse/env/lib/python3.10/site-packages/pymysql/connections.py", line 716, in connect
    raise exc
pymysql.err.OperationalError: (2003, "Can't connect to MySQL server on '127.0.0.1' ([Errno 111] Connection refused)")
2025-04-28 15:45:14,531 ERROR frappe Could not take error snapshot: (2003, "Can't connect to MySQL server on '127.0.0.1' ([Errno 111] Connection refused)")
Site: aria.localhost
Form Dict: {'doctype': 'User', 'fields': '["`tabUser`.`name`","`tabUser`.`owner`","`tabUser`.`creation`","`tabUser`.`modified`","`tabUser`.`modified_by`","`tabUser`.`_user_tags`","`tabUser`.`_comments`","`tabUser`.`_assign`","`tabUser`.`_liked_by`","`tabUser`.`docstatus`","`tabUser`.`idx`","`tabUser`.`user_type`","`tabUser`.`full_name`","`tabUser`.`user_image`","`tabUser`.`enabled`"]', 'filters': '[]', 'order_by': '`tabUser`.`modified` desc', 'start': '0', 'page_length': '20', 'view': 'List', 'group_by': '', 'with_comment_count': '1', 'cmd': 'frappe.desk.reportview.get'}
Traceback (most recent call last):
  File "/home/plm/ariasousse/env/lib/python3.10/site-packages/pymysql/connections.py", line 649, in connect
    sock = socket.create_connection(
  File "/usr/lib/python3.10/socket.py", line 845, in create_connection
    raise err
  File "/usr/lib/python3.10/socket.py", line 833, in create_connection
    sock.connect(sa)
ConnectionRefusedError: [Errno 111] Connection refused

During handling of the above exception, another exception occurred:

Traceback (most recent call last):
  File "/home/plm/ariasousse/apps/frappe/frappe/app.py", line 114, in application
    response = frappe.api.handle(request)
  File "/home/plm/ariasousse/apps/frappe/frappe/api/__init__.py", line 49, in handle
    data = endpoint(**arguments)
  File "/home/plm/ariasousse/apps/frappe/frappe/api/v1.py", line 36, in handle_rpc_call
    return frappe.handler.handle()
  File "/home/plm/ariasousse/apps/frappe/frappe/handler.py", line 49, in handle
    data = execute_cmd(cmd)
  File "/home/plm/ariasousse/apps/frappe/frappe/handler.py", line 85, in execute_cmd
    return frappe.call(method, **frappe.form_dict)
  File "/home/plm/ariasousse/apps/frappe/frappe/__init__.py", line 1725, in call
    return fn(*args, **newargs)
  File "/home/plm/ariasousse/apps/frappe/frappe/utils/typing_validations.py", line 31, in wrapper
    return func(*args, **kwargs)
  File "/home/plm/ariasousse/apps/frappe/frappe/__init__.py", line 878, in wrapper_fn
    retval = fn(*args, **get_newargs(fn, kwargs))
  File "/home/plm/ariasousse/apps/frappe/frappe/desk/reportview.py", line 32, in get
    data = compress(execute(**args), args=args)
  File "/home/plm/ariasousse/apps/frappe/frappe/desk/reportview.py", line 78, in execute
    return DatabaseQuery(doctype).execute(*args, **kwargs)
  File "/home/plm/ariasousse/apps/frappe/frappe/model/db_query.py", line 191, in execute
    result = self.build_and_run()
  File "/home/plm/ariasousse/apps/frappe/frappe/model/db_query.py", line 232, in build_and_run
    return frappe.db.sql(
  File "/home/plm/ariasousse/apps/frappe/frappe/database/database.py", line 207, in sql
    self.connect()
  File "/home/plm/ariasousse/apps/frappe/frappe/database/database.py", line 112, in connect
    self._conn: "MariadbConnection" | "PostgresConnection" = self.get_connection()
  File "/home/plm/ariasousse/apps/frappe/frappe/database/mariadb/database.py", line 107, in get_connection
    conn = self._get_connection()
  File "/home/plm/ariasousse/apps/frappe/frappe/database/mariadb/database.py", line 113, in _get_connection
    return self.create_connection()
  File "/home/plm/ariasousse/apps/frappe/frappe/database/mariadb/database.py", line 116, in create_connection
    return pymysql.connect(**self.get_connection_settings())
  File "/home/plm/ariasousse/env/lib/python3.10/site-packages/pymysql/connections.py", line 361, in __init__
    self.connect()
  File "/home/plm/ariasousse/env/lib/python3.10/site-packages/pymysql/connections.py", line 716, in connect
    raise exc
pymysql.err.OperationalError: (2003, "Can't connect to MySQL server on '127.0.0.1' ([Errno 111] Connection refused)")

During handling of the above exception, another exception occurred:

Traceback (most recent call last):
  File "/home/plm/ariasousse/env/lib/python3.10/site-packages/pymysql/connections.py", line 649, in connect
    sock = socket.create_connection(
  File "/usr/lib/python3.10/socket.py", line 845, in create_connection
    raise err
  File "/usr/lib/python3.10/socket.py", line 833, in create_connection
    sock.connect(sa)
ConnectionRefusedError: [Errno 111] Connection refused

During handling of the above exception, another exception occurred:

Traceback (most recent call last):
  File "/home/plm/ariasousse/apps/frappe/frappe/utils/error.py", line 86, in log_error_snapshot
    log_error(title=str(exception), defer_insert=True)
  File "/home/plm/ariasousse/apps/frappe/frappe/utils/error.py", line 61, in log_error
    error_log = frappe.get_doc(
  File "/home/plm/ariasousse/apps/frappe/frappe/__init__.py", line 1290, in get_doc
    doc = frappe.model.document.get_doc(*args, **kwargs)
  File "/home/plm/ariasousse/apps/frappe/frappe/model/document.py", line 83, in get_doc
    controller = get_controller(doctype)
  File "/home/plm/ariasousse/apps/frappe/frappe/model/base_document.py", line 70, in get_controller
    site_controllers[doctype] = import_controller(doctype)
  File "/home/plm/ariasousse/apps/frappe/frappe/model/base_document.py", line 81, in import_controller
    doctype_info = frappe.db.get_value("DocType", doctype, fieldname="*")
  File "/home/plm/ariasousse/apps/frappe/frappe/database/database.py", line 515, in get_value
    result = self.get_values(
  File "/home/plm/ariasousse/apps/frappe/frappe/database/database.py", line 619, in get_values
    out = self._get_values_from_table(
  File "/home/plm/ariasousse/apps/frappe/frappe/database/database.py", line 892, in _get_values_from_table
    return query.run(as_dict=as_dict, debug=debug, update=update, run=run, pluck=pluck)
  File "/home/plm/ariasousse/apps/frappe/frappe/query_builder/utils.py", line 87, in execute_query
    result = frappe.db.sql(query, params, *args, **kwargs)  # nosemgrep
  File "/home/plm/ariasousse/apps/frappe/frappe/database/database.py", line 207, in sql
    self.connect()
  File "/home/plm/ariasousse/apps/frappe/frappe/database/database.py", line 112, in connect
    self._conn: "MariadbConnection" | "PostgresConnection" = self.get_connection()
  File "/home/plm/ariasousse/apps/frappe/frappe/database/mariadb/database.py", line 107, in get_connection
    conn = self._get_connection()
  File "/home/plm/ariasousse/apps/frappe/frappe/database/mariadb/database.py", line 113, in _get_connection
    return self.create_connection()
  File "/home/plm/ariasousse/apps/frappe/frappe/database/mariadb/database.py", line 116, in create_connection
    return pymysql.connect(**self.get_connection_settings())
  File "/home/plm/ariasousse/env/lib/python3.10/site-packages/pymysql/connections.py", line 361, in __init__
    self.connect()
  File "/home/plm/ariasousse/env/lib/python3.10/site-packages/pymysql/connections.py", line 716, in connect
    raise exc
pymysql.err.OperationalError: (2003, "Can't connect to MySQL server on '127.0.0.1' ([Errno 111] Connection refused)")
2025-04-28 16:10:11,638 ERROR frappe Could not take error snapshot: (2003, "Can't connect to MySQL server on '127.0.0.1' ([Errno 111] Connection refused)")
Site: aria.localhost
Form Dict: {'doctype': 'User', 'fields': '["`tabUser`.`name`","`tabUser`.`owner`","`tabUser`.`creation`","`tabUser`.`modified`","`tabUser`.`modified_by`","`tabUser`.`_user_tags`","`tabUser`.`_comments`","`tabUser`.`_assign`","`tabUser`.`_liked_by`","`tabUser`.`docstatus`","`tabUser`.`idx`","`tabUser`.`user_type`","`tabUser`.`full_name`","`tabUser`.`user_image`","`tabUser`.`enabled`"]', 'filters': '[]', 'order_by': '`tabUser`.`modified` desc', 'start': '0', 'page_length': '20', 'view': 'List', 'group_by': '', 'with_comment_count': '1', 'cmd': 'frappe.desk.reportview.get'}
Traceback (most recent call last):
  File "/home/plm/ariasousse/env/lib/python3.10/site-packages/pymysql/connections.py", line 649, in connect
    sock = socket.create_connection(
  File "/usr/lib/python3.10/socket.py", line 845, in create_connection
    raise err
  File "/usr/lib/python3.10/socket.py", line 833, in create_connection
    sock.connect(sa)
ConnectionRefusedError: [Errno 111] Connection refused

During handling of the above exception, another exception occurred:

Traceback (most recent call last):
  File "/home/plm/ariasousse/apps/frappe/frappe/app.py", line 114, in application
    response = frappe.api.handle(request)
  File "/home/plm/ariasousse/apps/frappe/frappe/api/__init__.py", line 49, in handle
    data = endpoint(**arguments)
  File "/home/plm/ariasousse/apps/frappe/frappe/api/v1.py", line 36, in handle_rpc_call
    return frappe.handler.handle()
  File "/home/plm/ariasousse/apps/frappe/frappe/handler.py", line 49, in handle
    data = execute_cmd(cmd)
  File "/home/plm/ariasousse/apps/frappe/frappe/handler.py", line 85, in execute_cmd
    return frappe.call(method, **frappe.form_dict)
  File "/home/plm/ariasousse/apps/frappe/frappe/__init__.py", line 1725, in call
    return fn(*args, **newargs)
  File "/home/plm/ariasousse/apps/frappe/frappe/utils/typing_validations.py", line 31, in wrapper
    return func(*args, **kwargs)
  File "/home/plm/ariasousse/apps/frappe/frappe/__init__.py", line 878, in wrapper_fn
    retval = fn(*args, **get_newargs(fn, kwargs))
  File "/home/plm/ariasousse/apps/frappe/frappe/desk/reportview.py", line 32, in get
    data = compress(execute(**args), args=args)
  File "/home/plm/ariasousse/apps/frappe/frappe/desk/reportview.py", line 78, in execute
    return DatabaseQuery(doctype).execute(*args, **kwargs)
  File "/home/plm/ariasousse/apps/frappe/frappe/model/db_query.py", line 191, in execute
    result = self.build_and_run()
  File "/home/plm/ariasousse/apps/frappe/frappe/model/db_query.py", line 232, in build_and_run
    return frappe.db.sql(
  File "/home/plm/ariasousse/apps/frappe/frappe/database/database.py", line 207, in sql
    self.connect()
  File "/home/plm/ariasousse/apps/frappe/frappe/database/database.py", line 112, in connect
    self._conn: "MariadbConnection" | "PostgresConnection" = self.get_connection()
  File "/home/plm/ariasousse/apps/frappe/frappe/database/mariadb/database.py", line 107, in get_connection
    conn = self._get_connection()
  File "/home/plm/ariasousse/apps/frappe/frappe/database/mariadb/database.py", line 113, in _get_connection
    return self.create_connection()
  File "/home/plm/ariasousse/apps/frappe/frappe/database/mariadb/database.py", line 116, in create_connection
    return pymysql.connect(**self.get_connection_settings())
  File "/home/plm/ariasousse/env/lib/python3.10/site-packages/pymysql/connections.py", line 361, in __init__
    self.connect()
  File "/home/plm/ariasousse/env/lib/python3.10/site-packages/pymysql/connections.py", line 716, in connect
    raise exc
pymysql.err.OperationalError: (2003, "Can't connect to MySQL server on '127.0.0.1' ([Errno 111] Connection refused)")

During handling of the above exception, another exception occurred:

Traceback (most recent call last):
  File "/home/plm/ariasousse/env/lib/python3.10/site-packages/pymysql/connections.py", line 649, in connect
    sock = socket.create_connection(
  File "/usr/lib/python3.10/socket.py", line 845, in create_connection
    raise err
  File "/usr/lib/python3.10/socket.py", line 833, in create_connection
    sock.connect(sa)
ConnectionRefusedError: [Errno 111] Connection refused

During handling of the above exception, another exception occurred:

Traceback (most recent call last):
  File "/home/plm/ariasousse/apps/frappe/frappe/utils/error.py", line 86, in log_error_snapshot
    log_error(title=str(exception), defer_insert=True)
  File "/home/plm/ariasousse/apps/frappe/frappe/utils/error.py", line 61, in log_error
    error_log = frappe.get_doc(
  File "/home/plm/ariasousse/apps/frappe/frappe/__init__.py", line 1290, in get_doc
    doc = frappe.model.document.get_doc(*args, **kwargs)
  File "/home/plm/ariasousse/apps/frappe/frappe/model/document.py", line 83, in get_doc
    controller = get_controller(doctype)
  File "/home/plm/ariasousse/apps/frappe/frappe/model/base_document.py", line 70, in get_controller
    site_controllers[doctype] = import_controller(doctype)
  File "/home/plm/ariasousse/apps/frappe/frappe/model/base_document.py", line 81, in import_controller
    doctype_info = frappe.db.get_value("DocType", doctype, fieldname="*")
  File "/home/plm/ariasousse/apps/frappe/frappe/database/database.py", line 515, in get_value
    result = self.get_values(
  File "/home/plm/ariasousse/apps/frappe/frappe/database/database.py", line 619, in get_values
    out = self._get_values_from_table(
  File "/home/plm/ariasousse/apps/frappe/frappe/database/database.py", line 892, in _get_values_from_table
    return query.run(as_dict=as_dict, debug=debug, update=update, run=run, pluck=pluck)
  File "/home/plm/ariasousse/apps/frappe/frappe/query_builder/utils.py", line 87, in execute_query
    result = frappe.db.sql(query, params, *args, **kwargs)  # nosemgrep
  File "/home/plm/ariasousse/apps/frappe/frappe/database/database.py", line 207, in sql
    self.connect()
  File "/home/plm/ariasousse/apps/frappe/frappe/database/database.py", line 112, in connect
    self._conn: "MariadbConnection" | "PostgresConnection" = self.get_connection()
  File "/home/plm/ariasousse/apps/frappe/frappe/database/mariadb/database.py", line 107, in get_connection
    conn = self._get_connection()
  File "/home/plm/ariasousse/apps/frappe/frappe/database/mariadb/database.py", line 113, in _get_connection
    return self.create_connection()
  File "/home/plm/ariasousse/apps/frappe/frappe/database/mariadb/database.py", line 116, in create_connection
    return pymysql.connect(**self.get_connection_settings())
  File "/home/plm/ariasousse/env/lib/python3.10/site-packages/pymysql/connections.py", line 361, in __init__
    self.connect()
  File "/home/plm/ariasousse/env/lib/python3.10/site-packages/pymysql/connections.py", line 716, in connect
    raise exc
pymysql.err.OperationalError: (2003, "Can't connect to MySQL server on '127.0.0.1' ([Errno 111] Connection refused)")
2025-04-28 16:30:11,365 ERROR frappe Could not take error snapshot: (2003, "Can't connect to MySQL server on '127.0.0.1' ([Errno 111] Connection refused)")
Site: aria.localhost
Form Dict: {'doctype': 'User', 'fields': '["`tabUser`.`name`","`tabUser`.`owner`","`tabUser`.`creation`","`tabUser`.`modified`","`tabUser`.`modified_by`","`tabUser`.`_user_tags`","`tabUser`.`_comments`","`tabUser`.`_assign`","`tabUser`.`_liked_by`","`tabUser`.`docstatus`","`tabUser`.`idx`","`tabUser`.`user_type`","`tabUser`.`full_name`","`tabUser`.`user_image`","`tabUser`.`enabled`"]', 'filters': '[]', 'order_by': '`tabUser`.`modified` desc', 'start': '0', 'page_length': '20', 'view': 'List', 'group_by': '', 'with_comment_count': '1', 'cmd': 'frappe.desk.reportview.get'}
Traceback (most recent call last):
  File "/home/plm/ariasousse/env/lib/python3.10/site-packages/pymysql/connections.py", line 649, in connect
    sock = socket.create_connection(
  File "/usr/lib/python3.10/socket.py", line 845, in create_connection
    raise err
  File "/usr/lib/python3.10/socket.py", line 833, in create_connection
    sock.connect(sa)
ConnectionRefusedError: [Errno 111] Connection refused

During handling of the above exception, another exception occurred:

Traceback (most recent call last):
  File "/home/plm/ariasousse/apps/frappe/frappe/app.py", line 114, in application
    response = frappe.api.handle(request)
  File "/home/plm/ariasousse/apps/frappe/frappe/api/__init__.py", line 49, in handle
    data = endpoint(**arguments)
  File "/home/plm/ariasousse/apps/frappe/frappe/api/v1.py", line 36, in handle_rpc_call
    return frappe.handler.handle()
  File "/home/plm/ariasousse/apps/frappe/frappe/handler.py", line 49, in handle
    data = execute_cmd(cmd)
  File "/home/plm/ariasousse/apps/frappe/frappe/handler.py", line 85, in execute_cmd
    return frappe.call(method, **frappe.form_dict)
  File "/home/plm/ariasousse/apps/frappe/frappe/__init__.py", line 1725, in call
    return fn(*args, **newargs)
  File "/home/plm/ariasousse/apps/frappe/frappe/utils/typing_validations.py", line 31, in wrapper
    return func(*args, **kwargs)
  File "/home/plm/ariasousse/apps/frappe/frappe/__init__.py", line 878, in wrapper_fn
    retval = fn(*args, **get_newargs(fn, kwargs))
  File "/home/plm/ariasousse/apps/frappe/frappe/desk/reportview.py", line 32, in get
    data = compress(execute(**args), args=args)
  File "/home/plm/ariasousse/apps/frappe/frappe/desk/reportview.py", line 78, in execute
    return DatabaseQuery(doctype).execute(*args, **kwargs)
  File "/home/plm/ariasousse/apps/frappe/frappe/model/db_query.py", line 191, in execute
    result = self.build_and_run()
  File "/home/plm/ariasousse/apps/frappe/frappe/model/db_query.py", line 232, in build_and_run
    return frappe.db.sql(
  File "/home/plm/ariasousse/apps/frappe/frappe/database/database.py", line 207, in sql
    self.connect()
  File "/home/plm/ariasousse/apps/frappe/frappe/database/database.py", line 112, in connect
    self._conn: "MariadbConnection" | "PostgresConnection" = self.get_connection()
  File "/home/plm/ariasousse/apps/frappe/frappe/database/mariadb/database.py", line 107, in get_connection
    conn = self._get_connection()
  File "/home/plm/ariasousse/apps/frappe/frappe/database/mariadb/database.py", line 113, in _get_connection
    return self.create_connection()
  File "/home/plm/ariasousse/apps/frappe/frappe/database/mariadb/database.py", line 116, in create_connection
    return pymysql.connect(**self.get_connection_settings())
  File "/home/plm/ariasousse/env/lib/python3.10/site-packages/pymysql/connections.py", line 361, in __init__
    self.connect()
  File "/home/plm/ariasousse/env/lib/python3.10/site-packages/pymysql/connections.py", line 716, in connect
    raise exc
pymysql.err.OperationalError: (2003, "Can't connect to MySQL server on '127.0.0.1' ([Errno 111] Connection refused)")

During handling of the above exception, another exception occurred:

Traceback (most recent call last):
  File "/home/plm/ariasousse/env/lib/python3.10/site-packages/pymysql/connections.py", line 649, in connect
    sock = socket.create_connection(
  File "/usr/lib/python3.10/socket.py", line 845, in create_connection
    raise err
  File "/usr/lib/python3.10/socket.py", line 833, in create_connection
    sock.connect(sa)
ConnectionRefusedError: [Errno 111] Connection refused

During handling of the above exception, another exception occurred:

Traceback (most recent call last):
  File "/home/plm/ariasousse/apps/frappe/frappe/utils/error.py", line 86, in log_error_snapshot
    log_error(title=str(exception), defer_insert=True)
  File "/home/plm/ariasousse/apps/frappe/frappe/utils/error.py", line 61, in log_error
    error_log = frappe.get_doc(
  File "/home/plm/ariasousse/apps/frappe/frappe/__init__.py", line 1290, in get_doc
    doc = frappe.model.document.get_doc(*args, **kwargs)
  File "/home/plm/ariasousse/apps/frappe/frappe/model/document.py", line 83, in get_doc
    controller = get_controller(doctype)
  File "/home/plm/ariasousse/apps/frappe/frappe/model/base_document.py", line 70, in get_controller
    site_controllers[doctype] = import_controller(doctype)
  File "/home/plm/ariasousse/apps/frappe/frappe/model/base_document.py", line 81, in import_controller
    doctype_info = frappe.db.get_value("DocType", doctype, fieldname="*")
  File "/home/plm/ariasousse/apps/frappe/frappe/database/database.py", line 515, in get_value
    result = self.get_values(
  File "/home/plm/ariasousse/apps/frappe/frappe/database/database.py", line 619, in get_values
    out = self._get_values_from_table(
  File "/home/plm/ariasousse/apps/frappe/frappe/database/database.py", line 892, in _get_values_from_table
    return query.run(as_dict=as_dict, debug=debug, update=update, run=run, pluck=pluck)
  File "/home/plm/ariasousse/apps/frappe/frappe/query_builder/utils.py", line 87, in execute_query
    result = frappe.db.sql(query, params, *args, **kwargs)  # nosemgrep
  File "/home/plm/ariasousse/apps/frappe/frappe/database/database.py", line 207, in sql
    self.connect()
  File "/home/plm/ariasousse/apps/frappe/frappe/database/database.py", line 112, in connect
    self._conn: "MariadbConnection" | "PostgresConnection" = self.get_connection()
  File "/home/plm/ariasousse/apps/frappe/frappe/database/mariadb/database.py", line 107, in get_connection
    conn = self._get_connection()
  File "/home/plm/ariasousse/apps/frappe/frappe/database/mariadb/database.py", line 113, in _get_connection
    return self.create_connection()
  File "/home/plm/ariasousse/apps/frappe/frappe/database/mariadb/database.py", line 116, in create_connection
    return pymysql.connect(**self.get_connection_settings())
  File "/home/plm/ariasousse/env/lib/python3.10/site-packages/pymysql/connections.py", line 361, in __init__
    self.connect()
  File "/home/plm/ariasousse/env/lib/python3.10/site-packages/pymysql/connections.py", line 716, in connect
    raise exc
pymysql.err.OperationalError: (2003, "Can't connect to MySQL server on '127.0.0.1' ([Errno 111] Connection refused)")
2025-04-28 16:40:11,434 ERROR frappe Could not take error snapshot: (2003, "Can't connect to MySQL server on '127.0.0.1' ([Errno 111] Connection refused)")
Site: aria.localhost
Form Dict: {'doctype': 'User', 'fields': '["`tabUser`.`name`","`tabUser`.`owner`","`tabUser`.`creation`","`tabUser`.`modified`","`tabUser`.`modified_by`","`tabUser`.`_user_tags`","`tabUser`.`_comments`","`tabUser`.`_assign`","`tabUser`.`_liked_by`","`tabUser`.`docstatus`","`tabUser`.`idx`","`tabUser`.`user_type`","`tabUser`.`full_name`","`tabUser`.`user_image`","`tabUser`.`enabled`"]', 'filters': '[]', 'order_by': '`tabUser`.`modified` desc', 'start': '0', 'page_length': '20', 'view': 'List', 'group_by': '', 'with_comment_count': '1', 'cmd': 'frappe.desk.reportview.get'}
Traceback (most recent call last):
  File "/home/plm/ariasousse/env/lib/python3.10/site-packages/pymysql/connections.py", line 649, in connect
    sock = socket.create_connection(
  File "/usr/lib/python3.10/socket.py", line 845, in create_connection
    raise err
  File "/usr/lib/python3.10/socket.py", line 833, in create_connection
    sock.connect(sa)
ConnectionRefusedError: [Errno 111] Connection refused

During handling of the above exception, another exception occurred:

Traceback (most recent call last):
  File "/home/plm/ariasousse/apps/frappe/frappe/app.py", line 114, in application
    response = frappe.api.handle(request)
  File "/home/plm/ariasousse/apps/frappe/frappe/api/__init__.py", line 49, in handle
    data = endpoint(**arguments)
  File "/home/plm/ariasousse/apps/frappe/frappe/api/v1.py", line 36, in handle_rpc_call
    return frappe.handler.handle()
  File "/home/plm/ariasousse/apps/frappe/frappe/handler.py", line 49, in handle
    data = execute_cmd(cmd)
  File "/home/plm/ariasousse/apps/frappe/frappe/handler.py", line 85, in execute_cmd
    return frappe.call(method, **frappe.form_dict)
  File "/home/plm/ariasousse/apps/frappe/frappe/__init__.py", line 1725, in call
    return fn(*args, **newargs)
  File "/home/plm/ariasousse/apps/frappe/frappe/utils/typing_validations.py", line 31, in wrapper
    return func(*args, **kwargs)
  File "/home/plm/ariasousse/apps/frappe/frappe/__init__.py", line 878, in wrapper_fn
    retval = fn(*args, **get_newargs(fn, kwargs))
  File "/home/plm/ariasousse/apps/frappe/frappe/desk/reportview.py", line 32, in get
    data = compress(execute(**args), args=args)
  File "/home/plm/ariasousse/apps/frappe/frappe/desk/reportview.py", line 78, in execute
    return DatabaseQuery(doctype).execute(*args, **kwargs)
  File "/home/plm/ariasousse/apps/frappe/frappe/model/db_query.py", line 191, in execute
    result = self.build_and_run()
  File "/home/plm/ariasousse/apps/frappe/frappe/model/db_query.py", line 232, in build_and_run
    return frappe.db.sql(
  File "/home/plm/ariasousse/apps/frappe/frappe/database/database.py", line 207, in sql
    self.connect()
  File "/home/plm/ariasousse/apps/frappe/frappe/database/database.py", line 112, in connect
    self._conn: "MariadbConnection" | "PostgresConnection" = self.get_connection()
  File "/home/plm/ariasousse/apps/frappe/frappe/database/mariadb/database.py", line 107, in get_connection
    conn = self._get_connection()
  File "/home/plm/ariasousse/apps/frappe/frappe/database/mariadb/database.py", line 113, in _get_connection
    return self.create_connection()
  File "/home/plm/ariasousse/apps/frappe/frappe/database/mariadb/database.py", line 116, in create_connection
    return pymysql.connect(**self.get_connection_settings())
  File "/home/plm/ariasousse/env/lib/python3.10/site-packages/pymysql/connections.py", line 361, in __init__
    self.connect()
  File "/home/plm/ariasousse/env/lib/python3.10/site-packages/pymysql/connections.py", line 716, in connect
    raise exc
pymysql.err.OperationalError: (2003, "Can't connect to MySQL server on '127.0.0.1' ([Errno 111] Connection refused)")

During handling of the above exception, another exception occurred:

Traceback (most recent call last):
  File "/home/plm/ariasousse/env/lib/python3.10/site-packages/pymysql/connections.py", line 649, in connect
    sock = socket.create_connection(
  File "/usr/lib/python3.10/socket.py", line 845, in create_connection
    raise err
  File "/usr/lib/python3.10/socket.py", line 833, in create_connection
    sock.connect(sa)
ConnectionRefusedError: [Errno 111] Connection refused

During handling of the above exception, another exception occurred:

Traceback (most recent call last):
  File "/home/plm/ariasousse/apps/frappe/frappe/utils/error.py", line 86, in log_error_snapshot
    log_error(title=str(exception), defer_insert=True)
  File "/home/plm/ariasousse/apps/frappe/frappe/utils/error.py", line 61, in log_error
    error_log = frappe.get_doc(
  File "/home/plm/ariasousse/apps/frappe/frappe/__init__.py", line 1290, in get_doc
    doc = frappe.model.document.get_doc(*args, **kwargs)
  File "/home/plm/ariasousse/apps/frappe/frappe/model/document.py", line 83, in get_doc
    controller = get_controller(doctype)
  File "/home/plm/ariasousse/apps/frappe/frappe/model/base_document.py", line 70, in get_controller
    site_controllers[doctype] = import_controller(doctype)
  File "/home/plm/ariasousse/apps/frappe/frappe/model/base_document.py", line 81, in import_controller
    doctype_info = frappe.db.get_value("DocType", doctype, fieldname="*")
  File "/home/plm/ariasousse/apps/frappe/frappe/database/database.py", line 515, in get_value
    result = self.get_values(
  File "/home/plm/ariasousse/apps/frappe/frappe/database/database.py", line 619, in get_values
    out = self._get_values_from_table(
  File "/home/plm/ariasousse/apps/frappe/frappe/database/database.py", line 892, in _get_values_from_table
    return query.run(as_dict=as_dict, debug=debug, update=update, run=run, pluck=pluck)
  File "/home/plm/ariasousse/apps/frappe/frappe/query_builder/utils.py", line 87, in execute_query
    result = frappe.db.sql(query, params, *args, **kwargs)  # nosemgrep
  File "/home/plm/ariasousse/apps/frappe/frappe/database/database.py", line 207, in sql
    self.connect()
  File "/home/plm/ariasousse/apps/frappe/frappe/database/database.py", line 112, in connect
    self._conn: "MariadbConnection" | "PostgresConnection" = self.get_connection()
  File "/home/plm/ariasousse/apps/frappe/frappe/database/mariadb/database.py", line 107, in get_connection
    conn = self._get_connection()
  File "/home/plm/ariasousse/apps/frappe/frappe/database/mariadb/database.py", line 113, in _get_connection
    return self.create_connection()
  File "/home/plm/ariasousse/apps/frappe/frappe/database/mariadb/database.py", line 116, in create_connection
    return pymysql.connect(**self.get_connection_settings())
  File "/home/plm/ariasousse/env/lib/python3.10/site-packages/pymysql/connections.py", line 361, in __init__
    self.connect()
  File "/home/plm/ariasousse/env/lib/python3.10/site-packages/pymysql/connections.py", line 716, in connect
    raise exc
pymysql.err.OperationalError: (2003, "Can't connect to MySQL server on '127.0.0.1' ([Errno 111] Connection refused)")
2025-04-28 18:21:32,157 ERROR frappe Could not take error snapshot: (2003, "Can't connect to MySQL server on '127.0.0.1' ([Errno 111] Connection refused)")
Site: aria.localhost
Form Dict: {}
Traceback (most recent call last):
  File "/home/plm/ariasousse/env/lib/python3.10/site-packages/pymysql/connections.py", line 649, in connect
    sock = socket.create_connection(
  File "/usr/lib/python3.10/socket.py", line 845, in create_connection
    raise err
  File "/usr/lib/python3.10/socket.py", line 833, in create_connection
    sock.connect(sa)
ConnectionRefusedError: [Errno 111] Connection refused

During handling of the above exception, another exception occurred:

Traceback (most recent call last):
  File "/home/plm/ariasousse/apps/frappe/frappe/website/serve.py", line 19, in get_response
    endpoint, renderer_instance = path_resolver.resolve()
  File "/home/plm/ariasousse/apps/frappe/frappe/website/path_resolver.py", line 38, in resolve
    resolve_redirect(self.path, request.query_string)
  File "/home/plm/ariasousse/apps/frappe/frappe/website/path_resolver.py", line 118, in resolve_redirect
    redirects += frappe.get_all(
  File "/home/plm/ariasousse/apps/frappe/frappe/__init__.py", line 2014, in get_all
    return get_list(doctype, *args, **kwargs)
  File "/home/plm/ariasousse/apps/frappe/frappe/__init__.py", line 1989, in get_list
    return frappe.model.db_query.DatabaseQuery(doctype).execute(*args, **kwargs)
  File "/home/plm/ariasousse/apps/frappe/frappe/model/db_query.py", line 191, in execute
    result = self.build_and_run()
  File "/home/plm/ariasousse/apps/frappe/frappe/model/db_query.py", line 232, in build_and_run
    return frappe.db.sql(
  File "/home/plm/ariasousse/apps/frappe/frappe/database/database.py", line 207, in sql
    self.connect()
  File "/home/plm/ariasousse/apps/frappe/frappe/database/database.py", line 112, in connect
    self._conn: "MariadbConnection" | "PostgresConnection" = self.get_connection()
  File "/home/plm/ariasousse/apps/frappe/frappe/database/mariadb/database.py", line 107, in get_connection
    conn = self._get_connection()
  File "/home/plm/ariasousse/apps/frappe/frappe/database/mariadb/database.py", line 113, in _get_connection
    return self.create_connection()
  File "/home/plm/ariasousse/apps/frappe/frappe/database/mariadb/database.py", line 116, in create_connection
    return pymysql.connect(**self.get_connection_settings())
  File "/home/plm/ariasousse/env/lib/python3.10/site-packages/pymysql/connections.py", line 361, in __init__
    self.connect()
  File "/home/plm/ariasousse/env/lib/python3.10/site-packages/pymysql/connections.py", line 716, in connect
    raise exc
pymysql.err.OperationalError: (2003, "Can't connect to MySQL server on '127.0.0.1' ([Errno 111] Connection refused)")

During handling of the above exception, another exception occurred:

Traceback (most recent call last):
  File "/home/plm/ariasousse/env/lib/python3.10/site-packages/pymysql/connections.py", line 649, in connect
    sock = socket.create_connection(
  File "/usr/lib/python3.10/socket.py", line 845, in create_connection
    raise err
  File "/usr/lib/python3.10/socket.py", line 833, in create_connection
    sock.connect(sa)
ConnectionRefusedError: [Errno 111] Connection refused

During handling of the above exception, another exception occurred:

Traceback (most recent call last):
  File "/home/plm/ariasousse/apps/frappe/frappe/app.py", line 123, in application
    response = get_response()
  File "/home/plm/ariasousse/apps/frappe/frappe/website/serve.py", line 28, in get_response
    response = ErrorPage(exception=e).render()
  File "/home/plm/ariasousse/apps/frappe/frappe/website/page_renderers/template_page.py", line 84, in render
    html = self.get_html()
  File "/home/plm/ariasousse/apps/frappe/frappe/website/utils.py", line 530, in cache_html_decorator
    html = func(*args, **kwargs)
  File "/home/plm/ariasousse/apps/frappe/frappe/website/page_renderers/template_page.py", line 92, in get_html
    self.init_context()
  File "/home/plm/ariasousse/apps/frappe/frappe/website/page_renderers/error_page.py", line 14, in init_context
    super().init_context()
  File "/home/plm/ariasousse/apps/frappe/frappe/website/page_renderers/base_template_page.py", line 15, in init_context
    self.context.update(get_website_settings())
  File "/home/plm/ariasousse/apps/frappe/frappe/website/doctype/website_settings/website_settings.py", line 263, in get_website_settings
    context.boot = get_boot_data()
  File "/home/plm/ariasousse/apps/frappe/frappe/website/utils.py", line 169, in get_boot_data
    apps = get_apps() or []
  File "/home/plm/ariasousse/apps/frappe/frappe/utils/typing_validations.py", line 31, in wrapper
    return func(*args, **kwargs)
  File "/home/plm/ariasousse/apps/frappe/frappe/apps.py", line 15, in get_apps
    allowed_workspaces = get_workspace_sidebar_items().get("pages")
  File "/home/plm/ariasousse/apps/frappe/frappe/utils/typing_validations.py", line 31, in wrapper
    return func(*args, **kwargs)
  File "/home/plm/ariasousse/apps/frappe/frappe/desk/desktop.py", line 447, in get_workspace_sidebar_items
    all_pages = frappe.get_all(
  File "/home/plm/ariasousse/apps/frappe/frappe/__init__.py", line 2014, in get_all
    return get_list(doctype, *args, **kwargs)
  File "/home/plm/ariasousse/apps/frappe/frappe/__init__.py", line 1989, in get_list
    return frappe.model.db_query.DatabaseQuery(doctype).execute(*args, **kwargs)
  File "/home/plm/ariasousse/apps/frappe/frappe/model/db_query.py", line 191, in execute
    result = self.build_and_run()
  File "/home/plm/ariasousse/apps/frappe/frappe/model/db_query.py", line 232, in build_and_run
    return frappe.db.sql(
  File "/home/plm/ariasousse/apps/frappe/frappe/database/database.py", line 207, in sql
    self.connect()
  File "/home/plm/ariasousse/apps/frappe/frappe/database/database.py", line 112, in connect
    self._conn: "MariadbConnection" | "PostgresConnection" = self.get_connection()
  File "/home/plm/ariasousse/apps/frappe/frappe/database/mariadb/database.py", line 107, in get_connection
    conn = self._get_connection()
  File "/home/plm/ariasousse/apps/frappe/frappe/database/mariadb/database.py", line 113, in _get_connection
    return self.create_connection()
  File "/home/plm/ariasousse/apps/frappe/frappe/database/mariadb/database.py", line 116, in create_connection
    return pymysql.connect(**self.get_connection_settings())
  File "/home/plm/ariasousse/env/lib/python3.10/site-packages/pymysql/connections.py", line 361, in __init__
    self.connect()
  File "/home/plm/ariasousse/env/lib/python3.10/site-packages/pymysql/connections.py", line 716, in connect
    raise exc
pymysql.err.OperationalError: (2003, "Can't connect to MySQL server on '127.0.0.1' ([Errno 111] Connection refused)")

During handling of the above exception, another exception occurred:

Traceback (most recent call last):
  File "/home/plm/ariasousse/env/lib/python3.10/site-packages/pymysql/connections.py", line 649, in connect
    sock = socket.create_connection(
  File "/usr/lib/python3.10/socket.py", line 845, in create_connection
    raise err
  File "/usr/lib/python3.10/socket.py", line 833, in create_connection
    sock.connect(sa)
ConnectionRefusedError: [Errno 111] Connection refused

During handling of the above exception, another exception occurred:

Traceback (most recent call last):
  File "/home/plm/ariasousse/apps/frappe/frappe/utils/error.py", line 86, in log_error_snapshot
    log_error(title=str(exception), defer_insert=True)
  File "/home/plm/ariasousse/apps/frappe/frappe/utils/error.py", line 61, in log_error
    error_log = frappe.get_doc(
  File "/home/plm/ariasousse/apps/frappe/frappe/__init__.py", line 1290, in get_doc
    doc = frappe.model.document.get_doc(*args, **kwargs)
  File "/home/plm/ariasousse/apps/frappe/frappe/model/document.py", line 83, in get_doc
    controller = get_controller(doctype)
  File "/home/plm/ariasousse/apps/frappe/frappe/model/base_document.py", line 70, in get_controller
    site_controllers[doctype] = import_controller(doctype)
  File "/home/plm/ariasousse/apps/frappe/frappe/model/base_document.py", line 81, in import_controller
    doctype_info = frappe.db.get_value("DocType", doctype, fieldname="*")
  File "/home/plm/ariasousse/apps/frappe/frappe/database/database.py", line 515, in get_value
    result = self.get_values(
  File "/home/plm/ariasousse/apps/frappe/frappe/database/database.py", line 619, in get_values
    out = self._get_values_from_table(
  File "/home/plm/ariasousse/apps/frappe/frappe/database/database.py", line 892, in _get_values_from_table
    return query.run(as_dict=as_dict, debug=debug, update=update, run=run, pluck=pluck)
  File "/home/plm/ariasousse/apps/frappe/frappe/query_builder/utils.py", line 87, in execute_query
    result = frappe.db.sql(query, params, *args, **kwargs)  # nosemgrep
  File "/home/plm/ariasousse/apps/frappe/frappe/database/database.py", line 207, in sql
    self.connect()
  File "/home/plm/ariasousse/apps/frappe/frappe/database/database.py", line 112, in connect
    self._conn: "MariadbConnection" | "PostgresConnection" = self.get_connection()
  File "/home/plm/ariasousse/apps/frappe/frappe/database/mariadb/database.py", line 107, in get_connection
    conn = self._get_connection()
  File "/home/plm/ariasousse/apps/frappe/frappe/database/mariadb/database.py", line 113, in _get_connection
    return self.create_connection()
  File "/home/plm/ariasousse/apps/frappe/frappe/database/mariadb/database.py", line 116, in create_connection
    return pymysql.connect(**self.get_connection_settings())
  File "/home/plm/ariasousse/env/lib/python3.10/site-packages/pymysql/connections.py", line 361, in __init__
    self.connect()
  File "/home/plm/ariasousse/env/lib/python3.10/site-packages/pymysql/connections.py", line 716, in connect
    raise exc
pymysql.err.OperationalError: (2003, "Can't connect to MySQL server on '127.0.0.1' ([Errno 111] Connection refused)")
2025-04-28 18:21:37,766 ERROR frappe Could not take error snapshot: (2003, "Can't connect to MySQL server on '127.0.0.1' ([Errno 111] Connection refused)")
Site: aria.localhost
Form Dict: {}
Traceback (most recent call last):
  File "/home/plm/ariasousse/env/lib/python3.10/site-packages/pymysql/connections.py", line 649, in connect
    sock = socket.create_connection(
  File "/usr/lib/python3.10/socket.py", line 845, in create_connection
    raise err
  File "/usr/lib/python3.10/socket.py", line 833, in create_connection
    sock.connect(sa)
ConnectionRefusedError: [Errno 111] Connection refused

During handling of the above exception, another exception occurred:

Traceback (most recent call last):
  File "/home/plm/ariasousse/apps/frappe/frappe/website/serve.py", line 19, in get_response
    endpoint, renderer_instance = path_resolver.resolve()
  File "/home/plm/ariasousse/apps/frappe/frappe/website/path_resolver.py", line 38, in resolve
    resolve_redirect(self.path, request.query_string)
  File "/home/plm/ariasousse/apps/frappe/frappe/website/path_resolver.py", line 118, in resolve_redirect
    redirects += frappe.get_all(
  File "/home/plm/ariasousse/apps/frappe/frappe/__init__.py", line 2014, in get_all
    return get_list(doctype, *args, **kwargs)
  File "/home/plm/ariasousse/apps/frappe/frappe/__init__.py", line 1989, in get_list
    return frappe.model.db_query.DatabaseQuery(doctype).execute(*args, **kwargs)
  File "/home/plm/ariasousse/apps/frappe/frappe/model/db_query.py", line 191, in execute
    result = self.build_and_run()
  File "/home/plm/ariasousse/apps/frappe/frappe/model/db_query.py", line 232, in build_and_run
    return frappe.db.sql(
  File "/home/plm/ariasousse/apps/frappe/frappe/database/database.py", line 207, in sql
    self.connect()
  File "/home/plm/ariasousse/apps/frappe/frappe/database/database.py", line 112, in connect
    self._conn: "MariadbConnection" | "PostgresConnection" = self.get_connection()
  File "/home/plm/ariasousse/apps/frappe/frappe/database/mariadb/database.py", line 107, in get_connection
    conn = self._get_connection()
  File "/home/plm/ariasousse/apps/frappe/frappe/database/mariadb/database.py", line 113, in _get_connection
    return self.create_connection()
  File "/home/plm/ariasousse/apps/frappe/frappe/database/mariadb/database.py", line 116, in create_connection
    return pymysql.connect(**self.get_connection_settings())
  File "/home/plm/ariasousse/env/lib/python3.10/site-packages/pymysql/connections.py", line 361, in __init__
    self.connect()
  File "/home/plm/ariasousse/env/lib/python3.10/site-packages/pymysql/connections.py", line 716, in connect
    raise exc
pymysql.err.OperationalError: (2003, "Can't connect to MySQL server on '127.0.0.1' ([Errno 111] Connection refused)")

During handling of the above exception, another exception occurred:

Traceback (most recent call last):
  File "/home/plm/ariasousse/env/lib/python3.10/site-packages/pymysql/connections.py", line 649, in connect
    sock = socket.create_connection(
  File "/usr/lib/python3.10/socket.py", line 845, in create_connection
    raise err
  File "/usr/lib/python3.10/socket.py", line 833, in create_connection
    sock.connect(sa)
ConnectionRefusedError: [Errno 111] Connection refused

During handling of the above exception, another exception occurred:

Traceback (most recent call last):
  File "/home/plm/ariasousse/apps/frappe/frappe/app.py", line 123, in application
    response = get_response()
  File "/home/plm/ariasousse/apps/frappe/frappe/website/serve.py", line 28, in get_response
    response = ErrorPage(exception=e).render()
  File "/home/plm/ariasousse/apps/frappe/frappe/website/page_renderers/template_page.py", line 84, in render
    html = self.get_html()
  File "/home/plm/ariasousse/apps/frappe/frappe/website/utils.py", line 530, in cache_html_decorator
    html = func(*args, **kwargs)
  File "/home/plm/ariasousse/apps/frappe/frappe/website/page_renderers/template_page.py", line 92, in get_html
    self.init_context()
  File "/home/plm/ariasousse/apps/frappe/frappe/website/page_renderers/error_page.py", line 14, in init_context
    super().init_context()
  File "/home/plm/ariasousse/apps/frappe/frappe/website/page_renderers/base_template_page.py", line 15, in init_context
    self.context.update(get_website_settings())
  File "/home/plm/ariasousse/apps/frappe/frappe/website/doctype/website_settings/website_settings.py", line 263, in get_website_settings
    context.boot = get_boot_data()
  File "/home/plm/ariasousse/apps/frappe/frappe/website/utils.py", line 169, in get_boot_data
    apps = get_apps() or []
  File "/home/plm/ariasousse/apps/frappe/frappe/utils/typing_validations.py", line 31, in wrapper
    return func(*args, **kwargs)
  File "/home/plm/ariasousse/apps/frappe/frappe/apps.py", line 15, in get_apps
    allowed_workspaces = get_workspace_sidebar_items().get("pages")
  File "/home/plm/ariasousse/apps/frappe/frappe/utils/typing_validations.py", line 31, in wrapper
    return func(*args, **kwargs)
  File "/home/plm/ariasousse/apps/frappe/frappe/desk/desktop.py", line 447, in get_workspace_sidebar_items
    all_pages = frappe.get_all(
  File "/home/plm/ariasousse/apps/frappe/frappe/__init__.py", line 2014, in get_all
    return get_list(doctype, *args, **kwargs)
  File "/home/plm/ariasousse/apps/frappe/frappe/__init__.py", line 1989, in get_list
    return frappe.model.db_query.DatabaseQuery(doctype).execute(*args, **kwargs)
  File "/home/plm/ariasousse/apps/frappe/frappe/model/db_query.py", line 191, in execute
    result = self.build_and_run()
  File "/home/plm/ariasousse/apps/frappe/frappe/model/db_query.py", line 232, in build_and_run
    return frappe.db.sql(
  File "/home/plm/ariasousse/apps/frappe/frappe/database/database.py", line 207, in sql
    self.connect()
  File "/home/plm/ariasousse/apps/frappe/frappe/database/database.py", line 112, in connect
    self._conn: "MariadbConnection" | "PostgresConnection" = self.get_connection()
  File "/home/plm/ariasousse/apps/frappe/frappe/database/mariadb/database.py", line 107, in get_connection
    conn = self._get_connection()
  File "/home/plm/ariasousse/apps/frappe/frappe/database/mariadb/database.py", line 113, in _get_connection
    return self.create_connection()
  File "/home/plm/ariasousse/apps/frappe/frappe/database/mariadb/database.py", line 116, in create_connection
    return pymysql.connect(**self.get_connection_settings())
  File "/home/plm/ariasousse/env/lib/python3.10/site-packages/pymysql/connections.py", line 361, in __init__
    self.connect()
  File "/home/plm/ariasousse/env/lib/python3.10/site-packages/pymysql/connections.py", line 716, in connect
    raise exc
pymysql.err.OperationalError: (2003, "Can't connect to MySQL server on '127.0.0.1' ([Errno 111] Connection refused)")

During handling of the above exception, another exception occurred:

Traceback (most recent call last):
  File "/home/plm/ariasousse/env/lib/python3.10/site-packages/pymysql/connections.py", line 649, in connect
    sock = socket.create_connection(
  File "/usr/lib/python3.10/socket.py", line 845, in create_connection
    raise err
  File "/usr/lib/python3.10/socket.py", line 833, in create_connection
    sock.connect(sa)
ConnectionRefusedError: [Errno 111] Connection refused

During handling of the above exception, another exception occurred:

Traceback (most recent call last):
  File "/home/plm/ariasousse/apps/frappe/frappe/utils/error.py", line 86, in log_error_snapshot
    log_error(title=str(exception), defer_insert=True)
  File "/home/plm/ariasousse/apps/frappe/frappe/utils/error.py", line 61, in log_error
    error_log = frappe.get_doc(
  File "/home/plm/ariasousse/apps/frappe/frappe/__init__.py", line 1290, in get_doc
    doc = frappe.model.document.get_doc(*args, **kwargs)
  File "/home/plm/ariasousse/apps/frappe/frappe/model/document.py", line 83, in get_doc
    controller = get_controller(doctype)
  File "/home/plm/ariasousse/apps/frappe/frappe/model/base_document.py", line 70, in get_controller
    site_controllers[doctype] = import_controller(doctype)
  File "/home/plm/ariasousse/apps/frappe/frappe/model/base_document.py", line 81, in import_controller
    doctype_info = frappe.db.get_value("DocType", doctype, fieldname="*")
  File "/home/plm/ariasousse/apps/frappe/frappe/database/database.py", line 515, in get_value
    result = self.get_values(
  File "/home/plm/ariasousse/apps/frappe/frappe/database/database.py", line 619, in get_values
    out = self._get_values_from_table(
  File "/home/plm/ariasousse/apps/frappe/frappe/database/database.py", line 892, in _get_values_from_table
    return query.run(as_dict=as_dict, debug=debug, update=update, run=run, pluck=pluck)
  File "/home/plm/ariasousse/apps/frappe/frappe/query_builder/utils.py", line 87, in execute_query
    result = frappe.db.sql(query, params, *args, **kwargs)  # nosemgrep
  File "/home/plm/ariasousse/apps/frappe/frappe/database/database.py", line 207, in sql
    self.connect()
  File "/home/plm/ariasousse/apps/frappe/frappe/database/database.py", line 112, in connect
    self._conn: "MariadbConnection" | "PostgresConnection" = self.get_connection()
  File "/home/plm/ariasousse/apps/frappe/frappe/database/mariadb/database.py", line 107, in get_connection
    conn = self._get_connection()
  File "/home/plm/ariasousse/apps/frappe/frappe/database/mariadb/database.py", line 113, in _get_connection
    return self.create_connection()
  File "/home/plm/ariasousse/apps/frappe/frappe/database/mariadb/database.py", line 116, in create_connection
    return pymysql.connect(**self.get_connection_settings())
  File "/home/plm/ariasousse/env/lib/python3.10/site-packages/pymysql/connections.py", line 361, in __init__
    self.connect()
  File "/home/plm/ariasousse/env/lib/python3.10/site-packages/pymysql/connections.py", line 716, in connect
    raise exc
pymysql.err.OperationalError: (2003, "Can't connect to MySQL server on '127.0.0.1' ([Errno 111] Connection refused)")
2025-04-28 18:21:46,066 ERROR frappe Could not take error snapshot: (2003, "Can't connect to MySQL server on '127.0.0.1' ([Errno 111] Connection refused)")
Site: aria.localhost
Form Dict: {'0x[]': '0x_0x'}
Traceback (most recent call last):
  File "/home/plm/ariasousse/env/lib/python3.10/site-packages/pymysql/connections.py", line 649, in connect
    sock = socket.create_connection(
  File "/usr/lib/python3.10/socket.py", line 845, in create_connection
    raise err
  File "/usr/lib/python3.10/socket.py", line 833, in create_connection
    sock.connect(sa)
ConnectionRefusedError: [Errno 111] Connection refused

During handling of the above exception, another exception occurred:

Traceback (most recent call last):
  File "/home/plm/ariasousse/apps/frappe/frappe/website/serve.py", line 19, in get_response
    endpoint, renderer_instance = path_resolver.resolve()
  File "/home/plm/ariasousse/apps/frappe/frappe/website/path_resolver.py", line 38, in resolve
    resolve_redirect(self.path, request.query_string)
  File "/home/plm/ariasousse/apps/frappe/frappe/website/path_resolver.py", line 118, in resolve_redirect
    redirects += frappe.get_all(
  File "/home/plm/ariasousse/apps/frappe/frappe/__init__.py", line 2014, in get_all
    return get_list(doctype, *args, **kwargs)
  File "/home/plm/ariasousse/apps/frappe/frappe/__init__.py", line 1989, in get_list
    return frappe.model.db_query.DatabaseQuery(doctype).execute(*args, **kwargs)
  File "/home/plm/ariasousse/apps/frappe/frappe/model/db_query.py", line 191, in execute
    result = self.build_and_run()
  File "/home/plm/ariasousse/apps/frappe/frappe/model/db_query.py", line 232, in build_and_run
    return frappe.db.sql(
  File "/home/plm/ariasousse/apps/frappe/frappe/database/database.py", line 207, in sql
    self.connect()
  File "/home/plm/ariasousse/apps/frappe/frappe/database/database.py", line 112, in connect
    self._conn: "MariadbConnection" | "PostgresConnection" = self.get_connection()
  File "/home/plm/ariasousse/apps/frappe/frappe/database/mariadb/database.py", line 107, in get_connection
    conn = self._get_connection()
  File "/home/plm/ariasousse/apps/frappe/frappe/database/mariadb/database.py", line 113, in _get_connection
    return self.create_connection()
  File "/home/plm/ariasousse/apps/frappe/frappe/database/mariadb/database.py", line 116, in create_connection
    return pymysql.connect(**self.get_connection_settings())
  File "/home/plm/ariasousse/env/lib/python3.10/site-packages/pymysql/connections.py", line 361, in __init__
    self.connect()
  File "/home/plm/ariasousse/env/lib/python3.10/site-packages/pymysql/connections.py", line 716, in connect
    raise exc
pymysql.err.OperationalError: (2003, "Can't connect to MySQL server on '127.0.0.1' ([Errno 111] Connection refused)")

During handling of the above exception, another exception occurred:

Traceback (most recent call last):
  File "/home/plm/ariasousse/env/lib/python3.10/site-packages/pymysql/connections.py", line 649, in connect
    sock = socket.create_connection(
  File "/usr/lib/python3.10/socket.py", line 845, in create_connection
    raise err
  File "/usr/lib/python3.10/socket.py", line 833, in create_connection
    sock.connect(sa)
ConnectionRefusedError: [Errno 111] Connection refused

During handling of the above exception, another exception occurred:

Traceback (most recent call last):
  File "/home/plm/ariasousse/apps/frappe/frappe/app.py", line 123, in application
    response = get_response()
  File "/home/plm/ariasousse/apps/frappe/frappe/website/serve.py", line 28, in get_response
    response = ErrorPage(exception=e).render()
  File "/home/plm/ariasousse/apps/frappe/frappe/website/page_renderers/template_page.py", line 84, in render
    html = self.get_html()
  File "/home/plm/ariasousse/apps/frappe/frappe/website/utils.py", line 530, in cache_html_decorator
    html = func(*args, **kwargs)
  File "/home/plm/ariasousse/apps/frappe/frappe/website/page_renderers/template_page.py", line 92, in get_html
    self.init_context()
  File "/home/plm/ariasousse/apps/frappe/frappe/website/page_renderers/error_page.py", line 14, in init_context
    super().init_context()
  File "/home/plm/ariasousse/apps/frappe/frappe/website/page_renderers/base_template_page.py", line 15, in init_context
    self.context.update(get_website_settings())
  File "/home/plm/ariasousse/apps/frappe/frappe/website/doctype/website_settings/website_settings.py", line 263, in get_website_settings
    context.boot = get_boot_data()
  File "/home/plm/ariasousse/apps/frappe/frappe/website/utils.py", line 169, in get_boot_data
    apps = get_apps() or []
  File "/home/plm/ariasousse/apps/frappe/frappe/utils/typing_validations.py", line 31, in wrapper
    return func(*args, **kwargs)
  File "/home/plm/ariasousse/apps/frappe/frappe/apps.py", line 15, in get_apps
    allowed_workspaces = get_workspace_sidebar_items().get("pages")
  File "/home/plm/ariasousse/apps/frappe/frappe/utils/typing_validations.py", line 31, in wrapper
    return func(*args, **kwargs)
  File "/home/plm/ariasousse/apps/frappe/frappe/desk/desktop.py", line 447, in get_workspace_sidebar_items
    all_pages = frappe.get_all(
  File "/home/plm/ariasousse/apps/frappe/frappe/__init__.py", line 2014, in get_all
    return get_list(doctype, *args, **kwargs)
  File "/home/plm/ariasousse/apps/frappe/frappe/__init__.py", line 1989, in get_list
    return frappe.model.db_query.DatabaseQuery(doctype).execute(*args, **kwargs)
  File "/home/plm/ariasousse/apps/frappe/frappe/model/db_query.py", line 191, in execute
    result = self.build_and_run()
  File "/home/plm/ariasousse/apps/frappe/frappe/model/db_query.py", line 232, in build_and_run
    return frappe.db.sql(
  File "/home/plm/ariasousse/apps/frappe/frappe/database/database.py", line 207, in sql
    self.connect()
  File "/home/plm/ariasousse/apps/frappe/frappe/database/database.py", line 112, in connect
    self._conn: "MariadbConnection" | "PostgresConnection" = self.get_connection()
  File "/home/plm/ariasousse/apps/frappe/frappe/database/mariadb/database.py", line 107, in get_connection
    conn = self._get_connection()
  File "/home/plm/ariasousse/apps/frappe/frappe/database/mariadb/database.py", line 113, in _get_connection
    return self.create_connection()
  File "/home/plm/ariasousse/apps/frappe/frappe/database/mariadb/database.py", line 116, in create_connection
    return pymysql.connect(**self.get_connection_settings())
  File "/home/plm/ariasousse/env/lib/python3.10/site-packages/pymysql/connections.py", line 361, in __init__
    self.connect()
  File "/home/plm/ariasousse/env/lib/python3.10/site-packages/pymysql/connections.py", line 716, in connect
    raise exc
pymysql.err.OperationalError: (2003, "Can't connect to MySQL server on '127.0.0.1' ([Errno 111] Connection refused)")

During handling of the above exception, another exception occurred:

Traceback (most recent call last):
  File "/home/plm/ariasousse/env/lib/python3.10/site-packages/pymysql/connections.py", line 649, in connect
    sock = socket.create_connection(
  File "/usr/lib/python3.10/socket.py", line 845, in create_connection
    raise err
  File "/usr/lib/python3.10/socket.py", line 833, in create_connection
    sock.connect(sa)
ConnectionRefusedError: [Errno 111] Connection refused

During handling of the above exception, another exception occurred:

Traceback (most recent call last):
  File "/home/plm/ariasousse/apps/frappe/frappe/utils/error.py", line 86, in log_error_snapshot
    log_error(title=str(exception), defer_insert=True)
  File "/home/plm/ariasousse/apps/frappe/frappe/utils/error.py", line 61, in log_error
    error_log = frappe.get_doc(
  File "/home/plm/ariasousse/apps/frappe/frappe/__init__.py", line 1290, in get_doc
    doc = frappe.model.document.get_doc(*args, **kwargs)
  File "/home/plm/ariasousse/apps/frappe/frappe/model/document.py", line 83, in get_doc
    controller = get_controller(doctype)
  File "/home/plm/ariasousse/apps/frappe/frappe/model/base_document.py", line 70, in get_controller
    site_controllers[doctype] = import_controller(doctype)
  File "/home/plm/ariasousse/apps/frappe/frappe/model/base_document.py", line 81, in import_controller
    doctype_info = frappe.db.get_value("DocType", doctype, fieldname="*")
  File "/home/plm/ariasousse/apps/frappe/frappe/database/database.py", line 515, in get_value
    result = self.get_values(
  File "/home/plm/ariasousse/apps/frappe/frappe/database/database.py", line 619, in get_values
    out = self._get_values_from_table(
  File "/home/plm/ariasousse/apps/frappe/frappe/database/database.py", line 892, in _get_values_from_table
    return query.run(as_dict=as_dict, debug=debug, update=update, run=run, pluck=pluck)
  File "/home/plm/ariasousse/apps/frappe/frappe/query_builder/utils.py", line 87, in execute_query
    result = frappe.db.sql(query, params, *args, **kwargs)  # nosemgrep
  File "/home/plm/ariasousse/apps/frappe/frappe/database/database.py", line 207, in sql
    self.connect()
  File "/home/plm/ariasousse/apps/frappe/frappe/database/database.py", line 112, in connect
    self._conn: "MariadbConnection" | "PostgresConnection" = self.get_connection()
  File "/home/plm/ariasousse/apps/frappe/frappe/database/mariadb/database.py", line 107, in get_connection
    conn = self._get_connection()
  File "/home/plm/ariasousse/apps/frappe/frappe/database/mariadb/database.py", line 113, in _get_connection
    return self.create_connection()
  File "/home/plm/ariasousse/apps/frappe/frappe/database/mariadb/database.py", line 116, in create_connection
    return pymysql.connect(**self.get_connection_settings())
  File "/home/plm/ariasousse/env/lib/python3.10/site-packages/pymysql/connections.py", line 361, in __init__
    self.connect()
  File "/home/plm/ariasousse/env/lib/python3.10/site-packages/pymysql/connections.py", line 716, in connect
    raise exc
pymysql.err.OperationalError: (2003, "Can't connect to MySQL server on '127.0.0.1' ([Errno 111] Connection refused)")
2025-04-28 18:21:51,866 ERROR frappe Could not take error snapshot: (2003, "Can't connect to MySQL server on '127.0.0.1' ([Errno 111] Connection refused)")
Site: aria.localhost
Form Dict: {}
Traceback (most recent call last):
  File "/home/plm/ariasousse/env/lib/python3.10/site-packages/pymysql/connections.py", line 649, in connect
    sock = socket.create_connection(
  File "/usr/lib/python3.10/socket.py", line 845, in create_connection
    raise err
  File "/usr/lib/python3.10/socket.py", line 833, in create_connection
    sock.connect(sa)
ConnectionRefusedError: [Errno 111] Connection refused

During handling of the above exception, another exception occurred:

Traceback (most recent call last):
  File "/home/plm/ariasousse/apps/frappe/frappe/website/serve.py", line 19, in get_response
    endpoint, renderer_instance = path_resolver.resolve()
  File "/home/plm/ariasousse/apps/frappe/frappe/website/path_resolver.py", line 38, in resolve
    resolve_redirect(self.path, request.query_string)
  File "/home/plm/ariasousse/apps/frappe/frappe/website/path_resolver.py", line 118, in resolve_redirect
    redirects += frappe.get_all(
  File "/home/plm/ariasousse/apps/frappe/frappe/__init__.py", line 2014, in get_all
    return get_list(doctype, *args, **kwargs)
  File "/home/plm/ariasousse/apps/frappe/frappe/__init__.py", line 1989, in get_list
    return frappe.model.db_query.DatabaseQuery(doctype).execute(*args, **kwargs)
  File "/home/plm/ariasousse/apps/frappe/frappe/model/db_query.py", line 191, in execute
    result = self.build_and_run()
  File "/home/plm/ariasousse/apps/frappe/frappe/model/db_query.py", line 232, in build_and_run
    return frappe.db.sql(
  File "/home/plm/ariasousse/apps/frappe/frappe/database/database.py", line 207, in sql
    self.connect()
  File "/home/plm/ariasousse/apps/frappe/frappe/database/database.py", line 112, in connect
    self._conn: "MariadbConnection" | "PostgresConnection" = self.get_connection()
  File "/home/plm/ariasousse/apps/frappe/frappe/database/mariadb/database.py", line 107, in get_connection
    conn = self._get_connection()
  File "/home/plm/ariasousse/apps/frappe/frappe/database/mariadb/database.py", line 113, in _get_connection
    return self.create_connection()
  File "/home/plm/ariasousse/apps/frappe/frappe/database/mariadb/database.py", line 116, in create_connection
    return pymysql.connect(**self.get_connection_settings())
  File "/home/plm/ariasousse/env/lib/python3.10/site-packages/pymysql/connections.py", line 361, in __init__
    self.connect()
  File "/home/plm/ariasousse/env/lib/python3.10/site-packages/pymysql/connections.py", line 716, in connect
    raise exc
pymysql.err.OperationalError: (2003, "Can't connect to MySQL server on '127.0.0.1' ([Errno 111] Connection refused)")

During handling of the above exception, another exception occurred:

Traceback (most recent call last):
  File "/home/plm/ariasousse/env/lib/python3.10/site-packages/pymysql/connections.py", line 649, in connect
    sock = socket.create_connection(
  File "/usr/lib/python3.10/socket.py", line 845, in create_connection
    raise err
  File "/usr/lib/python3.10/socket.py", line 833, in create_connection
    sock.connect(sa)
ConnectionRefusedError: [Errno 111] Connection refused

During handling of the above exception, another exception occurred:

Traceback (most recent call last):
  File "/home/plm/ariasousse/apps/frappe/frappe/app.py", line 123, in application
    response = get_response()
  File "/home/plm/ariasousse/apps/frappe/frappe/website/serve.py", line 28, in get_response
    response = ErrorPage(exception=e).render()
  File "/home/plm/ariasousse/apps/frappe/frappe/website/page_renderers/template_page.py", line 84, in render
    html = self.get_html()
  File "/home/plm/ariasousse/apps/frappe/frappe/website/utils.py", line 530, in cache_html_decorator
    html = func(*args, **kwargs)
  File "/home/plm/ariasousse/apps/frappe/frappe/website/page_renderers/template_page.py", line 92, in get_html
    self.init_context()
  File "/home/plm/ariasousse/apps/frappe/frappe/website/page_renderers/error_page.py", line 14, in init_context
    super().init_context()
  File "/home/plm/ariasousse/apps/frappe/frappe/website/page_renderers/base_template_page.py", line 15, in init_context
    self.context.update(get_website_settings())
  File "/home/plm/ariasousse/apps/frappe/frappe/website/doctype/website_settings/website_settings.py", line 263, in get_website_settings
    context.boot = get_boot_data()
  File "/home/plm/ariasousse/apps/frappe/frappe/website/utils.py", line 169, in get_boot_data
    apps = get_apps() or []
  File "/home/plm/ariasousse/apps/frappe/frappe/utils/typing_validations.py", line 31, in wrapper
    return func(*args, **kwargs)
  File "/home/plm/ariasousse/apps/frappe/frappe/apps.py", line 15, in get_apps
    allowed_workspaces = get_workspace_sidebar_items().get("pages")
  File "/home/plm/ariasousse/apps/frappe/frappe/utils/typing_validations.py", line 31, in wrapper
    return func(*args, **kwargs)
  File "/home/plm/ariasousse/apps/frappe/frappe/desk/desktop.py", line 447, in get_workspace_sidebar_items
    all_pages = frappe.get_all(
  File "/home/plm/ariasousse/apps/frappe/frappe/__init__.py", line 2014, in get_all
    return get_list(doctype, *args, **kwargs)
  File "/home/plm/ariasousse/apps/frappe/frappe/__init__.py", line 1989, in get_list
    return frappe.model.db_query.DatabaseQuery(doctype).execute(*args, **kwargs)
  File "/home/plm/ariasousse/apps/frappe/frappe/model/db_query.py", line 191, in execute
    result = self.build_and_run()
  File "/home/plm/ariasousse/apps/frappe/frappe/model/db_query.py", line 232, in build_and_run
    return frappe.db.sql(
  File "/home/plm/ariasousse/apps/frappe/frappe/database/database.py", line 207, in sql
    self.connect()
  File "/home/plm/ariasousse/apps/frappe/frappe/database/database.py", line 112, in connect
    self._conn: "MariadbConnection" | "PostgresConnection" = self.get_connection()
  File "/home/plm/ariasousse/apps/frappe/frappe/database/mariadb/database.py", line 107, in get_connection
    conn = self._get_connection()
  File "/home/plm/ariasousse/apps/frappe/frappe/database/mariadb/database.py", line 113, in _get_connection
    return self.create_connection()
  File "/home/plm/ariasousse/apps/frappe/frappe/database/mariadb/database.py", line 116, in create_connection
    return pymysql.connect(**self.get_connection_settings())
  File "/home/plm/ariasousse/env/lib/python3.10/site-packages/pymysql/connections.py", line 361, in __init__
    self.connect()
  File "/home/plm/ariasousse/env/lib/python3.10/site-packages/pymysql/connections.py", line 716, in connect
    raise exc
pymysql.err.OperationalError: (2003, "Can't connect to MySQL server on '127.0.0.1' ([Errno 111] Connection refused)")

During handling of the above exception, another exception occurred:

Traceback (most recent call last):
  File "/home/plm/ariasousse/env/lib/python3.10/site-packages/pymysql/connections.py", line 649, in connect
    sock = socket.create_connection(
  File "/usr/lib/python3.10/socket.py", line 845, in create_connection
    raise err
  File "/usr/lib/python3.10/socket.py", line 833, in create_connection
    sock.connect(sa)
ConnectionRefusedError: [Errno 111] Connection refused

During handling of the above exception, another exception occurred:

Traceback (most recent call last):
  File "/home/plm/ariasousse/apps/frappe/frappe/utils/error.py", line 86, in log_error_snapshot
    log_error(title=str(exception), defer_insert=True)
  File "/home/plm/ariasousse/apps/frappe/frappe/utils/error.py", line 61, in log_error
    error_log = frappe.get_doc(
  File "/home/plm/ariasousse/apps/frappe/frappe/__init__.py", line 1290, in get_doc
    doc = frappe.model.document.get_doc(*args, **kwargs)
  File "/home/plm/ariasousse/apps/frappe/frappe/model/document.py", line 83, in get_doc
    controller = get_controller(doctype)
  File "/home/plm/ariasousse/apps/frappe/frappe/model/base_document.py", line 70, in get_controller
    site_controllers[doctype] = import_controller(doctype)
  File "/home/plm/ariasousse/apps/frappe/frappe/model/base_document.py", line 81, in import_controller
    doctype_info = frappe.db.get_value("DocType", doctype, fieldname="*")
  File "/home/plm/ariasousse/apps/frappe/frappe/database/database.py", line 515, in get_value
    result = self.get_values(
  File "/home/plm/ariasousse/apps/frappe/frappe/database/database.py", line 619, in get_values
    out = self._get_values_from_table(
  File "/home/plm/ariasousse/apps/frappe/frappe/database/database.py", line 892, in _get_values_from_table
    return query.run(as_dict=as_dict, debug=debug, update=update, run=run, pluck=pluck)
  File "/home/plm/ariasousse/apps/frappe/frappe/query_builder/utils.py", line 87, in execute_query
    result = frappe.db.sql(query, params, *args, **kwargs)  # nosemgrep
  File "/home/plm/ariasousse/apps/frappe/frappe/database/database.py", line 207, in sql
    self.connect()
  File "/home/plm/ariasousse/apps/frappe/frappe/database/database.py", line 112, in connect
    self._conn: "MariadbConnection" | "PostgresConnection" = self.get_connection()
  File "/home/plm/ariasousse/apps/frappe/frappe/database/mariadb/database.py", line 107, in get_connection
    conn = self._get_connection()
  File "/home/plm/ariasousse/apps/frappe/frappe/database/mariadb/database.py", line 113, in _get_connection
    return self.create_connection()
  File "/home/plm/ariasousse/apps/frappe/frappe/database/mariadb/database.py", line 116, in create_connection
    return pymysql.connect(**self.get_connection_settings())
  File "/home/plm/ariasousse/env/lib/python3.10/site-packages/pymysql/connections.py", line 361, in __init__
    self.connect()
  File "/home/plm/ariasousse/env/lib/python3.10/site-packages/pymysql/connections.py", line 716, in connect
    raise exc
pymysql.err.OperationalError: (2003, "Can't connect to MySQL server on '127.0.0.1' ([Errno 111] Connection refused)")
2025-04-29 00:03:07,811 ERROR frappe Could not take error snapshot: (2003, "Can't connect to MySQL server on '127.0.0.1' ([Errno 111] Connection refused)")
Site: aria.localhost
Form Dict: {}
Traceback (most recent call last):
  File "/home/plm/ariasousse/env/lib/python3.10/site-packages/pymysql/connections.py", line 649, in connect
    sock = socket.create_connection(
  File "/usr/lib/python3.10/socket.py", line 845, in create_connection
    raise err
  File "/usr/lib/python3.10/socket.py", line 833, in create_connection
    sock.connect(sa)
ConnectionRefusedError: [Errno 111] Connection refused

During handling of the above exception, another exception occurred:

Traceback (most recent call last):
  File "/home/plm/ariasousse/apps/frappe/frappe/website/serve.py", line 19, in get_response
    endpoint, renderer_instance = path_resolver.resolve()
  File "/home/plm/ariasousse/apps/frappe/frappe/website/path_resolver.py", line 38, in resolve
    resolve_redirect(self.path, request.query_string)
  File "/home/plm/ariasousse/apps/frappe/frappe/website/path_resolver.py", line 118, in resolve_redirect
    redirects += frappe.get_all(
  File "/home/plm/ariasousse/apps/frappe/frappe/__init__.py", line 2014, in get_all
    return get_list(doctype, *args, **kwargs)
  File "/home/plm/ariasousse/apps/frappe/frappe/__init__.py", line 1989, in get_list
    return frappe.model.db_query.DatabaseQuery(doctype).execute(*args, **kwargs)
  File "/home/plm/ariasousse/apps/frappe/frappe/model/db_query.py", line 191, in execute
    result = self.build_and_run()
  File "/home/plm/ariasousse/apps/frappe/frappe/model/db_query.py", line 232, in build_and_run
    return frappe.db.sql(
  File "/home/plm/ariasousse/apps/frappe/frappe/database/database.py", line 207, in sql
    self.connect()
  File "/home/plm/ariasousse/apps/frappe/frappe/database/database.py", line 112, in connect
    self._conn: "MariadbConnection" | "PostgresConnection" = self.get_connection()
  File "/home/plm/ariasousse/apps/frappe/frappe/database/mariadb/database.py", line 107, in get_connection
    conn = self._get_connection()
  File "/home/plm/ariasousse/apps/frappe/frappe/database/mariadb/database.py", line 113, in _get_connection
    return self.create_connection()
  File "/home/plm/ariasousse/apps/frappe/frappe/database/mariadb/database.py", line 116, in create_connection
    return pymysql.connect(**self.get_connection_settings())
  File "/home/plm/ariasousse/env/lib/python3.10/site-packages/pymysql/connections.py", line 361, in __init__
    self.connect()
  File "/home/plm/ariasousse/env/lib/python3.10/site-packages/pymysql/connections.py", line 716, in connect
    raise exc
pymysql.err.OperationalError: (2003, "Can't connect to MySQL server on '127.0.0.1' ([Errno 111] Connection refused)")

During handling of the above exception, another exception occurred:

Traceback (most recent call last):
  File "/home/plm/ariasousse/env/lib/python3.10/site-packages/pymysql/connections.py", line 649, in connect
    sock = socket.create_connection(
  File "/usr/lib/python3.10/socket.py", line 845, in create_connection
    raise err
  File "/usr/lib/python3.10/socket.py", line 833, in create_connection
    sock.connect(sa)
ConnectionRefusedError: [Errno 111] Connection refused

During handling of the above exception, another exception occurred:

Traceback (most recent call last):
  File "/home/plm/ariasousse/apps/frappe/frappe/app.py", line 123, in application
    response = get_response()
  File "/home/plm/ariasousse/apps/frappe/frappe/website/serve.py", line 28, in get_response
    response = ErrorPage(exception=e).render()
  File "/home/plm/ariasousse/apps/frappe/frappe/website/page_renderers/template_page.py", line 84, in render
    html = self.get_html()
  File "/home/plm/ariasousse/apps/frappe/frappe/website/utils.py", line 530, in cache_html_decorator
    html = func(*args, **kwargs)
  File "/home/plm/ariasousse/apps/frappe/frappe/website/page_renderers/template_page.py", line 92, in get_html
    self.init_context()
  File "/home/plm/ariasousse/apps/frappe/frappe/website/page_renderers/error_page.py", line 14, in init_context
    super().init_context()
  File "/home/plm/ariasousse/apps/frappe/frappe/website/page_renderers/base_template_page.py", line 15, in init_context
    self.context.update(get_website_settings())
  File "/home/plm/ariasousse/apps/frappe/frappe/website/doctype/website_settings/website_settings.py", line 263, in get_website_settings
    context.boot = get_boot_data()
  File "/home/plm/ariasousse/apps/frappe/frappe/website/utils.py", line 169, in get_boot_data
    apps = get_apps() or []
  File "/home/plm/ariasousse/apps/frappe/frappe/utils/typing_validations.py", line 31, in wrapper
    return func(*args, **kwargs)
  File "/home/plm/ariasousse/apps/frappe/frappe/apps.py", line 15, in get_apps
    allowed_workspaces = get_workspace_sidebar_items().get("pages")
  File "/home/plm/ariasousse/apps/frappe/frappe/utils/typing_validations.py", line 31, in wrapper
    return func(*args, **kwargs)
  File "/home/plm/ariasousse/apps/frappe/frappe/desk/desktop.py", line 447, in get_workspace_sidebar_items
    all_pages = frappe.get_all(
  File "/home/plm/ariasousse/apps/frappe/frappe/__init__.py", line 2014, in get_all
    return get_list(doctype, *args, **kwargs)
  File "/home/plm/ariasousse/apps/frappe/frappe/__init__.py", line 1989, in get_list
    return frappe.model.db_query.DatabaseQuery(doctype).execute(*args, **kwargs)
  File "/home/plm/ariasousse/apps/frappe/frappe/model/db_query.py", line 191, in execute
    result = self.build_and_run()
  File "/home/plm/ariasousse/apps/frappe/frappe/model/db_query.py", line 232, in build_and_run
    return frappe.db.sql(
  File "/home/plm/ariasousse/apps/frappe/frappe/database/database.py", line 207, in sql
    self.connect()
  File "/home/plm/ariasousse/apps/frappe/frappe/database/database.py", line 112, in connect
    self._conn: "MariadbConnection" | "PostgresConnection" = self.get_connection()
  File "/home/plm/ariasousse/apps/frappe/frappe/database/mariadb/database.py", line 107, in get_connection
    conn = self._get_connection()
  File "/home/plm/ariasousse/apps/frappe/frappe/database/mariadb/database.py", line 113, in _get_connection
    return self.create_connection()
  File "/home/plm/ariasousse/apps/frappe/frappe/database/mariadb/database.py", line 116, in create_connection
    return pymysql.connect(**self.get_connection_settings())
  File "/home/plm/ariasousse/env/lib/python3.10/site-packages/pymysql/connections.py", line 361, in __init__
    self.connect()
  File "/home/plm/ariasousse/env/lib/python3.10/site-packages/pymysql/connections.py", line 716, in connect
    raise exc
pymysql.err.OperationalError: (2003, "Can't connect to MySQL server on '127.0.0.1' ([Errno 111] Connection refused)")

During handling of the above exception, another exception occurred:

Traceback (most recent call last):
  File "/home/plm/ariasousse/env/lib/python3.10/site-packages/pymysql/connections.py", line 649, in connect
    sock = socket.create_connection(
  File "/usr/lib/python3.10/socket.py", line 845, in create_connection
    raise err
  File "/usr/lib/python3.10/socket.py", line 833, in create_connection
    sock.connect(sa)
ConnectionRefusedError: [Errno 111] Connection refused

During handling of the above exception, another exception occurred:

Traceback (most recent call last):
  File "/home/plm/ariasousse/apps/frappe/frappe/utils/error.py", line 86, in log_error_snapshot
    log_error(title=str(exception), defer_insert=True)
  File "/home/plm/ariasousse/apps/frappe/frappe/utils/error.py", line 61, in log_error
    error_log = frappe.get_doc(
  File "/home/plm/ariasousse/apps/frappe/frappe/__init__.py", line 1290, in get_doc
    doc = frappe.model.document.get_doc(*args, **kwargs)
  File "/home/plm/ariasousse/apps/frappe/frappe/model/document.py", line 83, in get_doc
    controller = get_controller(doctype)
  File "/home/plm/ariasousse/apps/frappe/frappe/model/base_document.py", line 70, in get_controller
    site_controllers[doctype] = import_controller(doctype)
  File "/home/plm/ariasousse/apps/frappe/frappe/model/base_document.py", line 81, in import_controller
    doctype_info = frappe.db.get_value("DocType", doctype, fieldname="*")
  File "/home/plm/ariasousse/apps/frappe/frappe/database/database.py", line 515, in get_value
    result = self.get_values(
  File "/home/plm/ariasousse/apps/frappe/frappe/database/database.py", line 619, in get_values
    out = self._get_values_from_table(
  File "/home/plm/ariasousse/apps/frappe/frappe/database/database.py", line 892, in _get_values_from_table
    return query.run(as_dict=as_dict, debug=debug, update=update, run=run, pluck=pluck)
  File "/home/plm/ariasousse/apps/frappe/frappe/query_builder/utils.py", line 87, in execute_query
    result = frappe.db.sql(query, params, *args, **kwargs)  # nosemgrep
  File "/home/plm/ariasousse/apps/frappe/frappe/database/database.py", line 207, in sql
    self.connect()
  File "/home/plm/ariasousse/apps/frappe/frappe/database/database.py", line 112, in connect
    self._conn: "MariadbConnection" | "PostgresConnection" = self.get_connection()
  File "/home/plm/ariasousse/apps/frappe/frappe/database/mariadb/database.py", line 107, in get_connection
    conn = self._get_connection()
  File "/home/plm/ariasousse/apps/frappe/frappe/database/mariadb/database.py", line 113, in _get_connection
    return self.create_connection()
  File "/home/plm/ariasousse/apps/frappe/frappe/database/mariadb/database.py", line 116, in create_connection
    return pymysql.connect(**self.get_connection_settings())
  File "/home/plm/ariasousse/env/lib/python3.10/site-packages/pymysql/connections.py", line 361, in __init__
    self.connect()
  File "/home/plm/ariasousse/env/lib/python3.10/site-packages/pymysql/connections.py", line 716, in connect
    raise exc
pymysql.err.OperationalError: (2003, "Can't connect to MySQL server on '127.0.0.1' ([Errno 111] Connection refused)")
2025-04-29 07:29:40,567 ERROR frappe Could not take error snapshot: (2003, "Can't connect to MySQL server on '127.0.0.1' ([Errno 111] Connection refused)")
Site: aria.localhost
Form Dict: {}
Traceback (most recent call last):
  File "/home/plm/ariasousse/env/lib/python3.10/site-packages/pymysql/connections.py", line 649, in connect
    sock = socket.create_connection(
  File "/usr/lib/python3.10/socket.py", line 845, in create_connection
    raise err
  File "/usr/lib/python3.10/socket.py", line 833, in create_connection
    sock.connect(sa)
ConnectionRefusedError: [Errno 111] Connection refused

During handling of the above exception, another exception occurred:

Traceback (most recent call last):
  File "/home/plm/ariasousse/apps/frappe/frappe/website/serve.py", line 19, in get_response
    endpoint, renderer_instance = path_resolver.resolve()
  File "/home/plm/ariasousse/apps/frappe/frappe/website/path_resolver.py", line 38, in resolve
    resolve_redirect(self.path, request.query_string)
  File "/home/plm/ariasousse/apps/frappe/frappe/website/path_resolver.py", line 118, in resolve_redirect
    redirects += frappe.get_all(
  File "/home/plm/ariasousse/apps/frappe/frappe/__init__.py", line 2014, in get_all
    return get_list(doctype, *args, **kwargs)
  File "/home/plm/ariasousse/apps/frappe/frappe/__init__.py", line 1989, in get_list
    return frappe.model.db_query.DatabaseQuery(doctype).execute(*args, **kwargs)
  File "/home/plm/ariasousse/apps/frappe/frappe/model/db_query.py", line 191, in execute
    result = self.build_and_run()
  File "/home/plm/ariasousse/apps/frappe/frappe/model/db_query.py", line 232, in build_and_run
    return frappe.db.sql(
  File "/home/plm/ariasousse/apps/frappe/frappe/database/database.py", line 207, in sql
    self.connect()
  File "/home/plm/ariasousse/apps/frappe/frappe/database/database.py", line 112, in connect
    self._conn: "MariadbConnection" | "PostgresConnection" = self.get_connection()
  File "/home/plm/ariasousse/apps/frappe/frappe/database/mariadb/database.py", line 107, in get_connection
    conn = self._get_connection()
  File "/home/plm/ariasousse/apps/frappe/frappe/database/mariadb/database.py", line 113, in _get_connection
    return self.create_connection()
  File "/home/plm/ariasousse/apps/frappe/frappe/database/mariadb/database.py", line 116, in create_connection
    return pymysql.connect(**self.get_connection_settings())
  File "/home/plm/ariasousse/env/lib/python3.10/site-packages/pymysql/connections.py", line 361, in __init__
    self.connect()
  File "/home/plm/ariasousse/env/lib/python3.10/site-packages/pymysql/connections.py", line 716, in connect
    raise exc
pymysql.err.OperationalError: (2003, "Can't connect to MySQL server on '127.0.0.1' ([Errno 111] Connection refused)")

During handling of the above exception, another exception occurred:

Traceback (most recent call last):
  File "/home/plm/ariasousse/env/lib/python3.10/site-packages/pymysql/connections.py", line 649, in connect
    sock = socket.create_connection(
  File "/usr/lib/python3.10/socket.py", line 845, in create_connection
    raise err
  File "/usr/lib/python3.10/socket.py", line 833, in create_connection
    sock.connect(sa)
ConnectionRefusedError: [Errno 111] Connection refused

During handling of the above exception, another exception occurred:

Traceback (most recent call last):
  File "/home/plm/ariasousse/apps/frappe/frappe/app.py", line 123, in application
    response = get_response()
  File "/home/plm/ariasousse/apps/frappe/frappe/website/serve.py", line 28, in get_response
    response = ErrorPage(exception=e).render()
  File "/home/plm/ariasousse/apps/frappe/frappe/website/page_renderers/template_page.py", line 84, in render
    html = self.get_html()
  File "/home/plm/ariasousse/apps/frappe/frappe/website/utils.py", line 530, in cache_html_decorator
    html = func(*args, **kwargs)
  File "/home/plm/ariasousse/apps/frappe/frappe/website/page_renderers/template_page.py", line 92, in get_html
    self.init_context()
  File "/home/plm/ariasousse/apps/frappe/frappe/website/page_renderers/error_page.py", line 14, in init_context
    super().init_context()
  File "/home/plm/ariasousse/apps/frappe/frappe/website/page_renderers/base_template_page.py", line 15, in init_context
    self.context.update(get_website_settings())
  File "/home/plm/ariasousse/apps/frappe/frappe/website/doctype/website_settings/website_settings.py", line 263, in get_website_settings
    context.boot = get_boot_data()
  File "/home/plm/ariasousse/apps/frappe/frappe/website/utils.py", line 169, in get_boot_data
    apps = get_apps() or []
  File "/home/plm/ariasousse/apps/frappe/frappe/utils/typing_validations.py", line 31, in wrapper
    return func(*args, **kwargs)
  File "/home/plm/ariasousse/apps/frappe/frappe/apps.py", line 15, in get_apps
    allowed_workspaces = get_workspace_sidebar_items().get("pages")
  File "/home/plm/ariasousse/apps/frappe/frappe/utils/typing_validations.py", line 31, in wrapper
    return func(*args, **kwargs)
  File "/home/plm/ariasousse/apps/frappe/frappe/desk/desktop.py", line 447, in get_workspace_sidebar_items
    all_pages = frappe.get_all(
  File "/home/plm/ariasousse/apps/frappe/frappe/__init__.py", line 2014, in get_all
    return get_list(doctype, *args, **kwargs)
  File "/home/plm/ariasousse/apps/frappe/frappe/__init__.py", line 1989, in get_list
    return frappe.model.db_query.DatabaseQuery(doctype).execute(*args, **kwargs)
  File "/home/plm/ariasousse/apps/frappe/frappe/model/db_query.py", line 191, in execute
    result = self.build_and_run()
  File "/home/plm/ariasousse/apps/frappe/frappe/model/db_query.py", line 232, in build_and_run
    return frappe.db.sql(
  File "/home/plm/ariasousse/apps/frappe/frappe/database/database.py", line 207, in sql
    self.connect()
  File "/home/plm/ariasousse/apps/frappe/frappe/database/database.py", line 112, in connect
    self._conn: "MariadbConnection" | "PostgresConnection" = self.get_connection()
  File "/home/plm/ariasousse/apps/frappe/frappe/database/mariadb/database.py", line 107, in get_connection
    conn = self._get_connection()
  File "/home/plm/ariasousse/apps/frappe/frappe/database/mariadb/database.py", line 113, in _get_connection
    return self.create_connection()
  File "/home/plm/ariasousse/apps/frappe/frappe/database/mariadb/database.py", line 116, in create_connection
    return pymysql.connect(**self.get_connection_settings())
  File "/home/plm/ariasousse/env/lib/python3.10/site-packages/pymysql/connections.py", line 361, in __init__
    self.connect()
  File "/home/plm/ariasousse/env/lib/python3.10/site-packages/pymysql/connections.py", line 716, in connect
    raise exc
pymysql.err.OperationalError: (2003, "Can't connect to MySQL server on '127.0.0.1' ([Errno 111] Connection refused)")

During handling of the above exception, another exception occurred:

Traceback (most recent call last):
  File "/home/plm/ariasousse/env/lib/python3.10/site-packages/pymysql/connections.py", line 649, in connect
    sock = socket.create_connection(
  File "/usr/lib/python3.10/socket.py", line 845, in create_connection
    raise err
  File "/usr/lib/python3.10/socket.py", line 833, in create_connection
    sock.connect(sa)
ConnectionRefusedError: [Errno 111] Connection refused

During handling of the above exception, another exception occurred:

Traceback (most recent call last):
  File "/home/plm/ariasousse/apps/frappe/frappe/utils/error.py", line 86, in log_error_snapshot
    log_error(title=str(exception), defer_insert=True)
  File "/home/plm/ariasousse/apps/frappe/frappe/utils/error.py", line 61, in log_error
    error_log = frappe.get_doc(
  File "/home/plm/ariasousse/apps/frappe/frappe/__init__.py", line 1290, in get_doc
    doc = frappe.model.document.get_doc(*args, **kwargs)
  File "/home/plm/ariasousse/apps/frappe/frappe/model/document.py", line 83, in get_doc
    controller = get_controller(doctype)
  File "/home/plm/ariasousse/apps/frappe/frappe/model/base_document.py", line 70, in get_controller
    site_controllers[doctype] = import_controller(doctype)
  File "/home/plm/ariasousse/apps/frappe/frappe/model/base_document.py", line 81, in import_controller
    doctype_info = frappe.db.get_value("DocType", doctype, fieldname="*")
  File "/home/plm/ariasousse/apps/frappe/frappe/database/database.py", line 515, in get_value
    result = self.get_values(
  File "/home/plm/ariasousse/apps/frappe/frappe/database/database.py", line 619, in get_values
    out = self._get_values_from_table(
  File "/home/plm/ariasousse/apps/frappe/frappe/database/database.py", line 892, in _get_values_from_table
    return query.run(as_dict=as_dict, debug=debug, update=update, run=run, pluck=pluck)
  File "/home/plm/ariasousse/apps/frappe/frappe/query_builder/utils.py", line 87, in execute_query
    result = frappe.db.sql(query, params, *args, **kwargs)  # nosemgrep
  File "/home/plm/ariasousse/apps/frappe/frappe/database/database.py", line 207, in sql
    self.connect()
  File "/home/plm/ariasousse/apps/frappe/frappe/database/database.py", line 112, in connect
    self._conn: "MariadbConnection" | "PostgresConnection" = self.get_connection()
  File "/home/plm/ariasousse/apps/frappe/frappe/database/mariadb/database.py", line 107, in get_connection
    conn = self._get_connection()
  File "/home/plm/ariasousse/apps/frappe/frappe/database/mariadb/database.py", line 113, in _get_connection
    return self.create_connection()
  File "/home/plm/ariasousse/apps/frappe/frappe/database/mariadb/database.py", line 116, in create_connection
    return pymysql.connect(**self.get_connection_settings())
  File "/home/plm/ariasousse/env/lib/python3.10/site-packages/pymysql/connections.py", line 361, in __init__
    self.connect()
  File "/home/plm/ariasousse/env/lib/python3.10/site-packages/pymysql/connections.py", line 716, in connect
    raise exc
pymysql.err.OperationalError: (2003, "Can't connect to MySQL server on '127.0.0.1' ([Errno 111] Connection refused)")
