2025-01-19 12:59:59,772 ERROR scheduler Exception in Enqueue Events for Site abc.localhost
Traceback (most recent call last):
  File "/home/plm/ariasousse/env/lib/python3.10/site-packages/pymysql/connections.py", line 649, in connect
    sock = socket.create_connection(
  File "/usr/lib/python3.10/socket.py", line 845, in create_connection
    raise err
  File "/usr/lib/python3.10/socket.py", line 833, in create_connection
    sock.connect(sa)
ConnectionRefusedError: [Errno 111] Connection refused

During handling of the above exception, another exception occurred:

Traceback (most recent call last):
  File "/home/plm/ariasousse/apps/frappe/frappe/utils/scheduler.py", line 75, in enqueue_events_for_site
    if is_scheduler_inactive():
  File "/home/plm/ariasousse/apps/frappe/frappe/utils/scheduler.py", line 117, in is_scheduler_inactive
    if is_scheduler_disabled(verbose=verbose):
  File "/home/plm/ariasousse/apps/frappe/frappe/utils/scheduler.py", line 130, in is_scheduler_disabled
    frappe.db.get_single_value("System Settings", "enable_scheduler")
  File "/home/plm/ariasousse/apps/frappe/frappe/database/database.py", line 837, in get_single_value
    ).run()
  File "/home/plm/ariasousse/apps/frappe/frappe/query_builder/utils.py", line 87, in execute_query
    result = frappe.db.sql(query, params, *args, **kwargs)  # nosemgrep
  File "/home/plm/ariasousse/apps/frappe/frappe/database/database.py", line 207, in sql
    self.connect()
  File "/home/plm/ariasousse/apps/frappe/frappe/database/database.py", line 112, in connect
    self._conn: "MariadbConnection" | "PostgresConnection" = self.get_connection()
  File "/home/plm/ariasousse/apps/frappe/frappe/database/mariadb/database.py", line 107, in get_connection
    conn = self._get_connection()
  File "/home/plm/ariasousse/apps/frappe/frappe/database/mariadb/database.py", line 113, in _get_connection
    return self.create_connection()
  File "/home/plm/ariasousse/apps/frappe/frappe/database/mariadb/database.py", line 116, in create_connection
    return pymysql.connect(**self.get_connection_settings())
  File "/home/plm/ariasousse/env/lib/python3.10/site-packages/pymysql/connections.py", line 361, in __init__
    self.connect()
  File "/home/plm/ariasousse/env/lib/python3.10/site-packages/pymysql/connections.py", line 716, in connect
    raise exc
pymysql.err.OperationalError: (2003, "Can't connect to MySQL server on '127.0.0.1' ([Errno 111] Connection refused)")
2025-01-19 13:00:59,848 ERROR scheduler Exception in Enqueue Events for Site abc.localhost
Traceback (most recent call last):
  File "/home/plm/ariasousse/env/lib/python3.10/site-packages/pymysql/connections.py", line 649, in connect
    sock = socket.create_connection(
  File "/usr/lib/python3.10/socket.py", line 845, in create_connection
    raise err
  File "/usr/lib/python3.10/socket.py", line 833, in create_connection
    sock.connect(sa)
ConnectionRefusedError: [Errno 111] Connection refused

During handling of the above exception, another exception occurred:

Traceback (most recent call last):
  File "/home/plm/ariasousse/apps/frappe/frappe/utils/scheduler.py", line 75, in enqueue_events_for_site
    if is_scheduler_inactive():
  File "/home/plm/ariasousse/apps/frappe/frappe/utils/scheduler.py", line 117, in is_scheduler_inactive
    if is_scheduler_disabled(verbose=verbose):
  File "/home/plm/ariasousse/apps/frappe/frappe/utils/scheduler.py", line 130, in is_scheduler_disabled
    frappe.db.get_single_value("System Settings", "enable_scheduler")
  File "/home/plm/ariasousse/apps/frappe/frappe/database/database.py", line 837, in get_single_value
    ).run()
  File "/home/plm/ariasousse/apps/frappe/frappe/query_builder/utils.py", line 87, in execute_query
    result = frappe.db.sql(query, params, *args, **kwargs)  # nosemgrep
  File "/home/plm/ariasousse/apps/frappe/frappe/database/database.py", line 207, in sql
    self.connect()
  File "/home/plm/ariasousse/apps/frappe/frappe/database/database.py", line 112, in connect
    self._conn: "MariadbConnection" | "PostgresConnection" = self.get_connection()
  File "/home/plm/ariasousse/apps/frappe/frappe/database/mariadb/database.py", line 107, in get_connection
    conn = self._get_connection()
  File "/home/plm/ariasousse/apps/frappe/frappe/database/mariadb/database.py", line 113, in _get_connection
    return self.create_connection()
  File "/home/plm/ariasousse/apps/frappe/frappe/database/mariadb/database.py", line 116, in create_connection
    return pymysql.connect(**self.get_connection_settings())
  File "/home/plm/ariasousse/env/lib/python3.10/site-packages/pymysql/connections.py", line 361, in __init__
    self.connect()
  File "/home/plm/ariasousse/env/lib/python3.10/site-packages/pymysql/connections.py", line 716, in connect
    raise exc
pymysql.err.OperationalError: (2003, "Can't connect to MySQL server on '127.0.0.1' ([Errno 111] Connection refused)")
2025-01-19 13:01:59,955 ERROR scheduler Exception in Enqueue Events for Site abc.localhost
Traceback (most recent call last):
  File "/home/plm/ariasousse/env/lib/python3.10/site-packages/pymysql/connections.py", line 649, in connect
    sock = socket.create_connection(
  File "/usr/lib/python3.10/socket.py", line 845, in create_connection
    raise err
  File "/usr/lib/python3.10/socket.py", line 833, in create_connection
    sock.connect(sa)
ConnectionRefusedError: [Errno 111] Connection refused

During handling of the above exception, another exception occurred:

Traceback (most recent call last):
  File "/home/plm/ariasousse/apps/frappe/frappe/utils/scheduler.py", line 75, in enqueue_events_for_site
    if is_scheduler_inactive():
  File "/home/plm/ariasousse/apps/frappe/frappe/utils/scheduler.py", line 117, in is_scheduler_inactive
    if is_scheduler_disabled(verbose=verbose):
  File "/home/plm/ariasousse/apps/frappe/frappe/utils/scheduler.py", line 130, in is_scheduler_disabled
    frappe.db.get_single_value("System Settings", "enable_scheduler")
  File "/home/plm/ariasousse/apps/frappe/frappe/database/database.py", line 837, in get_single_value
    ).run()
  File "/home/plm/ariasousse/apps/frappe/frappe/query_builder/utils.py", line 87, in execute_query
    result = frappe.db.sql(query, params, *args, **kwargs)  # nosemgrep
  File "/home/plm/ariasousse/apps/frappe/frappe/database/database.py", line 207, in sql
    self.connect()
  File "/home/plm/ariasousse/apps/frappe/frappe/database/database.py", line 112, in connect
    self._conn: "MariadbConnection" | "PostgresConnection" = self.get_connection()
  File "/home/plm/ariasousse/apps/frappe/frappe/database/mariadb/database.py", line 107, in get_connection
    conn = self._get_connection()
  File "/home/plm/ariasousse/apps/frappe/frappe/database/mariadb/database.py", line 113, in _get_connection
    return self.create_connection()
  File "/home/plm/ariasousse/apps/frappe/frappe/database/mariadb/database.py", line 116, in create_connection
    return pymysql.connect(**self.get_connection_settings())
  File "/home/plm/ariasousse/env/lib/python3.10/site-packages/pymysql/connections.py", line 361, in __init__
    self.connect()
  File "/home/plm/ariasousse/env/lib/python3.10/site-packages/pymysql/connections.py", line 716, in connect
    raise exc
pymysql.err.OperationalError: (2003, "Can't connect to MySQL server on '127.0.0.1' ([Errno 111] Connection refused)")
2025-01-19 13:03:00,063 ERROR scheduler Exception in Enqueue Events for Site abc.localhost
Traceback (most recent call last):
  File "/home/plm/ariasousse/env/lib/python3.10/site-packages/pymysql/connections.py", line 649, in connect
    sock = socket.create_connection(
  File "/usr/lib/python3.10/socket.py", line 845, in create_connection
    raise err
  File "/usr/lib/python3.10/socket.py", line 833, in create_connection
    sock.connect(sa)
ConnectionRefusedError: [Errno 111] Connection refused

During handling of the above exception, another exception occurred:

Traceback (most recent call last):
  File "/home/plm/ariasousse/apps/frappe/frappe/utils/scheduler.py", line 75, in enqueue_events_for_site
    if is_scheduler_inactive():
  File "/home/plm/ariasousse/apps/frappe/frappe/utils/scheduler.py", line 117, in is_scheduler_inactive
    if is_scheduler_disabled(verbose=verbose):
  File "/home/plm/ariasousse/apps/frappe/frappe/utils/scheduler.py", line 130, in is_scheduler_disabled
    frappe.db.get_single_value("System Settings", "enable_scheduler")
  File "/home/plm/ariasousse/apps/frappe/frappe/database/database.py", line 837, in get_single_value
    ).run()
  File "/home/plm/ariasousse/apps/frappe/frappe/query_builder/utils.py", line 87, in execute_query
    result = frappe.db.sql(query, params, *args, **kwargs)  # nosemgrep
  File "/home/plm/ariasousse/apps/frappe/frappe/database/database.py", line 207, in sql
    self.connect()
  File "/home/plm/ariasousse/apps/frappe/frappe/database/database.py", line 112, in connect
    self._conn: "MariadbConnection" | "PostgresConnection" = self.get_connection()
  File "/home/plm/ariasousse/apps/frappe/frappe/database/mariadb/database.py", line 107, in get_connection
    conn = self._get_connection()
  File "/home/plm/ariasousse/apps/frappe/frappe/database/mariadb/database.py", line 113, in _get_connection
    return self.create_connection()
  File "/home/plm/ariasousse/apps/frappe/frappe/database/mariadb/database.py", line 116, in create_connection
    return pymysql.connect(**self.get_connection_settings())
  File "/home/plm/ariasousse/env/lib/python3.10/site-packages/pymysql/connections.py", line 361, in __init__
    self.connect()
  File "/home/plm/ariasousse/env/lib/python3.10/site-packages/pymysql/connections.py", line 716, in connect
    raise exc
pymysql.err.OperationalError: (2003, "Can't connect to MySQL server on '127.0.0.1' ([Errno 111] Connection refused)")
2025-01-19 13:04:00,151 ERROR scheduler Exception in Enqueue Events for Site abc.localhost
Traceback (most recent call last):
  File "/home/plm/ariasousse/env/lib/python3.10/site-packages/pymysql/connections.py", line 649, in connect
    sock = socket.create_connection(
  File "/usr/lib/python3.10/socket.py", line 845, in create_connection
    raise err
  File "/usr/lib/python3.10/socket.py", line 833, in create_connection
    sock.connect(sa)
ConnectionRefusedError: [Errno 111] Connection refused

During handling of the above exception, another exception occurred:

Traceback (most recent call last):
  File "/home/plm/ariasousse/apps/frappe/frappe/utils/scheduler.py", line 75, in enqueue_events_for_site
    if is_scheduler_inactive():
  File "/home/plm/ariasousse/apps/frappe/frappe/utils/scheduler.py", line 117, in is_scheduler_inactive
    if is_scheduler_disabled(verbose=verbose):
  File "/home/plm/ariasousse/apps/frappe/frappe/utils/scheduler.py", line 130, in is_scheduler_disabled
    frappe.db.get_single_value("System Settings", "enable_scheduler")
  File "/home/plm/ariasousse/apps/frappe/frappe/database/database.py", line 837, in get_single_value
    ).run()
  File "/home/plm/ariasousse/apps/frappe/frappe/query_builder/utils.py", line 87, in execute_query
    result = frappe.db.sql(query, params, *args, **kwargs)  # nosemgrep
  File "/home/plm/ariasousse/apps/frappe/frappe/database/database.py", line 207, in sql
    self.connect()
  File "/home/plm/ariasousse/apps/frappe/frappe/database/database.py", line 112, in connect
    self._conn: "MariadbConnection" | "PostgresConnection" = self.get_connection()
  File "/home/plm/ariasousse/apps/frappe/frappe/database/mariadb/database.py", line 107, in get_connection
    conn = self._get_connection()
  File "/home/plm/ariasousse/apps/frappe/frappe/database/mariadb/database.py", line 113, in _get_connection
    return self.create_connection()
  File "/home/plm/ariasousse/apps/frappe/frappe/database/mariadb/database.py", line 116, in create_connection
    return pymysql.connect(**self.get_connection_settings())
  File "/home/plm/ariasousse/env/lib/python3.10/site-packages/pymysql/connections.py", line 361, in __init__
    self.connect()
  File "/home/plm/ariasousse/env/lib/python3.10/site-packages/pymysql/connections.py", line 716, in connect
    raise exc
pymysql.err.OperationalError: (2003, "Can't connect to MySQL server on '127.0.0.1' ([Errno 111] Connection refused)")
2025-01-19 13:05:00,255 ERROR scheduler Exception in Enqueue Events for Site abc.localhost
Traceback (most recent call last):
  File "/home/plm/ariasousse/env/lib/python3.10/site-packages/pymysql/connections.py", line 649, in connect
    sock = socket.create_connection(
  File "/usr/lib/python3.10/socket.py", line 845, in create_connection
    raise err
  File "/usr/lib/python3.10/socket.py", line 833, in create_connection
    sock.connect(sa)
ConnectionRefusedError: [Errno 111] Connection refused

During handling of the above exception, another exception occurred:

Traceback (most recent call last):
  File "/home/plm/ariasousse/apps/frappe/frappe/utils/scheduler.py", line 75, in enqueue_events_for_site
    if is_scheduler_inactive():
  File "/home/plm/ariasousse/apps/frappe/frappe/utils/scheduler.py", line 117, in is_scheduler_inactive
    if is_scheduler_disabled(verbose=verbose):
  File "/home/plm/ariasousse/apps/frappe/frappe/utils/scheduler.py", line 130, in is_scheduler_disabled
    frappe.db.get_single_value("System Settings", "enable_scheduler")
  File "/home/plm/ariasousse/apps/frappe/frappe/database/database.py", line 837, in get_single_value
    ).run()
  File "/home/plm/ariasousse/apps/frappe/frappe/query_builder/utils.py", line 87, in execute_query
    result = frappe.db.sql(query, params, *args, **kwargs)  # nosemgrep
  File "/home/plm/ariasousse/apps/frappe/frappe/database/database.py", line 207, in sql
    self.connect()
  File "/home/plm/ariasousse/apps/frappe/frappe/database/database.py", line 112, in connect
    self._conn: "MariadbConnection" | "PostgresConnection" = self.get_connection()
  File "/home/plm/ariasousse/apps/frappe/frappe/database/mariadb/database.py", line 107, in get_connection
    conn = self._get_connection()
  File "/home/plm/ariasousse/apps/frappe/frappe/database/mariadb/database.py", line 113, in _get_connection
    return self.create_connection()
  File "/home/plm/ariasousse/apps/frappe/frappe/database/mariadb/database.py", line 116, in create_connection
    return pymysql.connect(**self.get_connection_settings())
  File "/home/plm/ariasousse/env/lib/python3.10/site-packages/pymysql/connections.py", line 361, in __init__
    self.connect()
  File "/home/plm/ariasousse/env/lib/python3.10/site-packages/pymysql/connections.py", line 716, in connect
    raise exc
pymysql.err.OperationalError: (2003, "Can't connect to MySQL server on '127.0.0.1' ([Errno 111] Connection refused)")
2025-01-19 13:06:00,364 ERROR scheduler Exception in Enqueue Events for Site abc.localhost
Traceback (most recent call last):
  File "/home/plm/ariasousse/env/lib/python3.10/site-packages/pymysql/connections.py", line 649, in connect
    sock = socket.create_connection(
  File "/usr/lib/python3.10/socket.py", line 845, in create_connection
    raise err
  File "/usr/lib/python3.10/socket.py", line 833, in create_connection
    sock.connect(sa)
ConnectionRefusedError: [Errno 111] Connection refused

During handling of the above exception, another exception occurred:

Traceback (most recent call last):
  File "/home/plm/ariasousse/apps/frappe/frappe/utils/scheduler.py", line 75, in enqueue_events_for_site
    if is_scheduler_inactive():
  File "/home/plm/ariasousse/apps/frappe/frappe/utils/scheduler.py", line 117, in is_scheduler_inactive
    if is_scheduler_disabled(verbose=verbose):
  File "/home/plm/ariasousse/apps/frappe/frappe/utils/scheduler.py", line 130, in is_scheduler_disabled
    frappe.db.get_single_value("System Settings", "enable_scheduler")
  File "/home/plm/ariasousse/apps/frappe/frappe/database/database.py", line 837, in get_single_value
    ).run()
  File "/home/plm/ariasousse/apps/frappe/frappe/query_builder/utils.py", line 87, in execute_query
    result = frappe.db.sql(query, params, *args, **kwargs)  # nosemgrep
  File "/home/plm/ariasousse/apps/frappe/frappe/database/database.py", line 207, in sql
    self.connect()
  File "/home/plm/ariasousse/apps/frappe/frappe/database/database.py", line 112, in connect
    self._conn: "MariadbConnection" | "PostgresConnection" = self.get_connection()
  File "/home/plm/ariasousse/apps/frappe/frappe/database/mariadb/database.py", line 107, in get_connection
    conn = self._get_connection()
  File "/home/plm/ariasousse/apps/frappe/frappe/database/mariadb/database.py", line 113, in _get_connection
    return self.create_connection()
  File "/home/plm/ariasousse/apps/frappe/frappe/database/mariadb/database.py", line 116, in create_connection
    return pymysql.connect(**self.get_connection_settings())
  File "/home/plm/ariasousse/env/lib/python3.10/site-packages/pymysql/connections.py", line 361, in __init__
    self.connect()
  File "/home/plm/ariasousse/env/lib/python3.10/site-packages/pymysql/connections.py", line 716, in connect
    raise exc
pymysql.err.OperationalError: (2003, "Can't connect to MySQL server on '127.0.0.1' ([Errno 111] Connection refused)")
2025-01-19 13:07:00,467 ERROR scheduler Exception in Enqueue Events for Site abc.localhost
Traceback (most recent call last):
  File "/home/plm/ariasousse/env/lib/python3.10/site-packages/pymysql/connections.py", line 649, in connect
    sock = socket.create_connection(
  File "/usr/lib/python3.10/socket.py", line 845, in create_connection
    raise err
  File "/usr/lib/python3.10/socket.py", line 833, in create_connection
    sock.connect(sa)
ConnectionRefusedError: [Errno 111] Connection refused

During handling of the above exception, another exception occurred:

Traceback (most recent call last):
  File "/home/plm/ariasousse/apps/frappe/frappe/utils/scheduler.py", line 75, in enqueue_events_for_site
    if is_scheduler_inactive():
  File "/home/plm/ariasousse/apps/frappe/frappe/utils/scheduler.py", line 117, in is_scheduler_inactive
    if is_scheduler_disabled(verbose=verbose):
  File "/home/plm/ariasousse/apps/frappe/frappe/utils/scheduler.py", line 130, in is_scheduler_disabled
    frappe.db.get_single_value("System Settings", "enable_scheduler")
  File "/home/plm/ariasousse/apps/frappe/frappe/database/database.py", line 837, in get_single_value
    ).run()
  File "/home/plm/ariasousse/apps/frappe/frappe/query_builder/utils.py", line 87, in execute_query
    result = frappe.db.sql(query, params, *args, **kwargs)  # nosemgrep
  File "/home/plm/ariasousse/apps/frappe/frappe/database/database.py", line 207, in sql
    self.connect()
  File "/home/plm/ariasousse/apps/frappe/frappe/database/database.py", line 112, in connect
    self._conn: "MariadbConnection" | "PostgresConnection" = self.get_connection()
  File "/home/plm/ariasousse/apps/frappe/frappe/database/mariadb/database.py", line 107, in get_connection
    conn = self._get_connection()
  File "/home/plm/ariasousse/apps/frappe/frappe/database/mariadb/database.py", line 113, in _get_connection
    return self.create_connection()
  File "/home/plm/ariasousse/apps/frappe/frappe/database/mariadb/database.py", line 116, in create_connection
    return pymysql.connect(**self.get_connection_settings())
  File "/home/plm/ariasousse/env/lib/python3.10/site-packages/pymysql/connections.py", line 361, in __init__
    self.connect()
  File "/home/plm/ariasousse/env/lib/python3.10/site-packages/pymysql/connections.py", line 716, in connect
    raise exc
pymysql.err.OperationalError: (2003, "Can't connect to MySQL server on '127.0.0.1' ([Errno 111] Connection refused)")
2025-01-19 13:08:00,482 ERROR scheduler Exception in Enqueue Events for Site abc.localhost
Traceback (most recent call last):
  File "/home/plm/ariasousse/env/lib/python3.10/site-packages/pymysql/connections.py", line 649, in connect
    sock = socket.create_connection(
  File "/usr/lib/python3.10/socket.py", line 845, in create_connection
    raise err
  File "/usr/lib/python3.10/socket.py", line 833, in create_connection
    sock.connect(sa)
ConnectionRefusedError: [Errno 111] Connection refused

During handling of the above exception, another exception occurred:

Traceback (most recent call last):
  File "/home/plm/ariasousse/apps/frappe/frappe/utils/scheduler.py", line 75, in enqueue_events_for_site
    if is_scheduler_inactive():
  File "/home/plm/ariasousse/apps/frappe/frappe/utils/scheduler.py", line 117, in is_scheduler_inactive
    if is_scheduler_disabled(verbose=verbose):
  File "/home/plm/ariasousse/apps/frappe/frappe/utils/scheduler.py", line 130, in is_scheduler_disabled
    frappe.db.get_single_value("System Settings", "enable_scheduler")
  File "/home/plm/ariasousse/apps/frappe/frappe/database/database.py", line 837, in get_single_value
    ).run()
  File "/home/plm/ariasousse/apps/frappe/frappe/query_builder/utils.py", line 87, in execute_query
    result = frappe.db.sql(query, params, *args, **kwargs)  # nosemgrep
  File "/home/plm/ariasousse/apps/frappe/frappe/database/database.py", line 207, in sql
    self.connect()
  File "/home/plm/ariasousse/apps/frappe/frappe/database/database.py", line 112, in connect
    self._conn: "MariadbConnection" | "PostgresConnection" = self.get_connection()
  File "/home/plm/ariasousse/apps/frappe/frappe/database/mariadb/database.py", line 107, in get_connection
    conn = self._get_connection()
  File "/home/plm/ariasousse/apps/frappe/frappe/database/mariadb/database.py", line 113, in _get_connection
    return self.create_connection()
  File "/home/plm/ariasousse/apps/frappe/frappe/database/mariadb/database.py", line 116, in create_connection
    return pymysql.connect(**self.get_connection_settings())
  File "/home/plm/ariasousse/env/lib/python3.10/site-packages/pymysql/connections.py", line 361, in __init__
    self.connect()
  File "/home/plm/ariasousse/env/lib/python3.10/site-packages/pymysql/connections.py", line 716, in connect
    raise exc
pymysql.err.OperationalError: (2003, "Can't connect to MySQL server on '127.0.0.1' ([Errno 111] Connection refused)")
2025-01-19 13:09:00,581 ERROR scheduler Exception in Enqueue Events for Site abc.localhost
Traceback (most recent call last):
  File "/home/plm/ariasousse/env/lib/python3.10/site-packages/pymysql/connections.py", line 649, in connect
    sock = socket.create_connection(
  File "/usr/lib/python3.10/socket.py", line 845, in create_connection
    raise err
  File "/usr/lib/python3.10/socket.py", line 833, in create_connection
    sock.connect(sa)
ConnectionRefusedError: [Errno 111] Connection refused

During handling of the above exception, another exception occurred:

Traceback (most recent call last):
  File "/home/plm/ariasousse/apps/frappe/frappe/utils/scheduler.py", line 75, in enqueue_events_for_site
    if is_scheduler_inactive():
  File "/home/plm/ariasousse/apps/frappe/frappe/utils/scheduler.py", line 117, in is_scheduler_inactive
    if is_scheduler_disabled(verbose=verbose):
  File "/home/plm/ariasousse/apps/frappe/frappe/utils/scheduler.py", line 130, in is_scheduler_disabled
    frappe.db.get_single_value("System Settings", "enable_scheduler")
  File "/home/plm/ariasousse/apps/frappe/frappe/database/database.py", line 837, in get_single_value
    ).run()
  File "/home/plm/ariasousse/apps/frappe/frappe/query_builder/utils.py", line 87, in execute_query
    result = frappe.db.sql(query, params, *args, **kwargs)  # nosemgrep
  File "/home/plm/ariasousse/apps/frappe/frappe/database/database.py", line 207, in sql
    self.connect()
  File "/home/plm/ariasousse/apps/frappe/frappe/database/database.py", line 112, in connect
    self._conn: "MariadbConnection" | "PostgresConnection" = self.get_connection()
  File "/home/plm/ariasousse/apps/frappe/frappe/database/mariadb/database.py", line 107, in get_connection
    conn = self._get_connection()
  File "/home/plm/ariasousse/apps/frappe/frappe/database/mariadb/database.py", line 113, in _get_connection
    return self.create_connection()
  File "/home/plm/ariasousse/apps/frappe/frappe/database/mariadb/database.py", line 116, in create_connection
    return pymysql.connect(**self.get_connection_settings())
  File "/home/plm/ariasousse/env/lib/python3.10/site-packages/pymysql/connections.py", line 361, in __init__
    self.connect()
  File "/home/plm/ariasousse/env/lib/python3.10/site-packages/pymysql/connections.py", line 716, in connect
    raise exc
pymysql.err.OperationalError: (2003, "Can't connect to MySQL server on '127.0.0.1' ([Errno 111] Connection refused)")
2025-01-19 13:10:00,683 ERROR scheduler Exception in Enqueue Events for Site abc.localhost
Traceback (most recent call last):
  File "/home/plm/ariasousse/env/lib/python3.10/site-packages/pymysql/connections.py", line 649, in connect
    sock = socket.create_connection(
  File "/usr/lib/python3.10/socket.py", line 845, in create_connection
    raise err
  File "/usr/lib/python3.10/socket.py", line 833, in create_connection
    sock.connect(sa)
ConnectionRefusedError: [Errno 111] Connection refused

During handling of the above exception, another exception occurred:

Traceback (most recent call last):
  File "/home/plm/ariasousse/apps/frappe/frappe/utils/scheduler.py", line 75, in enqueue_events_for_site
    if is_scheduler_inactive():
  File "/home/plm/ariasousse/apps/frappe/frappe/utils/scheduler.py", line 117, in is_scheduler_inactive
    if is_scheduler_disabled(verbose=verbose):
  File "/home/plm/ariasousse/apps/frappe/frappe/utils/scheduler.py", line 130, in is_scheduler_disabled
    frappe.db.get_single_value("System Settings", "enable_scheduler")
  File "/home/plm/ariasousse/apps/frappe/frappe/database/database.py", line 837, in get_single_value
    ).run()
  File "/home/plm/ariasousse/apps/frappe/frappe/query_builder/utils.py", line 87, in execute_query
    result = frappe.db.sql(query, params, *args, **kwargs)  # nosemgrep
  File "/home/plm/ariasousse/apps/frappe/frappe/database/database.py", line 207, in sql
    self.connect()
  File "/home/plm/ariasousse/apps/frappe/frappe/database/database.py", line 112, in connect
    self._conn: "MariadbConnection" | "PostgresConnection" = self.get_connection()
  File "/home/plm/ariasousse/apps/frappe/frappe/database/mariadb/database.py", line 107, in get_connection
    conn = self._get_connection()
  File "/home/plm/ariasousse/apps/frappe/frappe/database/mariadb/database.py", line 113, in _get_connection
    return self.create_connection()
  File "/home/plm/ariasousse/apps/frappe/frappe/database/mariadb/database.py", line 116, in create_connection
    return pymysql.connect(**self.get_connection_settings())
  File "/home/plm/ariasousse/env/lib/python3.10/site-packages/pymysql/connections.py", line 361, in __init__
    self.connect()
  File "/home/plm/ariasousse/env/lib/python3.10/site-packages/pymysql/connections.py", line 716, in connect
    raise exc
pymysql.err.OperationalError: (2003, "Can't connect to MySQL server on '127.0.0.1' ([Errno 111] Connection refused)")
2025-01-19 13:11:00,790 ERROR scheduler Exception in Enqueue Events for Site abc.localhost
Traceback (most recent call last):
  File "/home/plm/ariasousse/env/lib/python3.10/site-packages/pymysql/connections.py", line 649, in connect
    sock = socket.create_connection(
  File "/usr/lib/python3.10/socket.py", line 845, in create_connection
    raise err
  File "/usr/lib/python3.10/socket.py", line 833, in create_connection
    sock.connect(sa)
ConnectionRefusedError: [Errno 111] Connection refused

During handling of the above exception, another exception occurred:

Traceback (most recent call last):
  File "/home/plm/ariasousse/apps/frappe/frappe/utils/scheduler.py", line 75, in enqueue_events_for_site
    if is_scheduler_inactive():
  File "/home/plm/ariasousse/apps/frappe/frappe/utils/scheduler.py", line 117, in is_scheduler_inactive
    if is_scheduler_disabled(verbose=verbose):
  File "/home/plm/ariasousse/apps/frappe/frappe/utils/scheduler.py", line 130, in is_scheduler_disabled
    frappe.db.get_single_value("System Settings", "enable_scheduler")
  File "/home/plm/ariasousse/apps/frappe/frappe/database/database.py", line 837, in get_single_value
    ).run()
  File "/home/plm/ariasousse/apps/frappe/frappe/query_builder/utils.py", line 87, in execute_query
    result = frappe.db.sql(query, params, *args, **kwargs)  # nosemgrep
  File "/home/plm/ariasousse/apps/frappe/frappe/database/database.py", line 207, in sql
    self.connect()
  File "/home/plm/ariasousse/apps/frappe/frappe/database/database.py", line 112, in connect
    self._conn: "MariadbConnection" | "PostgresConnection" = self.get_connection()
  File "/home/plm/ariasousse/apps/frappe/frappe/database/mariadb/database.py", line 107, in get_connection
    conn = self._get_connection()
  File "/home/plm/ariasousse/apps/frappe/frappe/database/mariadb/database.py", line 113, in _get_connection
    return self.create_connection()
  File "/home/plm/ariasousse/apps/frappe/frappe/database/mariadb/database.py", line 116, in create_connection
    return pymysql.connect(**self.get_connection_settings())
  File "/home/plm/ariasousse/env/lib/python3.10/site-packages/pymysql/connections.py", line 361, in __init__
    self.connect()
  File "/home/plm/ariasousse/env/lib/python3.10/site-packages/pymysql/connections.py", line 716, in connect
    raise exc
pymysql.err.OperationalError: (2003, "Can't connect to MySQL server on '127.0.0.1' ([Errno 111] Connection refused)")
2025-01-19 13:12:00,891 ERROR scheduler Exception in Enqueue Events for Site abc.localhost
Traceback (most recent call last):
  File "/home/plm/ariasousse/env/lib/python3.10/site-packages/pymysql/connections.py", line 649, in connect
    sock = socket.create_connection(
  File "/usr/lib/python3.10/socket.py", line 845, in create_connection
    raise err
  File "/usr/lib/python3.10/socket.py", line 833, in create_connection
    sock.connect(sa)
ConnectionRefusedError: [Errno 111] Connection refused

During handling of the above exception, another exception occurred:

Traceback (most recent call last):
  File "/home/plm/ariasousse/apps/frappe/frappe/utils/scheduler.py", line 75, in enqueue_events_for_site
    if is_scheduler_inactive():
  File "/home/plm/ariasousse/apps/frappe/frappe/utils/scheduler.py", line 117, in is_scheduler_inactive
    if is_scheduler_disabled(verbose=verbose):
  File "/home/plm/ariasousse/apps/frappe/frappe/utils/scheduler.py", line 130, in is_scheduler_disabled
    frappe.db.get_single_value("System Settings", "enable_scheduler")
  File "/home/plm/ariasousse/apps/frappe/frappe/database/database.py", line 837, in get_single_value
    ).run()
  File "/home/plm/ariasousse/apps/frappe/frappe/query_builder/utils.py", line 87, in execute_query
    result = frappe.db.sql(query, params, *args, **kwargs)  # nosemgrep
  File "/home/plm/ariasousse/apps/frappe/frappe/database/database.py", line 207, in sql
    self.connect()
  File "/home/plm/ariasousse/apps/frappe/frappe/database/database.py", line 112, in connect
    self._conn: "MariadbConnection" | "PostgresConnection" = self.get_connection()
  File "/home/plm/ariasousse/apps/frappe/frappe/database/mariadb/database.py", line 107, in get_connection
    conn = self._get_connection()
  File "/home/plm/ariasousse/apps/frappe/frappe/database/mariadb/database.py", line 113, in _get_connection
    return self.create_connection()
  File "/home/plm/ariasousse/apps/frappe/frappe/database/mariadb/database.py", line 116, in create_connection
    return pymysql.connect(**self.get_connection_settings())
  File "/home/plm/ariasousse/env/lib/python3.10/site-packages/pymysql/connections.py", line 361, in __init__
    self.connect()
  File "/home/plm/ariasousse/env/lib/python3.10/site-packages/pymysql/connections.py", line 716, in connect
    raise exc
pymysql.err.OperationalError: (2003, "Can't connect to MySQL server on '127.0.0.1' ([Errno 111] Connection refused)")
2025-01-19 13:13:00,997 ERROR scheduler Exception in Enqueue Events for Site abc.localhost
Traceback (most recent call last):
  File "/home/plm/ariasousse/env/lib/python3.10/site-packages/pymysql/connections.py", line 649, in connect
    sock = socket.create_connection(
  File "/usr/lib/python3.10/socket.py", line 845, in create_connection
    raise err
  File "/usr/lib/python3.10/socket.py", line 833, in create_connection
    sock.connect(sa)
ConnectionRefusedError: [Errno 111] Connection refused

During handling of the above exception, another exception occurred:

Traceback (most recent call last):
  File "/home/plm/ariasousse/apps/frappe/frappe/utils/scheduler.py", line 75, in enqueue_events_for_site
    if is_scheduler_inactive():
  File "/home/plm/ariasousse/apps/frappe/frappe/utils/scheduler.py", line 117, in is_scheduler_inactive
    if is_scheduler_disabled(verbose=verbose):
  File "/home/plm/ariasousse/apps/frappe/frappe/utils/scheduler.py", line 130, in is_scheduler_disabled
    frappe.db.get_single_value("System Settings", "enable_scheduler")
  File "/home/plm/ariasousse/apps/frappe/frappe/database/database.py", line 837, in get_single_value
    ).run()
  File "/home/plm/ariasousse/apps/frappe/frappe/query_builder/utils.py", line 87, in execute_query
    result = frappe.db.sql(query, params, *args, **kwargs)  # nosemgrep
  File "/home/plm/ariasousse/apps/frappe/frappe/database/database.py", line 207, in sql
    self.connect()
  File "/home/plm/ariasousse/apps/frappe/frappe/database/database.py", line 112, in connect
    self._conn: "MariadbConnection" | "PostgresConnection" = self.get_connection()
  File "/home/plm/ariasousse/apps/frappe/frappe/database/mariadb/database.py", line 107, in get_connection
    conn = self._get_connection()
  File "/home/plm/ariasousse/apps/frappe/frappe/database/mariadb/database.py", line 113, in _get_connection
    return self.create_connection()
  File "/home/plm/ariasousse/apps/frappe/frappe/database/mariadb/database.py", line 116, in create_connection
    return pymysql.connect(**self.get_connection_settings())
  File "/home/plm/ariasousse/env/lib/python3.10/site-packages/pymysql/connections.py", line 361, in __init__
    self.connect()
  File "/home/plm/ariasousse/env/lib/python3.10/site-packages/pymysql/connections.py", line 716, in connect
    raise exc
pymysql.err.OperationalError: (2003, "Can't connect to MySQL server on '127.0.0.1' ([Errno 111] Connection refused)")
2025-01-19 13:14:01,104 ERROR scheduler Exception in Enqueue Events for Site abc.localhost
Traceback (most recent call last):
  File "/home/plm/ariasousse/env/lib/python3.10/site-packages/pymysql/connections.py", line 649, in connect
    sock = socket.create_connection(
  File "/usr/lib/python3.10/socket.py", line 845, in create_connection
    raise err
  File "/usr/lib/python3.10/socket.py", line 833, in create_connection
    sock.connect(sa)
ConnectionRefusedError: [Errno 111] Connection refused

During handling of the above exception, another exception occurred:

Traceback (most recent call last):
  File "/home/plm/ariasousse/apps/frappe/frappe/utils/scheduler.py", line 75, in enqueue_events_for_site
    if is_scheduler_inactive():
  File "/home/plm/ariasousse/apps/frappe/frappe/utils/scheduler.py", line 117, in is_scheduler_inactive
    if is_scheduler_disabled(verbose=verbose):
  File "/home/plm/ariasousse/apps/frappe/frappe/utils/scheduler.py", line 130, in is_scheduler_disabled
    frappe.db.get_single_value("System Settings", "enable_scheduler")
  File "/home/plm/ariasousse/apps/frappe/frappe/database/database.py", line 837, in get_single_value
    ).run()
  File "/home/plm/ariasousse/apps/frappe/frappe/query_builder/utils.py", line 87, in execute_query
    result = frappe.db.sql(query, params, *args, **kwargs)  # nosemgrep
  File "/home/plm/ariasousse/apps/frappe/frappe/database/database.py", line 207, in sql
    self.connect()
  File "/home/plm/ariasousse/apps/frappe/frappe/database/database.py", line 112, in connect
    self._conn: "MariadbConnection" | "PostgresConnection" = self.get_connection()
  File "/home/plm/ariasousse/apps/frappe/frappe/database/mariadb/database.py", line 107, in get_connection
    conn = self._get_connection()
  File "/home/plm/ariasousse/apps/frappe/frappe/database/mariadb/database.py", line 113, in _get_connection
    return self.create_connection()
  File "/home/plm/ariasousse/apps/frappe/frappe/database/mariadb/database.py", line 116, in create_connection
    return pymysql.connect(**self.get_connection_settings())
  File "/home/plm/ariasousse/env/lib/python3.10/site-packages/pymysql/connections.py", line 361, in __init__
    self.connect()
  File "/home/plm/ariasousse/env/lib/python3.10/site-packages/pymysql/connections.py", line 716, in connect
    raise exc
pymysql.err.OperationalError: (2003, "Can't connect to MySQL server on '127.0.0.1' ([Errno 111] Connection refused)")
2025-01-19 13:15:01,216 ERROR scheduler Exception in Enqueue Events for Site abc.localhost
Traceback (most recent call last):
  File "/home/plm/ariasousse/env/lib/python3.10/site-packages/pymysql/connections.py", line 649, in connect
    sock = socket.create_connection(
  File "/usr/lib/python3.10/socket.py", line 845, in create_connection
    raise err
  File "/usr/lib/python3.10/socket.py", line 833, in create_connection
    sock.connect(sa)
ConnectionRefusedError: [Errno 111] Connection refused

During handling of the above exception, another exception occurred:

Traceback (most recent call last):
  File "/home/plm/ariasousse/apps/frappe/frappe/utils/scheduler.py", line 75, in enqueue_events_for_site
    if is_scheduler_inactive():
  File "/home/plm/ariasousse/apps/frappe/frappe/utils/scheduler.py", line 117, in is_scheduler_inactive
    if is_scheduler_disabled(verbose=verbose):
  File "/home/plm/ariasousse/apps/frappe/frappe/utils/scheduler.py", line 130, in is_scheduler_disabled
    frappe.db.get_single_value("System Settings", "enable_scheduler")
  File "/home/plm/ariasousse/apps/frappe/frappe/database/database.py", line 837, in get_single_value
    ).run()
  File "/home/plm/ariasousse/apps/frappe/frappe/query_builder/utils.py", line 87, in execute_query
    result = frappe.db.sql(query, params, *args, **kwargs)  # nosemgrep
  File "/home/plm/ariasousse/apps/frappe/frappe/database/database.py", line 207, in sql
    self.connect()
  File "/home/plm/ariasousse/apps/frappe/frappe/database/database.py", line 112, in connect
    self._conn: "MariadbConnection" | "PostgresConnection" = self.get_connection()
  File "/home/plm/ariasousse/apps/frappe/frappe/database/mariadb/database.py", line 107, in get_connection
    conn = self._get_connection()
  File "/home/plm/ariasousse/apps/frappe/frappe/database/mariadb/database.py", line 113, in _get_connection
    return self.create_connection()
  File "/home/plm/ariasousse/apps/frappe/frappe/database/mariadb/database.py", line 116, in create_connection
    return pymysql.connect(**self.get_connection_settings())
  File "/home/plm/ariasousse/env/lib/python3.10/site-packages/pymysql/connections.py", line 361, in __init__
    self.connect()
  File "/home/plm/ariasousse/env/lib/python3.10/site-packages/pymysql/connections.py", line 716, in connect
    raise exc
pymysql.err.OperationalError: (2003, "Can't connect to MySQL server on '127.0.0.1' ([Errno 111] Connection refused)")
2025-01-19 13:16:01,322 ERROR scheduler Exception in Enqueue Events for Site abc.localhost
Traceback (most recent call last):
  File "/home/plm/ariasousse/env/lib/python3.10/site-packages/pymysql/connections.py", line 649, in connect
    sock = socket.create_connection(
  File "/usr/lib/python3.10/socket.py", line 845, in create_connection
    raise err
  File "/usr/lib/python3.10/socket.py", line 833, in create_connection
    sock.connect(sa)
ConnectionRefusedError: [Errno 111] Connection refused

During handling of the above exception, another exception occurred:

Traceback (most recent call last):
  File "/home/plm/ariasousse/apps/frappe/frappe/utils/scheduler.py", line 75, in enqueue_events_for_site
    if is_scheduler_inactive():
  File "/home/plm/ariasousse/apps/frappe/frappe/utils/scheduler.py", line 117, in is_scheduler_inactive
    if is_scheduler_disabled(verbose=verbose):
  File "/home/plm/ariasousse/apps/frappe/frappe/utils/scheduler.py", line 130, in is_scheduler_disabled
    frappe.db.get_single_value("System Settings", "enable_scheduler")
  File "/home/plm/ariasousse/apps/frappe/frappe/database/database.py", line 837, in get_single_value
    ).run()
  File "/home/plm/ariasousse/apps/frappe/frappe/query_builder/utils.py", line 87, in execute_query
    result = frappe.db.sql(query, params, *args, **kwargs)  # nosemgrep
  File "/home/plm/ariasousse/apps/frappe/frappe/database/database.py", line 207, in sql
    self.connect()
  File "/home/plm/ariasousse/apps/frappe/frappe/database/database.py", line 112, in connect
    self._conn: "MariadbConnection" | "PostgresConnection" = self.get_connection()
  File "/home/plm/ariasousse/apps/frappe/frappe/database/mariadb/database.py", line 107, in get_connection
    conn = self._get_connection()
  File "/home/plm/ariasousse/apps/frappe/frappe/database/mariadb/database.py", line 113, in _get_connection
    return self.create_connection()
  File "/home/plm/ariasousse/apps/frappe/frappe/database/mariadb/database.py", line 116, in create_connection
    return pymysql.connect(**self.get_connection_settings())
  File "/home/plm/ariasousse/env/lib/python3.10/site-packages/pymysql/connections.py", line 361, in __init__
    self.connect()
  File "/home/plm/ariasousse/env/lib/python3.10/site-packages/pymysql/connections.py", line 716, in connect
    raise exc
pymysql.err.OperationalError: (2003, "Can't connect to MySQL server on '127.0.0.1' ([Errno 111] Connection refused)")
2025-01-19 13:17:01,400 ERROR scheduler Exception in Enqueue Events for Site abc.localhost
Traceback (most recent call last):
  File "/home/plm/ariasousse/env/lib/python3.10/site-packages/pymysql/connections.py", line 649, in connect
    sock = socket.create_connection(
  File "/usr/lib/python3.10/socket.py", line 845, in create_connection
    raise err
  File "/usr/lib/python3.10/socket.py", line 833, in create_connection
    sock.connect(sa)
ConnectionRefusedError: [Errno 111] Connection refused

During handling of the above exception, another exception occurred:

Traceback (most recent call last):
  File "/home/plm/ariasousse/apps/frappe/frappe/utils/scheduler.py", line 75, in enqueue_events_for_site
    if is_scheduler_inactive():
  File "/home/plm/ariasousse/apps/frappe/frappe/utils/scheduler.py", line 117, in is_scheduler_inactive
    if is_scheduler_disabled(verbose=verbose):
  File "/home/plm/ariasousse/apps/frappe/frappe/utils/scheduler.py", line 130, in is_scheduler_disabled
    frappe.db.get_single_value("System Settings", "enable_scheduler")
  File "/home/plm/ariasousse/apps/frappe/frappe/database/database.py", line 837, in get_single_value
    ).run()
  File "/home/plm/ariasousse/apps/frappe/frappe/query_builder/utils.py", line 87, in execute_query
    result = frappe.db.sql(query, params, *args, **kwargs)  # nosemgrep
  File "/home/plm/ariasousse/apps/frappe/frappe/database/database.py", line 207, in sql
    self.connect()
  File "/home/plm/ariasousse/apps/frappe/frappe/database/database.py", line 112, in connect
    self._conn: "MariadbConnection" | "PostgresConnection" = self.get_connection()
  File "/home/plm/ariasousse/apps/frappe/frappe/database/mariadb/database.py", line 107, in get_connection
    conn = self._get_connection()
  File "/home/plm/ariasousse/apps/frappe/frappe/database/mariadb/database.py", line 113, in _get_connection
    return self.create_connection()
  File "/home/plm/ariasousse/apps/frappe/frappe/database/mariadb/database.py", line 116, in create_connection
    return pymysql.connect(**self.get_connection_settings())
  File "/home/plm/ariasousse/env/lib/python3.10/site-packages/pymysql/connections.py", line 361, in __init__
    self.connect()
  File "/home/plm/ariasousse/env/lib/python3.10/site-packages/pymysql/connections.py", line 716, in connect
    raise exc
pymysql.err.OperationalError: (2003, "Can't connect to MySQL server on '127.0.0.1' ([Errno 111] Connection refused)")
2025-01-19 13:18:01,503 ERROR scheduler Exception in Enqueue Events for Site abc.localhost
Traceback (most recent call last):
  File "/home/plm/ariasousse/env/lib/python3.10/site-packages/pymysql/connections.py", line 649, in connect
    sock = socket.create_connection(
  File "/usr/lib/python3.10/socket.py", line 845, in create_connection
    raise err
  File "/usr/lib/python3.10/socket.py", line 833, in create_connection
    sock.connect(sa)
ConnectionRefusedError: [Errno 111] Connection refused

During handling of the above exception, another exception occurred:

Traceback (most recent call last):
  File "/home/plm/ariasousse/apps/frappe/frappe/utils/scheduler.py", line 75, in enqueue_events_for_site
    if is_scheduler_inactive():
  File "/home/plm/ariasousse/apps/frappe/frappe/utils/scheduler.py", line 117, in is_scheduler_inactive
    if is_scheduler_disabled(verbose=verbose):
  File "/home/plm/ariasousse/apps/frappe/frappe/utils/scheduler.py", line 130, in is_scheduler_disabled
    frappe.db.get_single_value("System Settings", "enable_scheduler")
  File "/home/plm/ariasousse/apps/frappe/frappe/database/database.py", line 837, in get_single_value
    ).run()
  File "/home/plm/ariasousse/apps/frappe/frappe/query_builder/utils.py", line 87, in execute_query
    result = frappe.db.sql(query, params, *args, **kwargs)  # nosemgrep
  File "/home/plm/ariasousse/apps/frappe/frappe/database/database.py", line 207, in sql
    self.connect()
  File "/home/plm/ariasousse/apps/frappe/frappe/database/database.py", line 112, in connect
    self._conn: "MariadbConnection" | "PostgresConnection" = self.get_connection()
  File "/home/plm/ariasousse/apps/frappe/frappe/database/mariadb/database.py", line 107, in get_connection
    conn = self._get_connection()
  File "/home/plm/ariasousse/apps/frappe/frappe/database/mariadb/database.py", line 113, in _get_connection
    return self.create_connection()
  File "/home/plm/ariasousse/apps/frappe/frappe/database/mariadb/database.py", line 116, in create_connection
    return pymysql.connect(**self.get_connection_settings())
  File "/home/plm/ariasousse/env/lib/python3.10/site-packages/pymysql/connections.py", line 361, in __init__
    self.connect()
  File "/home/plm/ariasousse/env/lib/python3.10/site-packages/pymysql/connections.py", line 716, in connect
    raise exc
pymysql.err.OperationalError: (2003, "Can't connect to MySQL server on '127.0.0.1' ([Errno 111] Connection refused)")
2025-01-19 13:19:01,601 ERROR scheduler Exception in Enqueue Events for Site abc.localhost
Traceback (most recent call last):
  File "/home/plm/ariasousse/env/lib/python3.10/site-packages/pymysql/connections.py", line 649, in connect
    sock = socket.create_connection(
  File "/usr/lib/python3.10/socket.py", line 845, in create_connection
    raise err
  File "/usr/lib/python3.10/socket.py", line 833, in create_connection
    sock.connect(sa)
ConnectionRefusedError: [Errno 111] Connection refused

During handling of the above exception, another exception occurred:

Traceback (most recent call last):
  File "/home/plm/ariasousse/apps/frappe/frappe/utils/scheduler.py", line 75, in enqueue_events_for_site
    if is_scheduler_inactive():
  File "/home/plm/ariasousse/apps/frappe/frappe/utils/scheduler.py", line 117, in is_scheduler_inactive
    if is_scheduler_disabled(verbose=verbose):
  File "/home/plm/ariasousse/apps/frappe/frappe/utils/scheduler.py", line 130, in is_scheduler_disabled
    frappe.db.get_single_value("System Settings", "enable_scheduler")
  File "/home/plm/ariasousse/apps/frappe/frappe/database/database.py", line 837, in get_single_value
    ).run()
  File "/home/plm/ariasousse/apps/frappe/frappe/query_builder/utils.py", line 87, in execute_query
    result = frappe.db.sql(query, params, *args, **kwargs)  # nosemgrep
  File "/home/plm/ariasousse/apps/frappe/frappe/database/database.py", line 207, in sql
    self.connect()
  File "/home/plm/ariasousse/apps/frappe/frappe/database/database.py", line 112, in connect
    self._conn: "MariadbConnection" | "PostgresConnection" = self.get_connection()
  File "/home/plm/ariasousse/apps/frappe/frappe/database/mariadb/database.py", line 107, in get_connection
    conn = self._get_connection()
  File "/home/plm/ariasousse/apps/frappe/frappe/database/mariadb/database.py", line 113, in _get_connection
    return self.create_connection()
  File "/home/plm/ariasousse/apps/frappe/frappe/database/mariadb/database.py", line 116, in create_connection
    return pymysql.connect(**self.get_connection_settings())
  File "/home/plm/ariasousse/env/lib/python3.10/site-packages/pymysql/connections.py", line 361, in __init__
    self.connect()
  File "/home/plm/ariasousse/env/lib/python3.10/site-packages/pymysql/connections.py", line 716, in connect
    raise exc
pymysql.err.OperationalError: (2003, "Can't connect to MySQL server on '127.0.0.1' ([Errno 111] Connection refused)")
2025-01-19 13:20:01,706 ERROR scheduler Exception in Enqueue Events for Site abc.localhost
Traceback (most recent call last):
  File "/home/plm/ariasousse/env/lib/python3.10/site-packages/pymysql/connections.py", line 649, in connect
    sock = socket.create_connection(
  File "/usr/lib/python3.10/socket.py", line 845, in create_connection
    raise err
  File "/usr/lib/python3.10/socket.py", line 833, in create_connection
    sock.connect(sa)
ConnectionRefusedError: [Errno 111] Connection refused

During handling of the above exception, another exception occurred:

Traceback (most recent call last):
  File "/home/plm/ariasousse/apps/frappe/frappe/utils/scheduler.py", line 75, in enqueue_events_for_site
    if is_scheduler_inactive():
  File "/home/plm/ariasousse/apps/frappe/frappe/utils/scheduler.py", line 117, in is_scheduler_inactive
    if is_scheduler_disabled(verbose=verbose):
  File "/home/plm/ariasousse/apps/frappe/frappe/utils/scheduler.py", line 130, in is_scheduler_disabled
    frappe.db.get_single_value("System Settings", "enable_scheduler")
  File "/home/plm/ariasousse/apps/frappe/frappe/database/database.py", line 837, in get_single_value
    ).run()
  File "/home/plm/ariasousse/apps/frappe/frappe/query_builder/utils.py", line 87, in execute_query
    result = frappe.db.sql(query, params, *args, **kwargs)  # nosemgrep
  File "/home/plm/ariasousse/apps/frappe/frappe/database/database.py", line 207, in sql
    self.connect()
  File "/home/plm/ariasousse/apps/frappe/frappe/database/database.py", line 112, in connect
    self._conn: "MariadbConnection" | "PostgresConnection" = self.get_connection()
  File "/home/plm/ariasousse/apps/frappe/frappe/database/mariadb/database.py", line 107, in get_connection
    conn = self._get_connection()
  File "/home/plm/ariasousse/apps/frappe/frappe/database/mariadb/database.py", line 113, in _get_connection
    return self.create_connection()
  File "/home/plm/ariasousse/apps/frappe/frappe/database/mariadb/database.py", line 116, in create_connection
    return pymysql.connect(**self.get_connection_settings())
  File "/home/plm/ariasousse/env/lib/python3.10/site-packages/pymysql/connections.py", line 361, in __init__
    self.connect()
  File "/home/plm/ariasousse/env/lib/python3.10/site-packages/pymysql/connections.py", line 716, in connect
    raise exc
pymysql.err.OperationalError: (2003, "Can't connect to MySQL server on '127.0.0.1' ([Errno 111] Connection refused)")
2025-01-19 13:21:01,816 ERROR scheduler Exception in Enqueue Events for Site abc.localhost
Traceback (most recent call last):
  File "/home/plm/ariasousse/env/lib/python3.10/site-packages/pymysql/connections.py", line 649, in connect
    sock = socket.create_connection(
  File "/usr/lib/python3.10/socket.py", line 845, in create_connection
    raise err
  File "/usr/lib/python3.10/socket.py", line 833, in create_connection
    sock.connect(sa)
ConnectionRefusedError: [Errno 111] Connection refused

During handling of the above exception, another exception occurred:

Traceback (most recent call last):
  File "/home/plm/ariasousse/apps/frappe/frappe/utils/scheduler.py", line 75, in enqueue_events_for_site
    if is_scheduler_inactive():
  File "/home/plm/ariasousse/apps/frappe/frappe/utils/scheduler.py", line 117, in is_scheduler_inactive
    if is_scheduler_disabled(verbose=verbose):
  File "/home/plm/ariasousse/apps/frappe/frappe/utils/scheduler.py", line 130, in is_scheduler_disabled
    frappe.db.get_single_value("System Settings", "enable_scheduler")
  File "/home/plm/ariasousse/apps/frappe/frappe/database/database.py", line 837, in get_single_value
    ).run()
  File "/home/plm/ariasousse/apps/frappe/frappe/query_builder/utils.py", line 87, in execute_query
    result = frappe.db.sql(query, params, *args, **kwargs)  # nosemgrep
  File "/home/plm/ariasousse/apps/frappe/frappe/database/database.py", line 207, in sql
    self.connect()
  File "/home/plm/ariasousse/apps/frappe/frappe/database/database.py", line 112, in connect
    self._conn: "MariadbConnection" | "PostgresConnection" = self.get_connection()
  File "/home/plm/ariasousse/apps/frappe/frappe/database/mariadb/database.py", line 107, in get_connection
    conn = self._get_connection()
  File "/home/plm/ariasousse/apps/frappe/frappe/database/mariadb/database.py", line 113, in _get_connection
    return self.create_connection()
  File "/home/plm/ariasousse/apps/frappe/frappe/database/mariadb/database.py", line 116, in create_connection
    return pymysql.connect(**self.get_connection_settings())
  File "/home/plm/ariasousse/env/lib/python3.10/site-packages/pymysql/connections.py", line 361, in __init__
    self.connect()
  File "/home/plm/ariasousse/env/lib/python3.10/site-packages/pymysql/connections.py", line 716, in connect
    raise exc
pymysql.err.OperationalError: (2003, "Can't connect to MySQL server on '127.0.0.1' ([Errno 111] Connection refused)")
