2024-12-30 19:30:44,831 ERROR frappe Could not take error snapshot: (2003, "Can't connect to MySQL server on '127.0.0.1' ([Errno 111] Connection refused)")
Site: aria.localhost
Form Dict: {'doctype': 'Number Card', 'fields': '["`tabNumber Card`.`name`","`tabNumber Card`.`label`","`tabNumber Card`.`custom_backrougnd`","`tabNumber Card`.`document_type`"]', 'filters': '[]', 'order_by': '`tabNumber Card`.`modified` desc', 'start': '0', 'page_length': '20', 'view': 'Report', 'with_comment_count': '1', 'cmd': 'frappe.desk.reportview.get'}
Traceback (most recent call last):
  File "/home/plm/ariasousse/env/lib/python3.10/site-packages/pymysql/connections.py", line 649, in connect
    sock = socket.create_connection(
  File "/usr/lib/python3.10/socket.py", line 845, in create_connection
    raise err
  File "/usr/lib/python3.10/socket.py", line 833, in create_connection
    sock.connect(sa)
ConnectionRefusedError: [Errno 111] Connection refused

During handling of the above exception, another exception occurred:

Traceback (most recent call last):
  File "/home/plm/ariasousse/apps/frappe/frappe/app.py", line 114, in application
    response = frappe.api.handle(request)
  File "/home/plm/ariasousse/apps/frappe/frappe/api/__init__.py", line 49, in handle
    data = endpoint(**arguments)
  File "/home/plm/ariasousse/apps/frappe/frappe/api/v1.py", line 36, in handle_rpc_call
    return frappe.handler.handle()
  File "/home/plm/ariasousse/apps/frappe/frappe/handler.py", line 49, in handle
    data = execute_cmd(cmd)
  File "/home/plm/ariasousse/apps/frappe/frappe/handler.py", line 85, in execute_cmd
    return frappe.call(method, **frappe.form_dict)
  File "/home/plm/ariasousse/apps/frappe/frappe/__init__.py", line 1725, in call
    return fn(*args, **newargs)
  File "/home/plm/ariasousse/apps/frappe/frappe/utils/typing_validations.py", line 31, in wrapper
    return func(*args, **kwargs)
  File "/home/plm/ariasousse/apps/frappe/frappe/__init__.py", line 878, in wrapper_fn
    retval = fn(*args, **get_newargs(fn, kwargs))
  File "/home/plm/ariasousse/apps/frappe/frappe/desk/reportview.py", line 32, in get
    data = compress(execute(**args), args=args)
  File "/home/plm/ariasousse/apps/frappe/frappe/desk/reportview.py", line 78, in execute
    return DatabaseQuery(doctype).execute(*args, **kwargs)
  File "/home/plm/ariasousse/apps/frappe/frappe/model/db_query.py", line 191, in execute
    result = self.build_and_run()
  File "/home/plm/ariasousse/apps/frappe/frappe/model/db_query.py", line 232, in build_and_run
    return frappe.db.sql(
  File "/home/plm/ariasousse/apps/frappe/frappe/database/database.py", line 207, in sql
    self.connect()
  File "/home/plm/ariasousse/apps/frappe/frappe/database/database.py", line 112, in connect
    self._conn: "MariadbConnection" | "PostgresConnection" = self.get_connection()
  File "/home/plm/ariasousse/apps/frappe/frappe/database/mariadb/database.py", line 107, in get_connection
    conn = self._get_connection()
  File "/home/plm/ariasousse/apps/frappe/frappe/database/mariadb/database.py", line 113, in _get_connection
    return self.create_connection()
  File "/home/plm/ariasousse/apps/frappe/frappe/database/mariadb/database.py", line 116, in create_connection
    return pymysql.connect(**self.get_connection_settings())
  File "/home/plm/ariasousse/env/lib/python3.10/site-packages/pymysql/connections.py", line 361, in __init__
    self.connect()
  File "/home/plm/ariasousse/env/lib/python3.10/site-packages/pymysql/connections.py", line 716, in connect
    raise exc
pymysql.err.OperationalError: (2003, "Can't connect to MySQL server on '127.0.0.1' ([Errno 111] Connection refused)")

During handling of the above exception, another exception occurred:

Traceback (most recent call last):
  File "/home/plm/ariasousse/env/lib/python3.10/site-packages/pymysql/connections.py", line 649, in connect
    sock = socket.create_connection(
  File "/usr/lib/python3.10/socket.py", line 845, in create_connection
    raise err
  File "/usr/lib/python3.10/socket.py", line 833, in create_connection
    sock.connect(sa)
ConnectionRefusedError: [Errno 111] Connection refused

During handling of the above exception, another exception occurred:

Traceback (most recent call last):
  File "/home/plm/ariasousse/apps/frappe/frappe/utils/error.py", line 86, in log_error_snapshot
    log_error(title=str(exception), defer_insert=True)
  File "/home/plm/ariasousse/apps/frappe/frappe/utils/error.py", line 61, in log_error
    error_log = frappe.get_doc(
  File "/home/plm/ariasousse/apps/frappe/frappe/__init__.py", line 1290, in get_doc
    doc = frappe.model.document.get_doc(*args, **kwargs)
  File "/home/plm/ariasousse/apps/frappe/frappe/model/document.py", line 83, in get_doc
    controller = get_controller(doctype)
  File "/home/plm/ariasousse/apps/frappe/frappe/model/base_document.py", line 70, in get_controller
    site_controllers[doctype] = import_controller(doctype)
  File "/home/plm/ariasousse/apps/frappe/frappe/model/base_document.py", line 81, in import_controller
    doctype_info = frappe.db.get_value("DocType", doctype, fieldname="*")
  File "/home/plm/ariasousse/apps/frappe/frappe/database/database.py", line 515, in get_value
    result = self.get_values(
  File "/home/plm/ariasousse/apps/frappe/frappe/database/database.py", line 619, in get_values
    out = self._get_values_from_table(
  File "/home/plm/ariasousse/apps/frappe/frappe/database/database.py", line 892, in _get_values_from_table
    return query.run(as_dict=as_dict, debug=debug, update=update, run=run, pluck=pluck)
  File "/home/plm/ariasousse/apps/frappe/frappe/query_builder/utils.py", line 87, in execute_query
    result = frappe.db.sql(query, params, *args, **kwargs)  # nosemgrep
  File "/home/plm/ariasousse/apps/frappe/frappe/database/database.py", line 207, in sql
    self.connect()
  File "/home/plm/ariasousse/apps/frappe/frappe/database/database.py", line 112, in connect
    self._conn: "MariadbConnection" | "PostgresConnection" = self.get_connection()
  File "/home/plm/ariasousse/apps/frappe/frappe/database/mariadb/database.py", line 107, in get_connection
    conn = self._get_connection()
  File "/home/plm/ariasousse/apps/frappe/frappe/database/mariadb/database.py", line 113, in _get_connection
    return self.create_connection()
  File "/home/plm/ariasousse/apps/frappe/frappe/database/mariadb/database.py", line 116, in create_connection
    return pymysql.connect(**self.get_connection_settings())
  File "/home/plm/ariasousse/env/lib/python3.10/site-packages/pymysql/connections.py", line 361, in __init__
    self.connect()
  File "/home/plm/ariasousse/env/lib/python3.10/site-packages/pymysql/connections.py", line 716, in connect
    raise exc
pymysql.err.OperationalError: (2003, "Can't connect to MySQL server on '127.0.0.1' ([Errno 111] Connection refused)")
2024-12-30 19:35:44,863 ERROR frappe Could not take error snapshot: (2003, "Can't connect to MySQL server on '127.0.0.1' ([Errno 111] Connection refused)")
Site: aria.localhost
Form Dict: {'doctype': 'Number Card', 'fields': '["`tabNumber Card`.`name`","`tabNumber Card`.`label`","`tabNumber Card`.`custom_backrougnd`","`tabNumber Card`.`document_type`"]', 'filters': '[]', 'order_by': '`tabNumber Card`.`modified` desc', 'start': '0', 'page_length': '20', 'view': 'Report', 'with_comment_count': '1', 'cmd': 'frappe.desk.reportview.get'}
Traceback (most recent call last):
  File "/home/plm/ariasousse/env/lib/python3.10/site-packages/pymysql/connections.py", line 649, in connect
    sock = socket.create_connection(
  File "/usr/lib/python3.10/socket.py", line 845, in create_connection
    raise err
  File "/usr/lib/python3.10/socket.py", line 833, in create_connection
    sock.connect(sa)
ConnectionRefusedError: [Errno 111] Connection refused

During handling of the above exception, another exception occurred:

Traceback (most recent call last):
  File "/home/plm/ariasousse/apps/frappe/frappe/app.py", line 114, in application
    response = frappe.api.handle(request)
  File "/home/plm/ariasousse/apps/frappe/frappe/api/__init__.py", line 49, in handle
    data = endpoint(**arguments)
  File "/home/plm/ariasousse/apps/frappe/frappe/api/v1.py", line 36, in handle_rpc_call
    return frappe.handler.handle()
  File "/home/plm/ariasousse/apps/frappe/frappe/handler.py", line 49, in handle
    data = execute_cmd(cmd)
  File "/home/plm/ariasousse/apps/frappe/frappe/handler.py", line 85, in execute_cmd
    return frappe.call(method, **frappe.form_dict)
  File "/home/plm/ariasousse/apps/frappe/frappe/__init__.py", line 1725, in call
    return fn(*args, **newargs)
  File "/home/plm/ariasousse/apps/frappe/frappe/utils/typing_validations.py", line 31, in wrapper
    return func(*args, **kwargs)
  File "/home/plm/ariasousse/apps/frappe/frappe/__init__.py", line 878, in wrapper_fn
    retval = fn(*args, **get_newargs(fn, kwargs))
  File "/home/plm/ariasousse/apps/frappe/frappe/desk/reportview.py", line 32, in get
    data = compress(execute(**args), args=args)
  File "/home/plm/ariasousse/apps/frappe/frappe/desk/reportview.py", line 78, in execute
    return DatabaseQuery(doctype).execute(*args, **kwargs)
  File "/home/plm/ariasousse/apps/frappe/frappe/model/db_query.py", line 191, in execute
    result = self.build_and_run()
  File "/home/plm/ariasousse/apps/frappe/frappe/model/db_query.py", line 232, in build_and_run
    return frappe.db.sql(
  File "/home/plm/ariasousse/apps/frappe/frappe/database/database.py", line 207, in sql
    self.connect()
  File "/home/plm/ariasousse/apps/frappe/frappe/database/database.py", line 112, in connect
    self._conn: "MariadbConnection" | "PostgresConnection" = self.get_connection()
  File "/home/plm/ariasousse/apps/frappe/frappe/database/mariadb/database.py", line 107, in get_connection
    conn = self._get_connection()
  File "/home/plm/ariasousse/apps/frappe/frappe/database/mariadb/database.py", line 113, in _get_connection
    return self.create_connection()
  File "/home/plm/ariasousse/apps/frappe/frappe/database/mariadb/database.py", line 116, in create_connection
    return pymysql.connect(**self.get_connection_settings())
  File "/home/plm/ariasousse/env/lib/python3.10/site-packages/pymysql/connections.py", line 361, in __init__
    self.connect()
  File "/home/plm/ariasousse/env/lib/python3.10/site-packages/pymysql/connections.py", line 716, in connect
    raise exc
pymysql.err.OperationalError: (2003, "Can't connect to MySQL server on '127.0.0.1' ([Errno 111] Connection refused)")

During handling of the above exception, another exception occurred:

Traceback (most recent call last):
  File "/home/plm/ariasousse/env/lib/python3.10/site-packages/pymysql/connections.py", line 649, in connect
    sock = socket.create_connection(
  File "/usr/lib/python3.10/socket.py", line 845, in create_connection
    raise err
  File "/usr/lib/python3.10/socket.py", line 833, in create_connection
    sock.connect(sa)
ConnectionRefusedError: [Errno 111] Connection refused

During handling of the above exception, another exception occurred:

Traceback (most recent call last):
  File "/home/plm/ariasousse/apps/frappe/frappe/utils/error.py", line 86, in log_error_snapshot
    log_error(title=str(exception), defer_insert=True)
  File "/home/plm/ariasousse/apps/frappe/frappe/utils/error.py", line 61, in log_error
    error_log = frappe.get_doc(
  File "/home/plm/ariasousse/apps/frappe/frappe/__init__.py", line 1290, in get_doc
    doc = frappe.model.document.get_doc(*args, **kwargs)
  File "/home/plm/ariasousse/apps/frappe/frappe/model/document.py", line 83, in get_doc
    controller = get_controller(doctype)
  File "/home/plm/ariasousse/apps/frappe/frappe/model/base_document.py", line 70, in get_controller
    site_controllers[doctype] = import_controller(doctype)
  File "/home/plm/ariasousse/apps/frappe/frappe/model/base_document.py", line 81, in import_controller
    doctype_info = frappe.db.get_value("DocType", doctype, fieldname="*")
  File "/home/plm/ariasousse/apps/frappe/frappe/database/database.py", line 515, in get_value
    result = self.get_values(
  File "/home/plm/ariasousse/apps/frappe/frappe/database/database.py", line 619, in get_values
    out = self._get_values_from_table(
  File "/home/plm/ariasousse/apps/frappe/frappe/database/database.py", line 892, in _get_values_from_table
    return query.run(as_dict=as_dict, debug=debug, update=update, run=run, pluck=pluck)
  File "/home/plm/ariasousse/apps/frappe/frappe/query_builder/utils.py", line 87, in execute_query
    result = frappe.db.sql(query, params, *args, **kwargs)  # nosemgrep
  File "/home/plm/ariasousse/apps/frappe/frappe/database/database.py", line 207, in sql
    self.connect()
  File "/home/plm/ariasousse/apps/frappe/frappe/database/database.py", line 112, in connect
    self._conn: "MariadbConnection" | "PostgresConnection" = self.get_connection()
  File "/home/plm/ariasousse/apps/frappe/frappe/database/mariadb/database.py", line 107, in get_connection
    conn = self._get_connection()
  File "/home/plm/ariasousse/apps/frappe/frappe/database/mariadb/database.py", line 113, in _get_connection
    return self.create_connection()
  File "/home/plm/ariasousse/apps/frappe/frappe/database/mariadb/database.py", line 116, in create_connection
    return pymysql.connect(**self.get_connection_settings())
  File "/home/plm/ariasousse/env/lib/python3.10/site-packages/pymysql/connections.py", line 361, in __init__
    self.connect()
  File "/home/plm/ariasousse/env/lib/python3.10/site-packages/pymysql/connections.py", line 716, in connect
    raise exc
pymysql.err.OperationalError: (2003, "Can't connect to MySQL server on '127.0.0.1' ([Errno 111] Connection refused)")
2025-01-07 03:09:15,070 ERROR frappe Could not take error snapshot: (2003, "Can't connect to MySQL server on '127.0.0.1' ([Errno 111] Connection refused)")
Site: aria.localhost
Form Dict: {}
Traceback (most recent call last):
  File "/home/plm/ariasousse/env/lib/python3.10/site-packages/pymysql/connections.py", line 649, in connect
    sock = socket.create_connection(
  File "/usr/lib/python3.10/socket.py", line 845, in create_connection
    raise err
  File "/usr/lib/python3.10/socket.py", line 833, in create_connection
    sock.connect(sa)
ConnectionRefusedError: [Errno 111] Connection refused

During handling of the above exception, another exception occurred:

Traceback (most recent call last):
  File "/home/plm/ariasousse/apps/frappe/frappe/website/serve.py", line 19, in get_response
    endpoint, renderer_instance = path_resolver.resolve()
  File "/home/plm/ariasousse/apps/frappe/frappe/website/path_resolver.py", line 38, in resolve
    resolve_redirect(self.path, request.query_string)
  File "/home/plm/ariasousse/apps/frappe/frappe/website/path_resolver.py", line 118, in resolve_redirect
    redirects += frappe.get_all(
  File "/home/plm/ariasousse/apps/frappe/frappe/__init__.py", line 2014, in get_all
    return get_list(doctype, *args, **kwargs)
  File "/home/plm/ariasousse/apps/frappe/frappe/__init__.py", line 1989, in get_list
    return frappe.model.db_query.DatabaseQuery(doctype).execute(*args, **kwargs)
  File "/home/plm/ariasousse/apps/frappe/frappe/model/db_query.py", line 191, in execute
    result = self.build_and_run()
  File "/home/plm/ariasousse/apps/frappe/frappe/model/db_query.py", line 232, in build_and_run
    return frappe.db.sql(
  File "/home/plm/ariasousse/apps/frappe/frappe/database/database.py", line 207, in sql
    self.connect()
  File "/home/plm/ariasousse/apps/frappe/frappe/database/database.py", line 112, in connect
    self._conn: "MariadbConnection" | "PostgresConnection" = self.get_connection()
  File "/home/plm/ariasousse/apps/frappe/frappe/database/mariadb/database.py", line 107, in get_connection
    conn = self._get_connection()
  File "/home/plm/ariasousse/apps/frappe/frappe/database/mariadb/database.py", line 113, in _get_connection
    return self.create_connection()
  File "/home/plm/ariasousse/apps/frappe/frappe/database/mariadb/database.py", line 116, in create_connection
    return pymysql.connect(**self.get_connection_settings())
  File "/home/plm/ariasousse/env/lib/python3.10/site-packages/pymysql/connections.py", line 361, in __init__
    self.connect()
  File "/home/plm/ariasousse/env/lib/python3.10/site-packages/pymysql/connections.py", line 716, in connect
    raise exc
pymysql.err.OperationalError: (2003, "Can't connect to MySQL server on '127.0.0.1' ([Errno 111] Connection refused)")

During handling of the above exception, another exception occurred:

Traceback (most recent call last):
  File "/home/plm/ariasousse/env/lib/python3.10/site-packages/pymysql/connections.py", line 649, in connect
    sock = socket.create_connection(
  File "/usr/lib/python3.10/socket.py", line 845, in create_connection
    raise err
  File "/usr/lib/python3.10/socket.py", line 833, in create_connection
    sock.connect(sa)
ConnectionRefusedError: [Errno 111] Connection refused

During handling of the above exception, another exception occurred:

Traceback (most recent call last):
  File "/home/plm/ariasousse/apps/frappe/frappe/app.py", line 123, in application
    response = get_response()
  File "/home/plm/ariasousse/apps/frappe/frappe/website/serve.py", line 28, in get_response
    response = ErrorPage(exception=e).render()
  File "/home/plm/ariasousse/apps/frappe/frappe/website/page_renderers/template_page.py", line 84, in render
    html = self.get_html()
  File "/home/plm/ariasousse/apps/frappe/frappe/website/utils.py", line 530, in cache_html_decorator
    html = func(*args, **kwargs)
  File "/home/plm/ariasousse/apps/frappe/frappe/website/page_renderers/template_page.py", line 92, in get_html
    self.init_context()
  File "/home/plm/ariasousse/apps/frappe/frappe/website/page_renderers/error_page.py", line 14, in init_context
    super().init_context()
  File "/home/plm/ariasousse/apps/frappe/frappe/website/page_renderers/base_template_page.py", line 15, in init_context
    self.context.update(get_website_settings())
  File "/home/plm/ariasousse/apps/frappe/frappe/website/doctype/website_settings/website_settings.py", line 263, in get_website_settings
    context.boot = get_boot_data()
  File "/home/plm/ariasousse/apps/frappe/frappe/website/utils.py", line 169, in get_boot_data
    apps = get_apps() or []
  File "/home/plm/ariasousse/apps/frappe/frappe/utils/typing_validations.py", line 31, in wrapper
    return func(*args, **kwargs)
  File "/home/plm/ariasousse/apps/frappe/frappe/apps.py", line 15, in get_apps
    allowed_workspaces = get_workspace_sidebar_items().get("pages")
  File "/home/plm/ariasousse/apps/frappe/frappe/utils/typing_validations.py", line 31, in wrapper
    return func(*args, **kwargs)
  File "/home/plm/ariasousse/apps/frappe/frappe/desk/desktop.py", line 447, in get_workspace_sidebar_items
    all_pages = frappe.get_all(
  File "/home/plm/ariasousse/apps/frappe/frappe/__init__.py", line 2014, in get_all
    return get_list(doctype, *args, **kwargs)
  File "/home/plm/ariasousse/apps/frappe/frappe/__init__.py", line 1989, in get_list
    return frappe.model.db_query.DatabaseQuery(doctype).execute(*args, **kwargs)
  File "/home/plm/ariasousse/apps/frappe/frappe/model/db_query.py", line 191, in execute
    result = self.build_and_run()
  File "/home/plm/ariasousse/apps/frappe/frappe/model/db_query.py", line 232, in build_and_run
    return frappe.db.sql(
  File "/home/plm/ariasousse/apps/frappe/frappe/database/database.py", line 207, in sql
    self.connect()
  File "/home/plm/ariasousse/apps/frappe/frappe/database/database.py", line 112, in connect
    self._conn: "MariadbConnection" | "PostgresConnection" = self.get_connection()
  File "/home/plm/ariasousse/apps/frappe/frappe/database/mariadb/database.py", line 107, in get_connection
    conn = self._get_connection()
  File "/home/plm/ariasousse/apps/frappe/frappe/database/mariadb/database.py", line 113, in _get_connection
    return self.create_connection()
  File "/home/plm/ariasousse/apps/frappe/frappe/database/mariadb/database.py", line 116, in create_connection
    return pymysql.connect(**self.get_connection_settings())
  File "/home/plm/ariasousse/env/lib/python3.10/site-packages/pymysql/connections.py", line 361, in __init__
    self.connect()
  File "/home/plm/ariasousse/env/lib/python3.10/site-packages/pymysql/connections.py", line 716, in connect
    raise exc
pymysql.err.OperationalError: (2003, "Can't connect to MySQL server on '127.0.0.1' ([Errno 111] Connection refused)")

During handling of the above exception, another exception occurred:

Traceback (most recent call last):
  File "/home/plm/ariasousse/env/lib/python3.10/site-packages/pymysql/connections.py", line 649, in connect
    sock = socket.create_connection(
  File "/usr/lib/python3.10/socket.py", line 845, in create_connection
    raise err
  File "/usr/lib/python3.10/socket.py", line 833, in create_connection
    sock.connect(sa)
ConnectionRefusedError: [Errno 111] Connection refused

During handling of the above exception, another exception occurred:

Traceback (most recent call last):
  File "/home/plm/ariasousse/apps/frappe/frappe/utils/error.py", line 86, in log_error_snapshot
    log_error(title=str(exception), defer_insert=True)
  File "/home/plm/ariasousse/apps/frappe/frappe/utils/error.py", line 61, in log_error
    error_log = frappe.get_doc(
  File "/home/plm/ariasousse/apps/frappe/frappe/__init__.py", line 1290, in get_doc
    doc = frappe.model.document.get_doc(*args, **kwargs)
  File "/home/plm/ariasousse/apps/frappe/frappe/model/document.py", line 83, in get_doc
    controller = get_controller(doctype)
  File "/home/plm/ariasousse/apps/frappe/frappe/model/base_document.py", line 70, in get_controller
    site_controllers[doctype] = import_controller(doctype)
  File "/home/plm/ariasousse/apps/frappe/frappe/model/base_document.py", line 81, in import_controller
    doctype_info = frappe.db.get_value("DocType", doctype, fieldname="*")
  File "/home/plm/ariasousse/apps/frappe/frappe/database/database.py", line 515, in get_value
    result = self.get_values(
  File "/home/plm/ariasousse/apps/frappe/frappe/database/database.py", line 619, in get_values
    out = self._get_values_from_table(
  File "/home/plm/ariasousse/apps/frappe/frappe/database/database.py", line 892, in _get_values_from_table
    return query.run(as_dict=as_dict, debug=debug, update=update, run=run, pluck=pluck)
  File "/home/plm/ariasousse/apps/frappe/frappe/query_builder/utils.py", line 87, in execute_query
    result = frappe.db.sql(query, params, *args, **kwargs)  # nosemgrep
  File "/home/plm/ariasousse/apps/frappe/frappe/database/database.py", line 207, in sql
    self.connect()
  File "/home/plm/ariasousse/apps/frappe/frappe/database/database.py", line 112, in connect
    self._conn: "MariadbConnection" | "PostgresConnection" = self.get_connection()
  File "/home/plm/ariasousse/apps/frappe/frappe/database/mariadb/database.py", line 107, in get_connection
    conn = self._get_connection()
  File "/home/plm/ariasousse/apps/frappe/frappe/database/mariadb/database.py", line 113, in _get_connection
    return self.create_connection()
  File "/home/plm/ariasousse/apps/frappe/frappe/database/mariadb/database.py", line 116, in create_connection
    return pymysql.connect(**self.get_connection_settings())
  File "/home/plm/ariasousse/env/lib/python3.10/site-packages/pymysql/connections.py", line 361, in __init__
    self.connect()
  File "/home/plm/ariasousse/env/lib/python3.10/site-packages/pymysql/connections.py", line 716, in connect
    raise exc
pymysql.err.OperationalError: (2003, "Can't connect to MySQL server on '127.0.0.1' ([Errno 111] Connection refused)")
2025-01-08 11:11:19,558 ERROR frappe Could not take error snapshot: No module named 'linca'
Site: aria.localhost
Form Dict: {}
Traceback (most recent call last):
  File "/home/plm/ariasousse/apps/frappe/frappe/app.py", line 99, in application
    init_request(request)
  File "/home/plm/ariasousse/apps/frappe/frappe/app.py", line 172, in init_request
    frappe.init(site=site, sites_path=_sites_path, force=True)
  File "/home/plm/ariasousse/apps/frappe/frappe/__init__.py", line 257, in init
    setup_module_map(include_all_apps=not (frappe.request or frappe.job or frappe.flags.in_migrate))
  File "/home/plm/ariasousse/apps/frappe/frappe/__init__.py", line 1649, in setup_module_map
    for module in get_module_list(app):
  File "/home/plm/ariasousse/apps/frappe/frappe/__init__.py", line 1497, in get_module_list
    return get_file_items(get_app_path(app_name, "modules.txt"))
  File "/home/plm/ariasousse/apps/frappe/frappe/__init__.py", line 1462, in get_app_path
    return get_pymodule_path(app_name, *joins)
  File "/home/plm/ariasousse/apps/frappe/frappe/__init__.py", line 1492, in get_pymodule_path
    return abspath(join(dirname(get_module(scrub(modulename)).__file__ or ""), *joins))
  File "/home/plm/ariasousse/apps/frappe/frappe/__init__.py", line 1433, in get_module
    return importlib.import_module(modulename)
  File "/usr/lib/python3.10/importlib/__init__.py", line 126, in import_module
    return _bootstrap._gcd_import(name[level:], package, level)
  File "<frozen importlib._bootstrap>", line 1050, in _gcd_import
  File "<frozen importlib._bootstrap>", line 1027, in _find_and_load
  File "<frozen importlib._bootstrap>", line 1004, in _find_and_load_unlocked
ModuleNotFoundError: No module named 'linca'

During handling of the above exception, another exception occurred:

Traceback (most recent call last):
  File "/home/plm/ariasousse/apps/frappe/frappe/utils/error.py", line 86, in log_error_snapshot
    log_error(title=str(exception), defer_insert=True)
  File "/home/plm/ariasousse/apps/frappe/frappe/utils/error.py", line 61, in log_error
    error_log = frappe.get_doc(
  File "/home/plm/ariasousse/apps/frappe/frappe/__init__.py", line 1290, in get_doc
    doc = frappe.model.document.get_doc(*args, **kwargs)
  File "/home/plm/ariasousse/apps/frappe/frappe/model/document.py", line 83, in get_doc
    controller = get_controller(doctype)
  File "/home/plm/ariasousse/apps/frappe/frappe/model/base_document.py", line 70, in get_controller
    site_controllers[doctype] = import_controller(doctype)
  File "/home/plm/ariasousse/apps/frappe/frappe/model/base_document.py", line 88, in import_controller
    class_overrides = frappe.get_hooks("override_doctype_class")
  File "/home/plm/ariasousse/apps/frappe/frappe/__init__.py", line 1598, in get_hooks
    hooks = _dict(_load_app_hooks())
  File "/home/plm/ariasousse/apps/frappe/frappe/utils/caching.py", line 47, in wrapper
    return func(*args, **kwargs)
  File "/home/plm/ariasousse/apps/frappe/frappe/__init__.py", line 1567, in _load_app_hooks
    app_hooks = get_module(f"{app}.hooks")
  File "/home/plm/ariasousse/apps/frappe/frappe/__init__.py", line 1433, in get_module
    return importlib.import_module(modulename)
  File "/usr/lib/python3.10/importlib/__init__.py", line 126, in import_module
    return _bootstrap._gcd_import(name[level:], package, level)
  File "<frozen importlib._bootstrap>", line 1050, in _gcd_import
  File "<frozen importlib._bootstrap>", line 1027, in _find_and_load
  File "<frozen importlib._bootstrap>", line 992, in _find_and_load_unlocked
  File "<frozen importlib._bootstrap>", line 241, in _call_with_frames_removed
  File "<frozen importlib._bootstrap>", line 1050, in _gcd_import
  File "<frozen importlib._bootstrap>", line 1027, in _find_and_load
  File "<frozen importlib._bootstrap>", line 1004, in _find_and_load_unlocked
ModuleNotFoundError: No module named 'linca'
2025-01-08 11:11:26,292 ERROR frappe Could not take error snapshot: No module named 'linca'
Site: aria.localhost
Form Dict: {}
Traceback (most recent call last):
  File "/home/plm/ariasousse/apps/frappe/frappe/app.py", line 99, in application
    init_request(request)
  File "/home/plm/ariasousse/apps/frappe/frappe/app.py", line 172, in init_request
    frappe.init(site=site, sites_path=_sites_path, force=True)
  File "/home/plm/ariasousse/apps/frappe/frappe/__init__.py", line 257, in init
    setup_module_map(include_all_apps=not (frappe.request or frappe.job or frappe.flags.in_migrate))
  File "/home/plm/ariasousse/apps/frappe/frappe/__init__.py", line 1649, in setup_module_map
    for module in get_module_list(app):
  File "/home/plm/ariasousse/apps/frappe/frappe/__init__.py", line 1497, in get_module_list
    return get_file_items(get_app_path(app_name, "modules.txt"))
  File "/home/plm/ariasousse/apps/frappe/frappe/__init__.py", line 1462, in get_app_path
    return get_pymodule_path(app_name, *joins)
  File "/home/plm/ariasousse/apps/frappe/frappe/__init__.py", line 1492, in get_pymodule_path
    return abspath(join(dirname(get_module(scrub(modulename)).__file__ or ""), *joins))
  File "/home/plm/ariasousse/apps/frappe/frappe/__init__.py", line 1433, in get_module
    return importlib.import_module(modulename)
  File "/usr/lib/python3.10/importlib/__init__.py", line 126, in import_module
    return _bootstrap._gcd_import(name[level:], package, level)
  File "<frozen importlib._bootstrap>", line 1050, in _gcd_import
  File "<frozen importlib._bootstrap>", line 1027, in _find_and_load
  File "<frozen importlib._bootstrap>", line 1004, in _find_and_load_unlocked
ModuleNotFoundError: No module named 'linca'

During handling of the above exception, another exception occurred:

Traceback (most recent call last):
  File "/home/plm/ariasousse/apps/frappe/frappe/utils/error.py", line 86, in log_error_snapshot
    log_error(title=str(exception), defer_insert=True)
  File "/home/plm/ariasousse/apps/frappe/frappe/utils/error.py", line 61, in log_error
    error_log = frappe.get_doc(
  File "/home/plm/ariasousse/apps/frappe/frappe/__init__.py", line 1290, in get_doc
    doc = frappe.model.document.get_doc(*args, **kwargs)
  File "/home/plm/ariasousse/apps/frappe/frappe/model/document.py", line 83, in get_doc
    controller = get_controller(doctype)
  File "/home/plm/ariasousse/apps/frappe/frappe/model/base_document.py", line 70, in get_controller
    site_controllers[doctype] = import_controller(doctype)
  File "/home/plm/ariasousse/apps/frappe/frappe/model/base_document.py", line 88, in import_controller
    class_overrides = frappe.get_hooks("override_doctype_class")
  File "/home/plm/ariasousse/apps/frappe/frappe/__init__.py", line 1598, in get_hooks
    hooks = _dict(_load_app_hooks())
  File "/home/plm/ariasousse/apps/frappe/frappe/utils/caching.py", line 47, in wrapper
    return func(*args, **kwargs)
  File "/home/plm/ariasousse/apps/frappe/frappe/__init__.py", line 1567, in _load_app_hooks
    app_hooks = get_module(f"{app}.hooks")
  File "/home/plm/ariasousse/apps/frappe/frappe/__init__.py", line 1433, in get_module
    return importlib.import_module(modulename)
  File "/usr/lib/python3.10/importlib/__init__.py", line 126, in import_module
    return _bootstrap._gcd_import(name[level:], package, level)
  File "<frozen importlib._bootstrap>", line 1050, in _gcd_import
  File "<frozen importlib._bootstrap>", line 1027, in _find_and_load
  File "<frozen importlib._bootstrap>", line 992, in _find_and_load_unlocked
  File "<frozen importlib._bootstrap>", line 241, in _call_with_frames_removed
  File "<frozen importlib._bootstrap>", line 1050, in _gcd_import
  File "<frozen importlib._bootstrap>", line 1027, in _find_and_load
  File "<frozen importlib._bootstrap>", line 1004, in _find_and_load_unlocked
ModuleNotFoundError: No module named 'linca'
2025-01-08 11:11:50,318 ERROR frappe Could not take error snapshot: No module named 'linca'
Site: aria.localhost
Form Dict: {}
Traceback (most recent call last):
  File "/home/plm/ariasousse/apps/frappe/frappe/app.py", line 99, in application
    init_request(request)
  File "/home/plm/ariasousse/apps/frappe/frappe/app.py", line 172, in init_request
    frappe.init(site=site, sites_path=_sites_path, force=True)
  File "/home/plm/ariasousse/apps/frappe/frappe/__init__.py", line 257, in init
    setup_module_map(include_all_apps=not (frappe.request or frappe.job or frappe.flags.in_migrate))
  File "/home/plm/ariasousse/apps/frappe/frappe/__init__.py", line 1649, in setup_module_map
    for module in get_module_list(app):
  File "/home/plm/ariasousse/apps/frappe/frappe/__init__.py", line 1497, in get_module_list
    return get_file_items(get_app_path(app_name, "modules.txt"))
  File "/home/plm/ariasousse/apps/frappe/frappe/__init__.py", line 1462, in get_app_path
    return get_pymodule_path(app_name, *joins)
  File "/home/plm/ariasousse/apps/frappe/frappe/__init__.py", line 1492, in get_pymodule_path
    return abspath(join(dirname(get_module(scrub(modulename)).__file__ or ""), *joins))
  File "/home/plm/ariasousse/apps/frappe/frappe/__init__.py", line 1433, in get_module
    return importlib.import_module(modulename)
  File "/usr/lib/python3.10/importlib/__init__.py", line 126, in import_module
    return _bootstrap._gcd_import(name[level:], package, level)
  File "<frozen importlib._bootstrap>", line 1050, in _gcd_import
  File "<frozen importlib._bootstrap>", line 1027, in _find_and_load
  File "<frozen importlib._bootstrap>", line 1004, in _find_and_load_unlocked
ModuleNotFoundError: No module named 'linca'

During handling of the above exception, another exception occurred:

Traceback (most recent call last):
  File "/home/plm/ariasousse/apps/frappe/frappe/utils/error.py", line 86, in log_error_snapshot
    log_error(title=str(exception), defer_insert=True)
  File "/home/plm/ariasousse/apps/frappe/frappe/utils/error.py", line 61, in log_error
    error_log = frappe.get_doc(
  File "/home/plm/ariasousse/apps/frappe/frappe/__init__.py", line 1290, in get_doc
    doc = frappe.model.document.get_doc(*args, **kwargs)
  File "/home/plm/ariasousse/apps/frappe/frappe/model/document.py", line 83, in get_doc
    controller = get_controller(doctype)
  File "/home/plm/ariasousse/apps/frappe/frappe/model/base_document.py", line 70, in get_controller
    site_controllers[doctype] = import_controller(doctype)
  File "/home/plm/ariasousse/apps/frappe/frappe/model/base_document.py", line 88, in import_controller
    class_overrides = frappe.get_hooks("override_doctype_class")
  File "/home/plm/ariasousse/apps/frappe/frappe/__init__.py", line 1598, in get_hooks
    hooks = _dict(_load_app_hooks())
  File "/home/plm/ariasousse/apps/frappe/frappe/utils/caching.py", line 47, in wrapper
    return func(*args, **kwargs)
  File "/home/plm/ariasousse/apps/frappe/frappe/__init__.py", line 1567, in _load_app_hooks
    app_hooks = get_module(f"{app}.hooks")
  File "/home/plm/ariasousse/apps/frappe/frappe/__init__.py", line 1433, in get_module
    return importlib.import_module(modulename)
  File "/usr/lib/python3.10/importlib/__init__.py", line 126, in import_module
    return _bootstrap._gcd_import(name[level:], package, level)
  File "<frozen importlib._bootstrap>", line 1050, in _gcd_import
  File "<frozen importlib._bootstrap>", line 1027, in _find_and_load
  File "<frozen importlib._bootstrap>", line 992, in _find_and_load_unlocked
  File "<frozen importlib._bootstrap>", line 241, in _call_with_frames_removed
  File "<frozen importlib._bootstrap>", line 1050, in _gcd_import
  File "<frozen importlib._bootstrap>", line 1027, in _find_and_load
  File "<frozen importlib._bootstrap>", line 1004, in _find_and_load_unlocked
ModuleNotFoundError: No module named 'linca'
2025-01-08 11:12:07,564 ERROR frappe Could not take error snapshot: No module named 'linca'
Site: aria.localhost
Form Dict: {}
Traceback (most recent call last):
  File "/home/plm/ariasousse/apps/frappe/frappe/app.py", line 99, in application
    init_request(request)
  File "/home/plm/ariasousse/apps/frappe/frappe/app.py", line 172, in init_request
    frappe.init(site=site, sites_path=_sites_path, force=True)
  File "/home/plm/ariasousse/apps/frappe/frappe/__init__.py", line 257, in init
    setup_module_map(include_all_apps=not (frappe.request or frappe.job or frappe.flags.in_migrate))
  File "/home/plm/ariasousse/apps/frappe/frappe/__init__.py", line 1649, in setup_module_map
    for module in get_module_list(app):
  File "/home/plm/ariasousse/apps/frappe/frappe/__init__.py", line 1497, in get_module_list
    return get_file_items(get_app_path(app_name, "modules.txt"))
  File "/home/plm/ariasousse/apps/frappe/frappe/__init__.py", line 1462, in get_app_path
    return get_pymodule_path(app_name, *joins)
  File "/home/plm/ariasousse/apps/frappe/frappe/__init__.py", line 1492, in get_pymodule_path
    return abspath(join(dirname(get_module(scrub(modulename)).__file__ or ""), *joins))
  File "/home/plm/ariasousse/apps/frappe/frappe/__init__.py", line 1433, in get_module
    return importlib.import_module(modulename)
  File "/usr/lib/python3.10/importlib/__init__.py", line 126, in import_module
    return _bootstrap._gcd_import(name[level:], package, level)
  File "<frozen importlib._bootstrap>", line 1050, in _gcd_import
  File "<frozen importlib._bootstrap>", line 1027, in _find_and_load
  File "<frozen importlib._bootstrap>", line 1004, in _find_and_load_unlocked
ModuleNotFoundError: No module named 'linca'

During handling of the above exception, another exception occurred:

Traceback (most recent call last):
  File "/home/plm/ariasousse/apps/frappe/frappe/utils/error.py", line 86, in log_error_snapshot
    log_error(title=str(exception), defer_insert=True)
  File "/home/plm/ariasousse/apps/frappe/frappe/utils/error.py", line 61, in log_error
    error_log = frappe.get_doc(
  File "/home/plm/ariasousse/apps/frappe/frappe/__init__.py", line 1290, in get_doc
    doc = frappe.model.document.get_doc(*args, **kwargs)
  File "/home/plm/ariasousse/apps/frappe/frappe/model/document.py", line 83, in get_doc
    controller = get_controller(doctype)
  File "/home/plm/ariasousse/apps/frappe/frappe/model/base_document.py", line 70, in get_controller
    site_controllers[doctype] = import_controller(doctype)
  File "/home/plm/ariasousse/apps/frappe/frappe/model/base_document.py", line 88, in import_controller
    class_overrides = frappe.get_hooks("override_doctype_class")
  File "/home/plm/ariasousse/apps/frappe/frappe/__init__.py", line 1598, in get_hooks
    hooks = _dict(_load_app_hooks())
  File "/home/plm/ariasousse/apps/frappe/frappe/utils/caching.py", line 47, in wrapper
    return func(*args, **kwargs)
  File "/home/plm/ariasousse/apps/frappe/frappe/__init__.py", line 1567, in _load_app_hooks
    app_hooks = get_module(f"{app}.hooks")
  File "/home/plm/ariasousse/apps/frappe/frappe/__init__.py", line 1433, in get_module
    return importlib.import_module(modulename)
  File "/usr/lib/python3.10/importlib/__init__.py", line 126, in import_module
    return _bootstrap._gcd_import(name[level:], package, level)
  File "<frozen importlib._bootstrap>", line 1050, in _gcd_import
  File "<frozen importlib._bootstrap>", line 1027, in _find_and_load
  File "<frozen importlib._bootstrap>", line 992, in _find_and_load_unlocked
  File "<frozen importlib._bootstrap>", line 241, in _call_with_frames_removed
  File "<frozen importlib._bootstrap>", line 1050, in _gcd_import
  File "<frozen importlib._bootstrap>", line 1027, in _find_and_load
  File "<frozen importlib._bootstrap>", line 1004, in _find_and_load_unlocked
ModuleNotFoundError: No module named 'linca'
2025-01-08 11:12:15,728 ERROR frappe Could not take error snapshot: No module named 'linca'
Site: aria.localhost
Form Dict: {}
Traceback (most recent call last):
  File "/home/plm/ariasousse/apps/frappe/frappe/app.py", line 99, in application
    init_request(request)
  File "/home/plm/ariasousse/apps/frappe/frappe/app.py", line 172, in init_request
    frappe.init(site=site, sites_path=_sites_path, force=True)
  File "/home/plm/ariasousse/apps/frappe/frappe/__init__.py", line 257, in init
    setup_module_map(include_all_apps=not (frappe.request or frappe.job or frappe.flags.in_migrate))
  File "/home/plm/ariasousse/apps/frappe/frappe/__init__.py", line 1649, in setup_module_map
    for module in get_module_list(app):
  File "/home/plm/ariasousse/apps/frappe/frappe/__init__.py", line 1497, in get_module_list
    return get_file_items(get_app_path(app_name, "modules.txt"))
  File "/home/plm/ariasousse/apps/frappe/frappe/__init__.py", line 1462, in get_app_path
    return get_pymodule_path(app_name, *joins)
  File "/home/plm/ariasousse/apps/frappe/frappe/__init__.py", line 1492, in get_pymodule_path
    return abspath(join(dirname(get_module(scrub(modulename)).__file__ or ""), *joins))
  File "/home/plm/ariasousse/apps/frappe/frappe/__init__.py", line 1433, in get_module
    return importlib.import_module(modulename)
  File "/usr/lib/python3.10/importlib/__init__.py", line 126, in import_module
    return _bootstrap._gcd_import(name[level:], package, level)
  File "<frozen importlib._bootstrap>", line 1050, in _gcd_import
  File "<frozen importlib._bootstrap>", line 1027, in _find_and_load
  File "<frozen importlib._bootstrap>", line 1004, in _find_and_load_unlocked
ModuleNotFoundError: No module named 'linca'

During handling of the above exception, another exception occurred:

Traceback (most recent call last):
  File "/home/plm/ariasousse/apps/frappe/frappe/utils/error.py", line 86, in log_error_snapshot
    log_error(title=str(exception), defer_insert=True)
  File "/home/plm/ariasousse/apps/frappe/frappe/utils/error.py", line 61, in log_error
    error_log = frappe.get_doc(
  File "/home/plm/ariasousse/apps/frappe/frappe/__init__.py", line 1290, in get_doc
    doc = frappe.model.document.get_doc(*args, **kwargs)
  File "/home/plm/ariasousse/apps/frappe/frappe/model/document.py", line 83, in get_doc
    controller = get_controller(doctype)
  File "/home/plm/ariasousse/apps/frappe/frappe/model/base_document.py", line 70, in get_controller
    site_controllers[doctype] = import_controller(doctype)
  File "/home/plm/ariasousse/apps/frappe/frappe/model/base_document.py", line 88, in import_controller
    class_overrides = frappe.get_hooks("override_doctype_class")
  File "/home/plm/ariasousse/apps/frappe/frappe/__init__.py", line 1598, in get_hooks
    hooks = _dict(_load_app_hooks())
  File "/home/plm/ariasousse/apps/frappe/frappe/utils/caching.py", line 47, in wrapper
    return func(*args, **kwargs)
  File "/home/plm/ariasousse/apps/frappe/frappe/__init__.py", line 1567, in _load_app_hooks
    app_hooks = get_module(f"{app}.hooks")
  File "/home/plm/ariasousse/apps/frappe/frappe/__init__.py", line 1433, in get_module
    return importlib.import_module(modulename)
  File "/usr/lib/python3.10/importlib/__init__.py", line 126, in import_module
    return _bootstrap._gcd_import(name[level:], package, level)
  File "<frozen importlib._bootstrap>", line 1050, in _gcd_import
  File "<frozen importlib._bootstrap>", line 1027, in _find_and_load
  File "<frozen importlib._bootstrap>", line 992, in _find_and_load_unlocked
  File "<frozen importlib._bootstrap>", line 241, in _call_with_frames_removed
  File "<frozen importlib._bootstrap>", line 1050, in _gcd_import
  File "<frozen importlib._bootstrap>", line 1027, in _find_and_load
  File "<frozen importlib._bootstrap>", line 1004, in _find_and_load_unlocked
ModuleNotFoundError: No module named 'linca'
2025-01-08 11:12:36,416 ERROR frappe Could not take error snapshot: No module named 'linca'
Site: aria.localhost
Form Dict: {}
Traceback (most recent call last):
  File "/home/plm/ariasousse/apps/frappe/frappe/app.py", line 99, in application
    init_request(request)
  File "/home/plm/ariasousse/apps/frappe/frappe/app.py", line 172, in init_request
    frappe.init(site=site, sites_path=_sites_path, force=True)
  File "/home/plm/ariasousse/apps/frappe/frappe/__init__.py", line 257, in init
    setup_module_map(include_all_apps=not (frappe.request or frappe.job or frappe.flags.in_migrate))
  File "/home/plm/ariasousse/apps/frappe/frappe/__init__.py", line 1649, in setup_module_map
    for module in get_module_list(app):
  File "/home/plm/ariasousse/apps/frappe/frappe/__init__.py", line 1497, in get_module_list
    return get_file_items(get_app_path(app_name, "modules.txt"))
  File "/home/plm/ariasousse/apps/frappe/frappe/__init__.py", line 1462, in get_app_path
    return get_pymodule_path(app_name, *joins)
  File "/home/plm/ariasousse/apps/frappe/frappe/__init__.py", line 1492, in get_pymodule_path
    return abspath(join(dirname(get_module(scrub(modulename)).__file__ or ""), *joins))
  File "/home/plm/ariasousse/apps/frappe/frappe/__init__.py", line 1433, in get_module
    return importlib.import_module(modulename)
  File "/usr/lib/python3.10/importlib/__init__.py", line 126, in import_module
    return _bootstrap._gcd_import(name[level:], package, level)
  File "<frozen importlib._bootstrap>", line 1050, in _gcd_import
  File "<frozen importlib._bootstrap>", line 1027, in _find_and_load
  File "<frozen importlib._bootstrap>", line 1004, in _find_and_load_unlocked
ModuleNotFoundError: No module named 'linca'

During handling of the above exception, another exception occurred:

Traceback (most recent call last):
  File "/home/plm/ariasousse/apps/frappe/frappe/utils/error.py", line 86, in log_error_snapshot
    log_error(title=str(exception), defer_insert=True)
  File "/home/plm/ariasousse/apps/frappe/frappe/utils/error.py", line 61, in log_error
    error_log = frappe.get_doc(
  File "/home/plm/ariasousse/apps/frappe/frappe/__init__.py", line 1290, in get_doc
    doc = frappe.model.document.get_doc(*args, **kwargs)
  File "/home/plm/ariasousse/apps/frappe/frappe/model/document.py", line 83, in get_doc
    controller = get_controller(doctype)
  File "/home/plm/ariasousse/apps/frappe/frappe/model/base_document.py", line 70, in get_controller
    site_controllers[doctype] = import_controller(doctype)
  File "/home/plm/ariasousse/apps/frappe/frappe/model/base_document.py", line 88, in import_controller
    class_overrides = frappe.get_hooks("override_doctype_class")
  File "/home/plm/ariasousse/apps/frappe/frappe/__init__.py", line 1598, in get_hooks
    hooks = _dict(_load_app_hooks())
  File "/home/plm/ariasousse/apps/frappe/frappe/utils/caching.py", line 47, in wrapper
    return func(*args, **kwargs)
  File "/home/plm/ariasousse/apps/frappe/frappe/__init__.py", line 1567, in _load_app_hooks
    app_hooks = get_module(f"{app}.hooks")
  File "/home/plm/ariasousse/apps/frappe/frappe/__init__.py", line 1433, in get_module
    return importlib.import_module(modulename)
  File "/usr/lib/python3.10/importlib/__init__.py", line 126, in import_module
    return _bootstrap._gcd_import(name[level:], package, level)
  File "<frozen importlib._bootstrap>", line 1050, in _gcd_import
  File "<frozen importlib._bootstrap>", line 1027, in _find_and_load
  File "<frozen importlib._bootstrap>", line 992, in _find_and_load_unlocked
  File "<frozen importlib._bootstrap>", line 241, in _call_with_frames_removed
  File "<frozen importlib._bootstrap>", line 1050, in _gcd_import
  File "<frozen importlib._bootstrap>", line 1027, in _find_and_load
  File "<frozen importlib._bootstrap>", line 1004, in _find_and_load_unlocked
ModuleNotFoundError: No module named 'linca'
2025-01-08 11:12:53,495 ERROR frappe Could not take error snapshot: No module named 'linca'
Site: aria.localhost
Form Dict: {}
Traceback (most recent call last):
  File "/home/plm/ariasousse/apps/frappe/frappe/app.py", line 99, in application
    init_request(request)
  File "/home/plm/ariasousse/apps/frappe/frappe/app.py", line 172, in init_request
    frappe.init(site=site, sites_path=_sites_path, force=True)
  File "/home/plm/ariasousse/apps/frappe/frappe/__init__.py", line 257, in init
    setup_module_map(include_all_apps=not (frappe.request or frappe.job or frappe.flags.in_migrate))
  File "/home/plm/ariasousse/apps/frappe/frappe/__init__.py", line 1649, in setup_module_map
    for module in get_module_list(app):
  File "/home/plm/ariasousse/apps/frappe/frappe/__init__.py", line 1497, in get_module_list
    return get_file_items(get_app_path(app_name, "modules.txt"))
  File "/home/plm/ariasousse/apps/frappe/frappe/__init__.py", line 1462, in get_app_path
    return get_pymodule_path(app_name, *joins)
  File "/home/plm/ariasousse/apps/frappe/frappe/__init__.py", line 1492, in get_pymodule_path
    return abspath(join(dirname(get_module(scrub(modulename)).__file__ or ""), *joins))
  File "/home/plm/ariasousse/apps/frappe/frappe/__init__.py", line 1433, in get_module
    return importlib.import_module(modulename)
  File "/usr/lib/python3.10/importlib/__init__.py", line 126, in import_module
    return _bootstrap._gcd_import(name[level:], package, level)
  File "<frozen importlib._bootstrap>", line 1050, in _gcd_import
  File "<frozen importlib._bootstrap>", line 1027, in _find_and_load
  File "<frozen importlib._bootstrap>", line 1004, in _find_and_load_unlocked
ModuleNotFoundError: No module named 'linca'

During handling of the above exception, another exception occurred:

Traceback (most recent call last):
  File "/home/plm/ariasousse/apps/frappe/frappe/utils/error.py", line 86, in log_error_snapshot
    log_error(title=str(exception), defer_insert=True)
  File "/home/plm/ariasousse/apps/frappe/frappe/utils/error.py", line 61, in log_error
    error_log = frappe.get_doc(
  File "/home/plm/ariasousse/apps/frappe/frappe/__init__.py", line 1290, in get_doc
    doc = frappe.model.document.get_doc(*args, **kwargs)
  File "/home/plm/ariasousse/apps/frappe/frappe/model/document.py", line 83, in get_doc
    controller = get_controller(doctype)
  File "/home/plm/ariasousse/apps/frappe/frappe/model/base_document.py", line 70, in get_controller
    site_controllers[doctype] = import_controller(doctype)
  File "/home/plm/ariasousse/apps/frappe/frappe/model/base_document.py", line 88, in import_controller
    class_overrides = frappe.get_hooks("override_doctype_class")
  File "/home/plm/ariasousse/apps/frappe/frappe/__init__.py", line 1598, in get_hooks
    hooks = _dict(_load_app_hooks())
  File "/home/plm/ariasousse/apps/frappe/frappe/utils/caching.py", line 47, in wrapper
    return func(*args, **kwargs)
  File "/home/plm/ariasousse/apps/frappe/frappe/__init__.py", line 1567, in _load_app_hooks
    app_hooks = get_module(f"{app}.hooks")
  File "/home/plm/ariasousse/apps/frappe/frappe/__init__.py", line 1433, in get_module
    return importlib.import_module(modulename)
  File "/usr/lib/python3.10/importlib/__init__.py", line 126, in import_module
    return _bootstrap._gcd_import(name[level:], package, level)
  File "<frozen importlib._bootstrap>", line 1050, in _gcd_import
  File "<frozen importlib._bootstrap>", line 1027, in _find_and_load
  File "<frozen importlib._bootstrap>", line 992, in _find_and_load_unlocked
  File "<frozen importlib._bootstrap>", line 241, in _call_with_frames_removed
  File "<frozen importlib._bootstrap>", line 1050, in _gcd_import
  File "<frozen importlib._bootstrap>", line 1027, in _find_and_load
  File "<frozen importlib._bootstrap>", line 1004, in _find_and_load_unlocked
ModuleNotFoundError: No module named 'linca'
2025-01-08 11:13:08,038 ERROR frappe Could not take error snapshot: No module named 'linca'
Site: aria.localhost
Form Dict: {}
Traceback (most recent call last):
  File "/home/plm/ariasousse/apps/frappe/frappe/app.py", line 99, in application
    init_request(request)
  File "/home/plm/ariasousse/apps/frappe/frappe/app.py", line 172, in init_request
    frappe.init(site=site, sites_path=_sites_path, force=True)
  File "/home/plm/ariasousse/apps/frappe/frappe/__init__.py", line 257, in init
    setup_module_map(include_all_apps=not (frappe.request or frappe.job or frappe.flags.in_migrate))
  File "/home/plm/ariasousse/apps/frappe/frappe/__init__.py", line 1649, in setup_module_map
    for module in get_module_list(app):
  File "/home/plm/ariasousse/apps/frappe/frappe/__init__.py", line 1497, in get_module_list
    return get_file_items(get_app_path(app_name, "modules.txt"))
  File "/home/plm/ariasousse/apps/frappe/frappe/__init__.py", line 1462, in get_app_path
    return get_pymodule_path(app_name, *joins)
  File "/home/plm/ariasousse/apps/frappe/frappe/__init__.py", line 1492, in get_pymodule_path
    return abspath(join(dirname(get_module(scrub(modulename)).__file__ or ""), *joins))
  File "/home/plm/ariasousse/apps/frappe/frappe/__init__.py", line 1433, in get_module
    return importlib.import_module(modulename)
  File "/usr/lib/python3.10/importlib/__init__.py", line 126, in import_module
    return _bootstrap._gcd_import(name[level:], package, level)
  File "<frozen importlib._bootstrap>", line 1050, in _gcd_import
  File "<frozen importlib._bootstrap>", line 1027, in _find_and_load
  File "<frozen importlib._bootstrap>", line 1004, in _find_and_load_unlocked
ModuleNotFoundError: No module named 'linca'

During handling of the above exception, another exception occurred:

Traceback (most recent call last):
  File "/home/plm/ariasousse/apps/frappe/frappe/utils/error.py", line 86, in log_error_snapshot
    log_error(title=str(exception), defer_insert=True)
  File "/home/plm/ariasousse/apps/frappe/frappe/utils/error.py", line 61, in log_error
    error_log = frappe.get_doc(
  File "/home/plm/ariasousse/apps/frappe/frappe/__init__.py", line 1290, in get_doc
    doc = frappe.model.document.get_doc(*args, **kwargs)
  File "/home/plm/ariasousse/apps/frappe/frappe/model/document.py", line 83, in get_doc
    controller = get_controller(doctype)
  File "/home/plm/ariasousse/apps/frappe/frappe/model/base_document.py", line 70, in get_controller
    site_controllers[doctype] = import_controller(doctype)
  File "/home/plm/ariasousse/apps/frappe/frappe/model/base_document.py", line 88, in import_controller
    class_overrides = frappe.get_hooks("override_doctype_class")
  File "/home/plm/ariasousse/apps/frappe/frappe/__init__.py", line 1598, in get_hooks
    hooks = _dict(_load_app_hooks())
  File "/home/plm/ariasousse/apps/frappe/frappe/utils/caching.py", line 47, in wrapper
    return func(*args, **kwargs)
  File "/home/plm/ariasousse/apps/frappe/frappe/__init__.py", line 1567, in _load_app_hooks
    app_hooks = get_module(f"{app}.hooks")
  File "/home/plm/ariasousse/apps/frappe/frappe/__init__.py", line 1433, in get_module
    return importlib.import_module(modulename)
  File "/usr/lib/python3.10/importlib/__init__.py", line 126, in import_module
    return _bootstrap._gcd_import(name[level:], package, level)
  File "<frozen importlib._bootstrap>", line 1050, in _gcd_import
  File "<frozen importlib._bootstrap>", line 1027, in _find_and_load
  File "<frozen importlib._bootstrap>", line 992, in _find_and_load_unlocked
  File "<frozen importlib._bootstrap>", line 241, in _call_with_frames_removed
  File "<frozen importlib._bootstrap>", line 1050, in _gcd_import
  File "<frozen importlib._bootstrap>", line 1027, in _find_and_load
  File "<frozen importlib._bootstrap>", line 1004, in _find_and_load_unlocked
ModuleNotFoundError: No module named 'linca'
2025-01-08 13:12:59,312 ERROR frappe Could not take error snapshot: (2003, "Can't connect to MySQL server on '127.0.0.1' ([Errno 111] Connection refused)")
Site: aria.localhost
Form Dict: {}
Traceback (most recent call last):
  File "/home/plm/ariasousse/env/lib/python3.10/site-packages/pymysql/connections.py", line 649, in connect
    sock = socket.create_connection(
  File "/usr/lib/python3.10/socket.py", line 845, in create_connection
    raise err
  File "/usr/lib/python3.10/socket.py", line 833, in create_connection
    sock.connect(sa)
ConnectionRefusedError: [Errno 111] Connection refused

During handling of the above exception, another exception occurred:

Traceback (most recent call last):
  File "/home/plm/ariasousse/apps/frappe/frappe/website/serve.py", line 19, in get_response
    endpoint, renderer_instance = path_resolver.resolve()
  File "/home/plm/ariasousse/apps/frappe/frappe/website/path_resolver.py", line 38, in resolve
    resolve_redirect(self.path, request.query_string)
  File "/home/plm/ariasousse/apps/frappe/frappe/website/path_resolver.py", line 118, in resolve_redirect
    redirects += frappe.get_all(
  File "/home/plm/ariasousse/apps/frappe/frappe/__init__.py", line 2014, in get_all
    return get_list(doctype, *args, **kwargs)
  File "/home/plm/ariasousse/apps/frappe/frappe/__init__.py", line 1989, in get_list
    return frappe.model.db_query.DatabaseQuery(doctype).execute(*args, **kwargs)
  File "/home/plm/ariasousse/apps/frappe/frappe/model/db_query.py", line 191, in execute
    result = self.build_and_run()
  File "/home/plm/ariasousse/apps/frappe/frappe/model/db_query.py", line 232, in build_and_run
    return frappe.db.sql(
  File "/home/plm/ariasousse/apps/frappe/frappe/database/database.py", line 207, in sql
    self.connect()
  File "/home/plm/ariasousse/apps/frappe/frappe/database/database.py", line 112, in connect
    self._conn: "MariadbConnection" | "PostgresConnection" = self.get_connection()
  File "/home/plm/ariasousse/apps/frappe/frappe/database/mariadb/database.py", line 107, in get_connection
    conn = self._get_connection()
  File "/home/plm/ariasousse/apps/frappe/frappe/database/mariadb/database.py", line 113, in _get_connection
    return self.create_connection()
  File "/home/plm/ariasousse/apps/frappe/frappe/database/mariadb/database.py", line 116, in create_connection
    return pymysql.connect(**self.get_connection_settings())
  File "/home/plm/ariasousse/env/lib/python3.10/site-packages/pymysql/connections.py", line 361, in __init__
    self.connect()
  File "/home/plm/ariasousse/env/lib/python3.10/site-packages/pymysql/connections.py", line 716, in connect
    raise exc
pymysql.err.OperationalError: (2003, "Can't connect to MySQL server on '127.0.0.1' ([Errno 111] Connection refused)")

During handling of the above exception, another exception occurred:

Traceback (most recent call last):
  File "/home/plm/ariasousse/env/lib/python3.10/site-packages/pymysql/connections.py", line 649, in connect
    sock = socket.create_connection(
  File "/usr/lib/python3.10/socket.py", line 845, in create_connection
    raise err
  File "/usr/lib/python3.10/socket.py", line 833, in create_connection
    sock.connect(sa)
ConnectionRefusedError: [Errno 111] Connection refused

During handling of the above exception, another exception occurred:

Traceback (most recent call last):
  File "/home/plm/ariasousse/apps/frappe/frappe/app.py", line 123, in application
    response = get_response()
  File "/home/plm/ariasousse/apps/frappe/frappe/website/serve.py", line 28, in get_response
    response = ErrorPage(exception=e).render()
  File "/home/plm/ariasousse/apps/frappe/frappe/website/page_renderers/template_page.py", line 84, in render
    html = self.get_html()
  File "/home/plm/ariasousse/apps/frappe/frappe/website/utils.py", line 530, in cache_html_decorator
    html = func(*args, **kwargs)
  File "/home/plm/ariasousse/apps/frappe/frappe/website/page_renderers/template_page.py", line 92, in get_html
    self.init_context()
  File "/home/plm/ariasousse/apps/frappe/frappe/website/page_renderers/error_page.py", line 14, in init_context
    super().init_context()
  File "/home/plm/ariasousse/apps/frappe/frappe/website/page_renderers/base_template_page.py", line 15, in init_context
    self.context.update(get_website_settings())
  File "/home/plm/ariasousse/apps/frappe/frappe/website/doctype/website_settings/website_settings.py", line 263, in get_website_settings
    context.boot = get_boot_data()
  File "/home/plm/ariasousse/apps/frappe/frappe/website/utils.py", line 169, in get_boot_data
    apps = get_apps() or []
  File "/home/plm/ariasousse/apps/frappe/frappe/utils/typing_validations.py", line 31, in wrapper
    return func(*args, **kwargs)
  File "/home/plm/ariasousse/apps/frappe/frappe/apps.py", line 15, in get_apps
    allowed_workspaces = get_workspace_sidebar_items().get("pages")
  File "/home/plm/ariasousse/apps/frappe/frappe/utils/typing_validations.py", line 31, in wrapper
    return func(*args, **kwargs)
  File "/home/plm/ariasousse/apps/frappe/frappe/desk/desktop.py", line 447, in get_workspace_sidebar_items
    all_pages = frappe.get_all(
  File "/home/plm/ariasousse/apps/frappe/frappe/__init__.py", line 2014, in get_all
    return get_list(doctype, *args, **kwargs)
  File "/home/plm/ariasousse/apps/frappe/frappe/__init__.py", line 1989, in get_list
    return frappe.model.db_query.DatabaseQuery(doctype).execute(*args, **kwargs)
  File "/home/plm/ariasousse/apps/frappe/frappe/model/db_query.py", line 191, in execute
    result = self.build_and_run()
  File "/home/plm/ariasousse/apps/frappe/frappe/model/db_query.py", line 232, in build_and_run
    return frappe.db.sql(
  File "/home/plm/ariasousse/apps/frappe/frappe/database/database.py", line 207, in sql
    self.connect()
  File "/home/plm/ariasousse/apps/frappe/frappe/database/database.py", line 112, in connect
    self._conn: "MariadbConnection" | "PostgresConnection" = self.get_connection()
  File "/home/plm/ariasousse/apps/frappe/frappe/database/mariadb/database.py", line 107, in get_connection
    conn = self._get_connection()
  File "/home/plm/ariasousse/apps/frappe/frappe/database/mariadb/database.py", line 113, in _get_connection
    return self.create_connection()
  File "/home/plm/ariasousse/apps/frappe/frappe/database/mariadb/database.py", line 116, in create_connection
    return pymysql.connect(**self.get_connection_settings())
  File "/home/plm/ariasousse/env/lib/python3.10/site-packages/pymysql/connections.py", line 361, in __init__
    self.connect()
  File "/home/plm/ariasousse/env/lib/python3.10/site-packages/pymysql/connections.py", line 716, in connect
    raise exc
pymysql.err.OperationalError: (2003, "Can't connect to MySQL server on '127.0.0.1' ([Errno 111] Connection refused)")

During handling of the above exception, another exception occurred:

Traceback (most recent call last):
  File "/home/plm/ariasousse/env/lib/python3.10/site-packages/pymysql/connections.py", line 649, in connect
    sock = socket.create_connection(
  File "/usr/lib/python3.10/socket.py", line 845, in create_connection
    raise err
  File "/usr/lib/python3.10/socket.py", line 833, in create_connection
    sock.connect(sa)
ConnectionRefusedError: [Errno 111] Connection refused

During handling of the above exception, another exception occurred:

Traceback (most recent call last):
  File "/home/plm/ariasousse/apps/frappe/frappe/utils/error.py", line 86, in log_error_snapshot
    log_error(title=str(exception), defer_insert=True)
  File "/home/plm/ariasousse/apps/frappe/frappe/utils/error.py", line 61, in log_error
    error_log = frappe.get_doc(
  File "/home/plm/ariasousse/apps/frappe/frappe/__init__.py", line 1290, in get_doc
    doc = frappe.model.document.get_doc(*args, **kwargs)
  File "/home/plm/ariasousse/apps/frappe/frappe/model/document.py", line 83, in get_doc
    controller = get_controller(doctype)
  File "/home/plm/ariasousse/apps/frappe/frappe/model/base_document.py", line 70, in get_controller
    site_controllers[doctype] = import_controller(doctype)
  File "/home/plm/ariasousse/apps/frappe/frappe/model/base_document.py", line 81, in import_controller
    doctype_info = frappe.db.get_value("DocType", doctype, fieldname="*")
  File "/home/plm/ariasousse/apps/frappe/frappe/database/database.py", line 515, in get_value
    result = self.get_values(
  File "/home/plm/ariasousse/apps/frappe/frappe/database/database.py", line 619, in get_values
    out = self._get_values_from_table(
  File "/home/plm/ariasousse/apps/frappe/frappe/database/database.py", line 892, in _get_values_from_table
    return query.run(as_dict=as_dict, debug=debug, update=update, run=run, pluck=pluck)
  File "/home/plm/ariasousse/apps/frappe/frappe/query_builder/utils.py", line 87, in execute_query
    result = frappe.db.sql(query, params, *args, **kwargs)  # nosemgrep
  File "/home/plm/ariasousse/apps/frappe/frappe/database/database.py", line 207, in sql
    self.connect()
  File "/home/plm/ariasousse/apps/frappe/frappe/database/database.py", line 112, in connect
    self._conn: "MariadbConnection" | "PostgresConnection" = self.get_connection()
  File "/home/plm/ariasousse/apps/frappe/frappe/database/mariadb/database.py", line 107, in get_connection
    conn = self._get_connection()
  File "/home/plm/ariasousse/apps/frappe/frappe/database/mariadb/database.py", line 113, in _get_connection
    return self.create_connection()
  File "/home/plm/ariasousse/apps/frappe/frappe/database/mariadb/database.py", line 116, in create_connection
    return pymysql.connect(**self.get_connection_settings())
  File "/home/plm/ariasousse/env/lib/python3.10/site-packages/pymysql/connections.py", line 361, in __init__
    self.connect()
  File "/home/plm/ariasousse/env/lib/python3.10/site-packages/pymysql/connections.py", line 716, in connect
    raise exc
pymysql.err.OperationalError: (2003, "Can't connect to MySQL server on '127.0.0.1' ([Errno 111] Connection refused)")
2025-01-08 14:30:55,503 ERROR frappe Could not take error snapshot: (2003, "Can't connect to MySQL server on '127.0.0.1' ([Errno 111] Connection refused)")
Site: aria.localhost
Form Dict: {'doctype': 'DocType', 'docname': 'Patient et demande', 'fields': '[]', 'cmd': 'frappe.client.validate_link'}
Traceback (most recent call last):
  File "/home/plm/ariasousse/env/lib/python3.10/site-packages/pymysql/connections.py", line 649, in connect
    sock = socket.create_connection(
  File "/usr/lib/python3.10/socket.py", line 845, in create_connection
    raise err
  File "/usr/lib/python3.10/socket.py", line 833, in create_connection
    sock.connect(sa)
ConnectionRefusedError: [Errno 111] Connection refused

During handling of the above exception, another exception occurred:

Traceback (most recent call last):
  File "/home/plm/ariasousse/apps/frappe/frappe/app.py", line 114, in application
    response = frappe.api.handle(request)
  File "/home/plm/ariasousse/apps/frappe/frappe/api/__init__.py", line 49, in handle
    data = endpoint(**arguments)
  File "/home/plm/ariasousse/apps/frappe/frappe/api/v1.py", line 36, in handle_rpc_call
    return frappe.handler.handle()
  File "/home/plm/ariasousse/apps/frappe/frappe/handler.py", line 49, in handle
    data = execute_cmd(cmd)
  File "/home/plm/ariasousse/apps/frappe/frappe/handler.py", line 85, in execute_cmd
    return frappe.call(method, **frappe.form_dict)
  File "/home/plm/ariasousse/apps/frappe/frappe/__init__.py", line 1725, in call
    return fn(*args, **newargs)
  File "/home/plm/ariasousse/apps/frappe/frappe/utils/typing_validations.py", line 31, in wrapper
    return func(*args, **kwargs)
  File "/home/plm/ariasousse/apps/frappe/frappe/client.py", line 447, in validate_link
    values.name = frappe.db.get_value(doctype, docname, cache=True)
  File "/home/plm/ariasousse/apps/frappe/frappe/database/database.py", line 515, in get_value
    result = self.get_values(
  File "/home/plm/ariasousse/apps/frappe/frappe/database/database.py", line 619, in get_values
    out = self._get_values_from_table(
  File "/home/plm/ariasousse/apps/frappe/frappe/database/database.py", line 892, in _get_values_from_table
    return query.run(as_dict=as_dict, debug=debug, update=update, run=run, pluck=pluck)
  File "/home/plm/ariasousse/apps/frappe/frappe/query_builder/utils.py", line 87, in execute_query
    result = frappe.db.sql(query, params, *args, **kwargs)  # nosemgrep
  File "/home/plm/ariasousse/apps/frappe/frappe/database/database.py", line 207, in sql
    self.connect()
  File "/home/plm/ariasousse/apps/frappe/frappe/database/database.py", line 112, in connect
    self._conn: "MariadbConnection" | "PostgresConnection" = self.get_connection()
  File "/home/plm/ariasousse/apps/frappe/frappe/database/mariadb/database.py", line 107, in get_connection
    conn = self._get_connection()
  File "/home/plm/ariasousse/apps/frappe/frappe/database/mariadb/database.py", line 113, in _get_connection
    return self.create_connection()
  File "/home/plm/ariasousse/apps/frappe/frappe/database/mariadb/database.py", line 116, in create_connection
    return pymysql.connect(**self.get_connection_settings())
  File "/home/plm/ariasousse/env/lib/python3.10/site-packages/pymysql/connections.py", line 361, in __init__
    self.connect()
  File "/home/plm/ariasousse/env/lib/python3.10/site-packages/pymysql/connections.py", line 716, in connect
    raise exc
pymysql.err.OperationalError: (2003, "Can't connect to MySQL server on '127.0.0.1' ([Errno 111] Connection refused)")

During handling of the above exception, another exception occurred:

Traceback (most recent call last):
  File "/home/plm/ariasousse/env/lib/python3.10/site-packages/pymysql/connections.py", line 649, in connect
    sock = socket.create_connection(
  File "/usr/lib/python3.10/socket.py", line 845, in create_connection
    raise err
  File "/usr/lib/python3.10/socket.py", line 833, in create_connection
    sock.connect(sa)
ConnectionRefusedError: [Errno 111] Connection refused

During handling of the above exception, another exception occurred:

Traceback (most recent call last):
  File "/home/plm/ariasousse/apps/frappe/frappe/utils/error.py", line 86, in log_error_snapshot
    log_error(title=str(exception), defer_insert=True)
  File "/home/plm/ariasousse/apps/frappe/frappe/utils/error.py", line 61, in log_error
    error_log = frappe.get_doc(
  File "/home/plm/ariasousse/apps/frappe/frappe/__init__.py", line 1290, in get_doc
    doc = frappe.model.document.get_doc(*args, **kwargs)
  File "/home/plm/ariasousse/apps/frappe/frappe/model/document.py", line 83, in get_doc
    controller = get_controller(doctype)
  File "/home/plm/ariasousse/apps/frappe/frappe/model/base_document.py", line 70, in get_controller
    site_controllers[doctype] = import_controller(doctype)
  File "/home/plm/ariasousse/apps/frappe/frappe/model/base_document.py", line 81, in import_controller
    doctype_info = frappe.db.get_value("DocType", doctype, fieldname="*")
  File "/home/plm/ariasousse/apps/frappe/frappe/database/database.py", line 515, in get_value
    result = self.get_values(
  File "/home/plm/ariasousse/apps/frappe/frappe/database/database.py", line 619, in get_values
    out = self._get_values_from_table(
  File "/home/plm/ariasousse/apps/frappe/frappe/database/database.py", line 892, in _get_values_from_table
    return query.run(as_dict=as_dict, debug=debug, update=update, run=run, pluck=pluck)
  File "/home/plm/ariasousse/apps/frappe/frappe/query_builder/utils.py", line 87, in execute_query
    result = frappe.db.sql(query, params, *args, **kwargs)  # nosemgrep
  File "/home/plm/ariasousse/apps/frappe/frappe/database/database.py", line 207, in sql
    self.connect()
  File "/home/plm/ariasousse/apps/frappe/frappe/database/database.py", line 112, in connect
    self._conn: "MariadbConnection" | "PostgresConnection" = self.get_connection()
  File "/home/plm/ariasousse/apps/frappe/frappe/database/mariadb/database.py", line 107, in get_connection
    conn = self._get_connection()
  File "/home/plm/ariasousse/apps/frappe/frappe/database/mariadb/database.py", line 113, in _get_connection
    return self.create_connection()
  File "/home/plm/ariasousse/apps/frappe/frappe/database/mariadb/database.py", line 116, in create_connection
    return pymysql.connect(**self.get_connection_settings())
  File "/home/plm/ariasousse/env/lib/python3.10/site-packages/pymysql/connections.py", line 361, in __init__
    self.connect()
  File "/home/plm/ariasousse/env/lib/python3.10/site-packages/pymysql/connections.py", line 716, in connect
    raise exc
pymysql.err.OperationalError: (2003, "Can't connect to MySQL server on '127.0.0.1' ([Errno 111] Connection refused)")
2025-01-08 14:31:07,393 ERROR frappe Could not take error snapshot: (2003, "Can't connect to MySQL server on '127.0.0.1' ([Errno 111] Connection refused)")
Site: aria.localhost
Form Dict: {'doc': '{"name":"Avis a modfier","owner":"linca@linca.com","creation":"2024-12-27 09:26:46.221590","modified":"2024-12-27 09:49:08.412829","modified_by":"Administrator","docstatus":0,"idx":7,"is_standard":0,"label":"Avis a modfier ","custom_backrougnd":"#EC864B","type":"Document Type","function":"Count","aggregate_function_based_on":"","document_type":"Patient et demande","parent_document_type":"","report_function":"Sum","is_public":1,"show_percentage_stats":1,"stats_time_interval":"Daily","filters_json":"[[\\"Patient et demande\\",\\"status\\",\\"=\\",\\"Avis à modifier\\",false]]","dynamic_filters_json":"[]","doctype":"Number Card","__unsaved":1}', 'action': 'Save', 'cmd': 'frappe.desk.form.save.savedocs'}
Traceback (most recent call last):
  File "/home/plm/ariasousse/env/lib/python3.10/site-packages/pymysql/connections.py", line 649, in connect
    sock = socket.create_connection(
  File "/usr/lib/python3.10/socket.py", line 845, in create_connection
    raise err
  File "/usr/lib/python3.10/socket.py", line 833, in create_connection
    sock.connect(sa)
ConnectionRefusedError: [Errno 111] Connection refused

During handling of the above exception, another exception occurred:

Traceback (most recent call last):
  File "/home/plm/ariasousse/apps/frappe/frappe/app.py", line 114, in application
    response = frappe.api.handle(request)
  File "/home/plm/ariasousse/apps/frappe/frappe/api/__init__.py", line 49, in handle
    data = endpoint(**arguments)
  File "/home/plm/ariasousse/apps/frappe/frappe/api/v1.py", line 36, in handle_rpc_call
    return frappe.handler.handle()
  File "/home/plm/ariasousse/apps/frappe/frappe/handler.py", line 49, in handle
    data = execute_cmd(cmd)
  File "/home/plm/ariasousse/apps/frappe/frappe/handler.py", line 85, in execute_cmd
    return frappe.call(method, **frappe.form_dict)
  File "/home/plm/ariasousse/apps/frappe/frappe/__init__.py", line 1725, in call
    return fn(*args, **newargs)
  File "/home/plm/ariasousse/apps/frappe/frappe/utils/typing_validations.py", line 31, in wrapper
    return func(*args, **kwargs)
  File "/home/plm/ariasousse/apps/frappe/frappe/desk/form/save.py", line 39, in savedocs
    doc.save()
  File "/home/plm/ariasousse/apps/frappe/frappe/model/document.py", line 342, in save
    return self._save(*args, **kwargs)
  File "/home/plm/ariasousse/apps/frappe/frappe/model/document.py", line 372, in _save
    self.check_if_latest()
  File "/home/plm/ariasousse/apps/frappe/frappe/model/document.py", line 816, in check_if_latest
    self.load_doc_before_save(raise_exception=True)
  File "/home/plm/ariasousse/apps/frappe/frappe/model/document.py", line 1124, in load_doc_before_save
    self._doc_before_save = frappe.get_doc(self.doctype, self.name, for_update=True)
  File "/home/plm/ariasousse/apps/frappe/frappe/__init__.py", line 1290, in get_doc
    doc = frappe.model.document.get_doc(*args, **kwargs)
  File "/home/plm/ariasousse/apps/frappe/frappe/model/document.py", line 85, in get_doc
    return controller(*args, **kwargs)
  File "/home/plm/ariasousse/apps/frappe/frappe/model/document.py", line 126, in __init__
    self.load_from_db()
  File "/home/plm/ariasousse/apps/frappe/frappe/model/document.py", line 167, in load_from_db
    d = frappe.db.get_value(
  File "/home/plm/ariasousse/apps/frappe/frappe/database/database.py", line 515, in get_value
    result = self.get_values(
  File "/home/plm/ariasousse/apps/frappe/frappe/database/database.py", line 619, in get_values
    out = self._get_values_from_table(
  File "/home/plm/ariasousse/apps/frappe/frappe/database/database.py", line 892, in _get_values_from_table
    return query.run(as_dict=as_dict, debug=debug, update=update, run=run, pluck=pluck)
  File "/home/plm/ariasousse/apps/frappe/frappe/query_builder/utils.py", line 87, in execute_query
    result = frappe.db.sql(query, params, *args, **kwargs)  # nosemgrep
  File "/home/plm/ariasousse/apps/frappe/frappe/database/database.py", line 207, in sql
    self.connect()
  File "/home/plm/ariasousse/apps/frappe/frappe/database/database.py", line 112, in connect
    self._conn: "MariadbConnection" | "PostgresConnection" = self.get_connection()
  File "/home/plm/ariasousse/apps/frappe/frappe/database/mariadb/database.py", line 107, in get_connection
    conn = self._get_connection()
  File "/home/plm/ariasousse/apps/frappe/frappe/database/mariadb/database.py", line 113, in _get_connection
    return self.create_connection()
  File "/home/plm/ariasousse/apps/frappe/frappe/database/mariadb/database.py", line 116, in create_connection
    return pymysql.connect(**self.get_connection_settings())
  File "/home/plm/ariasousse/env/lib/python3.10/site-packages/pymysql/connections.py", line 361, in __init__
    self.connect()
  File "/home/plm/ariasousse/env/lib/python3.10/site-packages/pymysql/connections.py", line 716, in connect
    raise exc
pymysql.err.OperationalError: (2003, "Can't connect to MySQL server on '127.0.0.1' ([Errno 111] Connection refused)")

During handling of the above exception, another exception occurred:

Traceback (most recent call last):
  File "/home/plm/ariasousse/env/lib/python3.10/site-packages/pymysql/connections.py", line 649, in connect
    sock = socket.create_connection(
  File "/usr/lib/python3.10/socket.py", line 845, in create_connection
    raise err
  File "/usr/lib/python3.10/socket.py", line 833, in create_connection
    sock.connect(sa)
ConnectionRefusedError: [Errno 111] Connection refused

During handling of the above exception, another exception occurred:

Traceback (most recent call last):
  File "/home/plm/ariasousse/apps/frappe/frappe/utils/error.py", line 86, in log_error_snapshot
    log_error(title=str(exception), defer_insert=True)
  File "/home/plm/ariasousse/apps/frappe/frappe/utils/error.py", line 61, in log_error
    error_log = frappe.get_doc(
  File "/home/plm/ariasousse/apps/frappe/frappe/__init__.py", line 1290, in get_doc
    doc = frappe.model.document.get_doc(*args, **kwargs)
  File "/home/plm/ariasousse/apps/frappe/frappe/model/document.py", line 83, in get_doc
    controller = get_controller(doctype)
  File "/home/plm/ariasousse/apps/frappe/frappe/model/base_document.py", line 70, in get_controller
    site_controllers[doctype] = import_controller(doctype)
  File "/home/plm/ariasousse/apps/frappe/frappe/model/base_document.py", line 81, in import_controller
    doctype_info = frappe.db.get_value("DocType", doctype, fieldname="*")
  File "/home/plm/ariasousse/apps/frappe/frappe/database/database.py", line 515, in get_value
    result = self.get_values(
  File "/home/plm/ariasousse/apps/frappe/frappe/database/database.py", line 619, in get_values
    out = self._get_values_from_table(
  File "/home/plm/ariasousse/apps/frappe/frappe/database/database.py", line 892, in _get_values_from_table
    return query.run(as_dict=as_dict, debug=debug, update=update, run=run, pluck=pluck)
  File "/home/plm/ariasousse/apps/frappe/frappe/query_builder/utils.py", line 87, in execute_query
    result = frappe.db.sql(query, params, *args, **kwargs)  # nosemgrep
  File "/home/plm/ariasousse/apps/frappe/frappe/database/database.py", line 207, in sql
    self.connect()
  File "/home/plm/ariasousse/apps/frappe/frappe/database/database.py", line 112, in connect
    self._conn: "MariadbConnection" | "PostgresConnection" = self.get_connection()
  File "/home/plm/ariasousse/apps/frappe/frappe/database/mariadb/database.py", line 107, in get_connection
    conn = self._get_connection()
  File "/home/plm/ariasousse/apps/frappe/frappe/database/mariadb/database.py", line 113, in _get_connection
    return self.create_connection()
  File "/home/plm/ariasousse/apps/frappe/frappe/database/mariadb/database.py", line 116, in create_connection
    return pymysql.connect(**self.get_connection_settings())
  File "/home/plm/ariasousse/env/lib/python3.10/site-packages/pymysql/connections.py", line 361, in __init__
    self.connect()
  File "/home/plm/ariasousse/env/lib/python3.10/site-packages/pymysql/connections.py", line 716, in connect
    raise exc
pymysql.err.OperationalError: (2003, "Can't connect to MySQL server on '127.0.0.1' ([Errno 111] Connection refused)")
2025-01-08 14:31:51,633 ERROR frappe Could not take error snapshot: (2003, "Can't connect to MySQL server on '127.0.0.1' ([Errno 111] Connection refused)")
Site: aria.localhost
Form Dict: {'doc': '{"name":"Avis a modfier","owner":"linca@linca.com","creation":"2024-12-27 09:26:46.221590","modified":"2024-12-27 09:49:08.412829","modified_by":"Administrator","docstatus":0,"idx":7,"is_standard":0,"label":"Avis a modfier ","custom_backrougnd":"#EC864B","type":"Document Type","function":"Count","aggregate_function_based_on":"","document_type":"Patient et demande","parent_document_type":"","report_function":"Sum","is_public":1,"show_percentage_stats":1,"stats_time_interval":"Daily","filters_json":"[[\\"Patient et demande\\",\\"status\\",\\"=\\",\\"Avis à modifier\\",false]]","dynamic_filters_json":"[]","doctype":"Number Card","__unsaved":1}', 'action': 'Save', 'cmd': 'frappe.desk.form.save.savedocs'}
Traceback (most recent call last):
  File "/home/plm/ariasousse/env/lib/python3.10/site-packages/pymysql/connections.py", line 649, in connect
    sock = socket.create_connection(
  File "/usr/lib/python3.10/socket.py", line 845, in create_connection
    raise err
  File "/usr/lib/python3.10/socket.py", line 833, in create_connection
    sock.connect(sa)
ConnectionRefusedError: [Errno 111] Connection refused

During handling of the above exception, another exception occurred:

Traceback (most recent call last):
  File "/home/plm/ariasousse/apps/frappe/frappe/app.py", line 114, in application
    response = frappe.api.handle(request)
  File "/home/plm/ariasousse/apps/frappe/frappe/api/__init__.py", line 49, in handle
    data = endpoint(**arguments)
  File "/home/plm/ariasousse/apps/frappe/frappe/api/v1.py", line 36, in handle_rpc_call
    return frappe.handler.handle()
  File "/home/plm/ariasousse/apps/frappe/frappe/handler.py", line 49, in handle
    data = execute_cmd(cmd)
  File "/home/plm/ariasousse/apps/frappe/frappe/handler.py", line 85, in execute_cmd
    return frappe.call(method, **frappe.form_dict)
  File "/home/plm/ariasousse/apps/frappe/frappe/__init__.py", line 1725, in call
    return fn(*args, **newargs)
  File "/home/plm/ariasousse/apps/frappe/frappe/utils/typing_validations.py", line 31, in wrapper
    return func(*args, **kwargs)
  File "/home/plm/ariasousse/apps/frappe/frappe/desk/form/save.py", line 39, in savedocs
    doc.save()
  File "/home/plm/ariasousse/apps/frappe/frappe/model/document.py", line 342, in save
    return self._save(*args, **kwargs)
  File "/home/plm/ariasousse/apps/frappe/frappe/model/document.py", line 372, in _save
    self.check_if_latest()
  File "/home/plm/ariasousse/apps/frappe/frappe/model/document.py", line 816, in check_if_latest
    self.load_doc_before_save(raise_exception=True)
  File "/home/plm/ariasousse/apps/frappe/frappe/model/document.py", line 1124, in load_doc_before_save
    self._doc_before_save = frappe.get_doc(self.doctype, self.name, for_update=True)
  File "/home/plm/ariasousse/apps/frappe/frappe/__init__.py", line 1290, in get_doc
    doc = frappe.model.document.get_doc(*args, **kwargs)
  File "/home/plm/ariasousse/apps/frappe/frappe/model/document.py", line 85, in get_doc
    return controller(*args, **kwargs)
  File "/home/plm/ariasousse/apps/frappe/frappe/model/document.py", line 126, in __init__
    self.load_from_db()
  File "/home/plm/ariasousse/apps/frappe/frappe/model/document.py", line 167, in load_from_db
    d = frappe.db.get_value(
  File "/home/plm/ariasousse/apps/frappe/frappe/database/database.py", line 515, in get_value
    result = self.get_values(
  File "/home/plm/ariasousse/apps/frappe/frappe/database/database.py", line 619, in get_values
    out = self._get_values_from_table(
  File "/home/plm/ariasousse/apps/frappe/frappe/database/database.py", line 892, in _get_values_from_table
    return query.run(as_dict=as_dict, debug=debug, update=update, run=run, pluck=pluck)
  File "/home/plm/ariasousse/apps/frappe/frappe/query_builder/utils.py", line 87, in execute_query
    result = frappe.db.sql(query, params, *args, **kwargs)  # nosemgrep
  File "/home/plm/ariasousse/apps/frappe/frappe/database/database.py", line 207, in sql
    self.connect()
  File "/home/plm/ariasousse/apps/frappe/frappe/database/database.py", line 112, in connect
    self._conn: "MariadbConnection" | "PostgresConnection" = self.get_connection()
  File "/home/plm/ariasousse/apps/frappe/frappe/database/mariadb/database.py", line 107, in get_connection
    conn = self._get_connection()
  File "/home/plm/ariasousse/apps/frappe/frappe/database/mariadb/database.py", line 113, in _get_connection
    return self.create_connection()
  File "/home/plm/ariasousse/apps/frappe/frappe/database/mariadb/database.py", line 116, in create_connection
    return pymysql.connect(**self.get_connection_settings())
  File "/home/plm/ariasousse/env/lib/python3.10/site-packages/pymysql/connections.py", line 361, in __init__
    self.connect()
  File "/home/plm/ariasousse/env/lib/python3.10/site-packages/pymysql/connections.py", line 716, in connect
    raise exc
pymysql.err.OperationalError: (2003, "Can't connect to MySQL server on '127.0.0.1' ([Errno 111] Connection refused)")

During handling of the above exception, another exception occurred:

Traceback (most recent call last):
  File "/home/plm/ariasousse/env/lib/python3.10/site-packages/pymysql/connections.py", line 649, in connect
    sock = socket.create_connection(
  File "/usr/lib/python3.10/socket.py", line 845, in create_connection
    raise err
  File "/usr/lib/python3.10/socket.py", line 833, in create_connection
    sock.connect(sa)
ConnectionRefusedError: [Errno 111] Connection refused

During handling of the above exception, another exception occurred:

Traceback (most recent call last):
  File "/home/plm/ariasousse/apps/frappe/frappe/utils/error.py", line 86, in log_error_snapshot
    log_error(title=str(exception), defer_insert=True)
  File "/home/plm/ariasousse/apps/frappe/frappe/utils/error.py", line 61, in log_error
    error_log = frappe.get_doc(
  File "/home/plm/ariasousse/apps/frappe/frappe/__init__.py", line 1290, in get_doc
    doc = frappe.model.document.get_doc(*args, **kwargs)
  File "/home/plm/ariasousse/apps/frappe/frappe/model/document.py", line 83, in get_doc
    controller = get_controller(doctype)
  File "/home/plm/ariasousse/apps/frappe/frappe/model/base_document.py", line 70, in get_controller
    site_controllers[doctype] = import_controller(doctype)
  File "/home/plm/ariasousse/apps/frappe/frappe/model/base_document.py", line 81, in import_controller
    doctype_info = frappe.db.get_value("DocType", doctype, fieldname="*")
  File "/home/plm/ariasousse/apps/frappe/frappe/database/database.py", line 515, in get_value
    result = self.get_values(
  File "/home/plm/ariasousse/apps/frappe/frappe/database/database.py", line 619, in get_values
    out = self._get_values_from_table(
  File "/home/plm/ariasousse/apps/frappe/frappe/database/database.py", line 892, in _get_values_from_table
    return query.run(as_dict=as_dict, debug=debug, update=update, run=run, pluck=pluck)
  File "/home/plm/ariasousse/apps/frappe/frappe/query_builder/utils.py", line 87, in execute_query
    result = frappe.db.sql(query, params, *args, **kwargs)  # nosemgrep
  File "/home/plm/ariasousse/apps/frappe/frappe/database/database.py", line 207, in sql
    self.connect()
  File "/home/plm/ariasousse/apps/frappe/frappe/database/database.py", line 112, in connect
    self._conn: "MariadbConnection" | "PostgresConnection" = self.get_connection()
  File "/home/plm/ariasousse/apps/frappe/frappe/database/mariadb/database.py", line 107, in get_connection
    conn = self._get_connection()
  File "/home/plm/ariasousse/apps/frappe/frappe/database/mariadb/database.py", line 113, in _get_connection
    return self.create_connection()
  File "/home/plm/ariasousse/apps/frappe/frappe/database/mariadb/database.py", line 116, in create_connection
    return pymysql.connect(**self.get_connection_settings())
  File "/home/plm/ariasousse/env/lib/python3.10/site-packages/pymysql/connections.py", line 361, in __init__
    self.connect()
  File "/home/plm/ariasousse/env/lib/python3.10/site-packages/pymysql/connections.py", line 716, in connect
    raise exc
pymysql.err.OperationalError: (2003, "Can't connect to MySQL server on '127.0.0.1' ([Errno 111] Connection refused)")
2025-01-08 14:32:05,948 ERROR frappe Could not take error snapshot: (2003, "Can't connect to MySQL server on '127.0.0.1' ([Errno 111] Connection refused)")
Site: aria.localhost
Form Dict: {'doctype': 'Patient et demande', 'fields': '["`tabPatient et demande`.`name`","`tabPatient et demande`.`owner`","`tabPatient et demande`.`creation`","`tabPatient et demande`.`modified`","`tabPatient et demande`.`modified_by`","`tabPatient et demande`.`_user_tags`","`tabPatient et demande`.`_comments`","`tabPatient et demande`.`_assign`","`tabPatient et demande`.`_liked_by`","`tabPatient et demande`.`docstatus`","`tabPatient et demande`.`idx`","`tabPatient et demande`.`status`","`tabPatient et demande`.`nom_du_patient`","`tabPatient et demande`.`_seen`"]', 'filters': '[]', 'order_by': '`tabPatient et demande`.`modified` desc', 'start': '0', 'page_length': '20', 'view': 'List', 'group_by': '', 'with_comment_count': '1', 'cmd': 'frappe.desk.reportview.get'}
Traceback (most recent call last):
  File "/home/plm/ariasousse/env/lib/python3.10/site-packages/pymysql/connections.py", line 649, in connect
    sock = socket.create_connection(
  File "/usr/lib/python3.10/socket.py", line 845, in create_connection
    raise err
  File "/usr/lib/python3.10/socket.py", line 833, in create_connection
    sock.connect(sa)
ConnectionRefusedError: [Errno 111] Connection refused

During handling of the above exception, another exception occurred:

Traceback (most recent call last):
  File "/home/plm/ariasousse/apps/frappe/frappe/app.py", line 114, in application
    response = frappe.api.handle(request)
  File "/home/plm/ariasousse/apps/frappe/frappe/api/__init__.py", line 49, in handle
    data = endpoint(**arguments)
  File "/home/plm/ariasousse/apps/frappe/frappe/api/v1.py", line 36, in handle_rpc_call
    return frappe.handler.handle()
  File "/home/plm/ariasousse/apps/frappe/frappe/handler.py", line 49, in handle
    data = execute_cmd(cmd)
  File "/home/plm/ariasousse/apps/frappe/frappe/handler.py", line 85, in execute_cmd
    return frappe.call(method, **frappe.form_dict)
  File "/home/plm/ariasousse/apps/frappe/frappe/__init__.py", line 1725, in call
    return fn(*args, **newargs)
  File "/home/plm/ariasousse/apps/frappe/frappe/utils/typing_validations.py", line 31, in wrapper
    return func(*args, **kwargs)
  File "/home/plm/ariasousse/apps/frappe/frappe/__init__.py", line 878, in wrapper_fn
    retval = fn(*args, **get_newargs(fn, kwargs))
  File "/home/plm/ariasousse/apps/frappe/frappe/desk/reportview.py", line 32, in get
    data = compress(execute(**args), args=args)
  File "/home/plm/ariasousse/apps/frappe/frappe/desk/reportview.py", line 78, in execute
    return DatabaseQuery(doctype).execute(*args, **kwargs)
  File "/home/plm/ariasousse/apps/frappe/frappe/model/db_query.py", line 191, in execute
    result = self.build_and_run()
  File "/home/plm/ariasousse/apps/frappe/frappe/model/db_query.py", line 232, in build_and_run
    return frappe.db.sql(
  File "/home/plm/ariasousse/apps/frappe/frappe/database/database.py", line 207, in sql
    self.connect()
  File "/home/plm/ariasousse/apps/frappe/frappe/database/database.py", line 112, in connect
    self._conn: "MariadbConnection" | "PostgresConnection" = self.get_connection()
  File "/home/plm/ariasousse/apps/frappe/frappe/database/mariadb/database.py", line 107, in get_connection
    conn = self._get_connection()
  File "/home/plm/ariasousse/apps/frappe/frappe/database/mariadb/database.py", line 113, in _get_connection
    return self.create_connection()
  File "/home/plm/ariasousse/apps/frappe/frappe/database/mariadb/database.py", line 116, in create_connection
    return pymysql.connect(**self.get_connection_settings())
  File "/home/plm/ariasousse/env/lib/python3.10/site-packages/pymysql/connections.py", line 361, in __init__
    self.connect()
  File "/home/plm/ariasousse/env/lib/python3.10/site-packages/pymysql/connections.py", line 716, in connect
    raise exc
pymysql.err.OperationalError: (2003, "Can't connect to MySQL server on '127.0.0.1' ([Errno 111] Connection refused)")

During handling of the above exception, another exception occurred:

Traceback (most recent call last):
  File "/home/plm/ariasousse/env/lib/python3.10/site-packages/pymysql/connections.py", line 649, in connect
    sock = socket.create_connection(
  File "/usr/lib/python3.10/socket.py", line 845, in create_connection
    raise err
  File "/usr/lib/python3.10/socket.py", line 833, in create_connection
    sock.connect(sa)
ConnectionRefusedError: [Errno 111] Connection refused

During handling of the above exception, another exception occurred:

Traceback (most recent call last):
  File "/home/plm/ariasousse/apps/frappe/frappe/utils/error.py", line 86, in log_error_snapshot
    log_error(title=str(exception), defer_insert=True)
  File "/home/plm/ariasousse/apps/frappe/frappe/utils/error.py", line 61, in log_error
    error_log = frappe.get_doc(
  File "/home/plm/ariasousse/apps/frappe/frappe/__init__.py", line 1290, in get_doc
    doc = frappe.model.document.get_doc(*args, **kwargs)
  File "/home/plm/ariasousse/apps/frappe/frappe/model/document.py", line 83, in get_doc
    controller = get_controller(doctype)
  File "/home/plm/ariasousse/apps/frappe/frappe/model/base_document.py", line 70, in get_controller
    site_controllers[doctype] = import_controller(doctype)
  File "/home/plm/ariasousse/apps/frappe/frappe/model/base_document.py", line 81, in import_controller
    doctype_info = frappe.db.get_value("DocType", doctype, fieldname="*")
  File "/home/plm/ariasousse/apps/frappe/frappe/database/database.py", line 515, in get_value
    result = self.get_values(
  File "/home/plm/ariasousse/apps/frappe/frappe/database/database.py", line 619, in get_values
    out = self._get_values_from_table(
  File "/home/plm/ariasousse/apps/frappe/frappe/database/database.py", line 892, in _get_values_from_table
    return query.run(as_dict=as_dict, debug=debug, update=update, run=run, pluck=pluck)
  File "/home/plm/ariasousse/apps/frappe/frappe/query_builder/utils.py", line 87, in execute_query
    result = frappe.db.sql(query, params, *args, **kwargs)  # nosemgrep
  File "/home/plm/ariasousse/apps/frappe/frappe/database/database.py", line 207, in sql
    self.connect()
  File "/home/plm/ariasousse/apps/frappe/frappe/database/database.py", line 112, in connect
    self._conn: "MariadbConnection" | "PostgresConnection" = self.get_connection()
  File "/home/plm/ariasousse/apps/frappe/frappe/database/mariadb/database.py", line 107, in get_connection
    conn = self._get_connection()
  File "/home/plm/ariasousse/apps/frappe/frappe/database/mariadb/database.py", line 113, in _get_connection
    return self.create_connection()
  File "/home/plm/ariasousse/apps/frappe/frappe/database/mariadb/database.py", line 116, in create_connection
    return pymysql.connect(**self.get_connection_settings())
  File "/home/plm/ariasousse/env/lib/python3.10/site-packages/pymysql/connections.py", line 361, in __init__
    self.connect()
  File "/home/plm/ariasousse/env/lib/python3.10/site-packages/pymysql/connections.py", line 716, in connect
    raise exc
pymysql.err.OperationalError: (2003, "Can't connect to MySQL server on '127.0.0.1' ([Errno 111] Connection refused)")
2025-01-08 14:49:31,232 ERROR frappe New Exception collected in error log
Site: aria.localhost
Form Dict: {'recipients': 'linca@linca.com, ', 'subject': 'Patient et demande: test12', 'content': '<div class="ql-editor read-mode"><p><br></p></div>', 'doctype': 'Patient et demande', 'name': 'test12', 'send_email': '1', 'print_html': '', 'send_me_a_copy': '0', 'print_format': 'Standard', 'attachments': '[]', 'read_receipt': '0', 'print_letterhead': '1', 'send_after': '', 'print_language': 'fr', 'cmd': 'frappe.core.doctype.communication.email.make'}
